<?xml version="1.0"?>
<robot xmlns:sensor="http://playerstage.sourceforge.net/gazebo/xmlschema/#sensor"
       xmlns:controller="http://playerstage.sourceforge.net/gazebo/xmlschema/#controller"
       xmlns:interface="http://playerstage.sourceforge.net/gazebo/xmlschema/#interface"
       xmlns:xacro="http://playerstage.sourceforge.net/gazebo/xmlschema/#interface"
       name="lbr3">

 <link name="kuka_root">
    <visual>
      <origin rpy="0 0 0" xyz="0 0 0"/>
      <geometry>
        <box size="0.001 0.001 0.001"/>
      </geometry>
      <material name="Blue"/>
    </visual>
 </link>


 <link name="link_kinect">
    <visual>
      <geometry>
       <box size = "0.6 2.8 .4"/>
      </geometry>
      <material name="Blue"/>
    </visual>
 </link>

 <link name="segment_0">
    <visual>
      <geometry>
        <mesh filename="package://lbr3_model/cad/segment_0.dae" scale="0.01 0.01 0.01"/>
      </geometry>
    </visual>
	<collision>
			<geometry>
				<mesh filename="package://lbr3_model/cad/segment_0_collision.dae" scale="0.01 0.01 0.01"/>
			</geometry>
	</collision>
  </link>

 <link name="segment_1">
    <visual>
      <geometry>
        <mesh filename="package://lbr3_model/cad/segment_1.dae" scale="0.01 0.01 0.01"/>
      </geometry>
    </visual>
	<collision>
			<geometry>
				<mesh filename="package://lbr3_model/cad/segment_1_collision.dae" scale="0.01 0.01 0.01"/>
			</geometry>
		</collision> 
  </link>

 <link name="segment_2">
    <visual>
      <geometry>
        <mesh filename="package://lbr3_model/cad/segment_2.dae" scale="0.01 0.01 0.01"/>
      </geometry>
    </visual>
	<collision>
			<geometry>
				<mesh filename="package://lbr3_model/cad/segment_2_collision.dae" scale="0.01 0.01 0.01"/>
			</geometry>
		</collision>
  </link>

 <link name="segment_3">
    <visual>
      <geometry>
        <mesh filename="package://lbr3_model/cad/segment_3.dae" scale="0.01 0.01 0.01"/>
      </geometry>
    </visual>
		<collision>
			<geometry>
				<mesh filename="package://lbr3_model/cad/segment_3_collision.dae" scale="0.01 0.01 0.01"/>
			</geometry>
		</collision> 
  </link>

 <link name="segment_4">
    <visual>
      <geometry>
        <mesh filename="package://lbr3_model/cad/segment_4.dae" scale="0.01 0.01 0.01"/>
      </geometry>
    </visual>
		<collision>
			<geometry>
				<mesh filename="package://lbr3_model/cad/segment_4_collision.dae" scale="0.01 0.01 0.01"/>
			</geometry>
		</collision> -->
  </link>

 <link name="segment_5">
    <visual>
      <geometry>
        <mesh filename="package://lbr3_model/cad/segment_5.dae" scale="0.01 0.01 0.01"/>
      </geometry>
    </visual>
		<collision>
			<geometry>
				<mesh filename="package://lbr3_model/cad/segment_5_collision.dae" scale="0.01 0.01 0.01"/>
			</geometry>
		</collision> 
  </link>

  <link name="segment_6">
    <visual>
      <geometry>
        <mesh filename="package://lbr3_model/cad/segment_6.dae" scale="0.01 0.01 0.01"/>
      </geometry>
    </visual>
		<collision>
			<geometry>
				<mesh filename="package://lbr3_model/cad/segment_6_collision.dae" scale="0.01 0.01 0.01"/>
			</geometry>
		</collision>
  </link>

  <link name="segment_7">
    <visual>
      <geometry>
        <mesh filename="package://lbr3_model/cad/segment_7.dae" scale="0.01 0.01 0.01"/>
      </geometry>
    </visual>
		<collision>
			<geometry>
				<mesh filename="package://lbr3_model/cad/segment_7_collision.dae" scale="0.01 0.01 0.01"/>
			</geometry>
		</collision>
  </link>

  <!-- ################################### JOINTS ############################### -->

  <joint name="kinect_depth_joint" type="fixed">
     <origin xyz="5.15 9.6 14.55" rpy="0 0.87 -1.57"/>
     <parent link="segment_0"/>
     <child link="link_kinect"/>
  </joint>

  <joint name="joint_0" type="revolute">
    <limit lower="-2.96705972839031" upper="2.96705972839031" effort="176" velocity="1.31" />
    <safety_controller k_position="100" k_velocity="2000000" soft_lower_limit="-2.949605822" soft_upper_limit="2.949605822"/>
    <parent link="segment_0"/> 
    <child link="segment_1"/>
    <axis xyz="0 0 1"/>
    <origin xyz="0 0 1.105"/>
  </joint>

  <joint name="joint_1" type="revolute">
    <limit lower="-2.094395102393187" upper="2.0943951023931335" effort="176" velocity="1.31" />
    <safety_controller k_position="100" k_velocity="2000000" soft_lower_limit="-2.076941378" soft_upper_limit="2.076941378"/>
    <parent link="segment_1"/>
    <child link="segment_2"/>
    <axis xyz="0 1 0"/>
    <origin xyz="0 0 2"/>
  </joint>

  <joint name="joint_2" type="revolute">
    <limit lower="-2.96705972839031" upper="2.96705972839031" effort="110" velocity="1.57" />
    <safety_controller k_position="100" k_velocity="2000000" soft_lower_limit="-2.949605822" soft_upper_limit="2.949605822"/>
    <parent link="segment_2"/>
    <child link="segment_3"/>
    <axis xyz="0 0 1"/>
    <origin xyz="0 0 2"/>
  </joint>

  <joint name="joint_3" type="revolute">
    <limit lower="-2.09439510239316" upper="2.09439510239316" effort="110" velocity="1.57" />
    <safety_controller k_position="100" k_velocity="2000000" soft_lower_limit="-2.076941378" soft_upper_limit="2.076941378"/>
    <parent link="segment_3"/>
    <child link="segment_4"/>
    <axis xyz="0 -1 0"/>
    <origin xyz="0 0 2"/>
  </joint>

  <joint name="joint_4" type="revolute">
    <limit lower="-2.96705972839031" upper="2.96705972839031" effort="110" velocity="2.51" />
    <safety_controller k_position="100" k_velocity="2000000" soft_lower_limit="-2.949605822" soft_upper_limit="2.949605822"/>
    <parent link="segment_4"/>
    <child link="segment_5"/>
    <axis xyz="0 0 1"/>
    <origin xyz="0 0 2"/>
  </joint>

  <joint name="joint_5" type="revolute">
    <limit lower="-2.09439510239316" upper="2.09439510239316" effort="40" velocity="2.36" />
    <safety_controller k_position="100" k_velocity="2000000" soft_lower_limit="-2.076941378" soft_upper_limit="2.076941378"/>
    <parent link="segment_5"/>
    <child link="segment_6"/>
    <axis xyz="0 1 0"/>
    <origin xyz="0 0 1.885"/>
  </joint>

  <joint name="joint_6" type="revolute">
    <limit lower="-2.96705972839031" upper="2.96705972839031" effort="40" velocity="2.36" />
    <safety_controller k_position="100" k_velocity="2000000" soft_lower_limit="-2.949605822" soft_upper_limit="2.949605822"/>
    <parent link="segment_6"/>
    <child link="segment_7"/>
    <axis xyz="0 0 1"/>
    <origin xyz="0 0 .795"/>
  </joint>



  <joint name="joint_root" type="fixed">
    <parent link="kuka_root"/>
    <child link="segment_0"/>
    <axis xyz="0 0 1"/>
    <origin rpy="0 0 3.14159" xyz="5.4 1.9 4.16"/>
<!--    <origin rpy="0 0 0" xyz="5.4 1.9 4.16"/>-->
  </joint>



  <link name="tool">
    <visual>
      <geometry>
        <mesh filename="package://kuka_description/cad/tool_s.dae"/>
      </geometry>
    </visual>
    <collision>
      <geometry>
        <mesh filename="package://kuka_description/cad/tool_s.dae"/>
      </geometry>
    </collision>
  </link>
 <link name="end_effector_link">
  </link>

 <link name="tcp_1_link">
 </link>

 <link name="tcp_2_link">
 </link>

 <link name="goal_1_link">
 </link>
 <link name="goal_2_link">
 </link>
 <link name="goal_3_link">
 </link>
 <link name="goal_4_link">
 </link>
 <link name="goal_5_link">
 </link>
 <link name="goal_6_link">
 </link>

  <joint name="joint_tool" type="fixed">
    <parent link="segment_7"/>
    <child link="tool"/>
    <axis xyz="0 0 1"/>
    <origin xyz="0 0 0"/>
  </joint>

  <joint name="joint_ee" type="fixed">
    <parent link="tool"/>
    <child link="end_effector_link"/>
    <axis xyz="0 0 1"/>
    <origin xyz="0 0 0"/>
  </joint>

  <joint name="joint_tcp_1" type="fixed">
    <parent link="tool"/>
    <child link="tcp_1_link"/>
    <axis xyz="0 0 1"/>
    <origin xyz="-1.64 -0.28 2.32"/>
  </joint>

  <joint name="joint_tcp_2" type="fixed">
    <parent link="tool"/>
    <child link="tcp_2_link"/>
    <axis xyz="0 0 1"/>
    <origin rpy="0 -1.570796 0" xyz="-2.94 -0.11 0.44"/>
  </joint>

  <joint name="joint_goal_1" type="fixed">
    <parent link="kuka_root"/>
    <child link="goal_1_link"/>
    <axis xyz="0 0 1"/>
    <origin rpy="-1.570796 0 1.570796" xyz="2.0 0.5 12.0"/>
  </joint>

  <joint name="joint_goal_2" type="fixed">
    <parent link="kuka_root"/>
    <child link="goal_2_link"/>
    <axis xyz="0 0 1"/>
    <origin rpy="-1.570796 0 1.570796" xyz="2.0 1.0 12.0"/>
  </joint>

  <joint name="joint_goal_3" type="fixed">
    <parent link="kuka_root"/>
    <child link="goal_3_link"/>
    <axis xyz="0 0 1"/>
    <origin rpy="-1.570796 0 1.570796" xyz="2.0 1.5 12.0"/>
  </joint>

  <joint name="joint_goal_4" type="fixed">
    <parent link="kuka_root"/>
    <child link="goal_4_link"/>
    <axis xyz="0 0 1"/>
    <origin rpy="-1.570796 0 3.141592" xyz="2.0 2.0 8.5"/>
  </joint>

  <joint name="joint_goal_5" type="fixed">
    <parent link="kuka_root"/>
    <child link="goal_5_link"/>
    <axis xyz="0 0 1"/>
    <origin rpy="-1.570796 0 3.141592" xyz="1.5 2.0 8.5"/>
  </joint>

  <joint name="joint_goal_6" type="fixed">
    <parent link="kuka_root"/>
    <child link="goal_6_link"/>
    <axis xyz="0 0 1"/>
    <origin rpy="-1.570796 0 3.141592" xyz="1.0 2.0 8.5"/>
  </joint>


</robot>


