<?xml version="1.0"?>
<robot xmlns:sensor="http://playerstage.sourceforge.net/gazebo/xmlschema/#sensor"
       xmlns:controller="http://playerstage.sourceforge.net/gazebo/xmlschema/#controller"
       xmlns:interface="http://playerstage.sourceforge.net/gazebo/xmlschema/#interface"
       xmlns:xacro="http://playerstage.sourceforge.net/gazebo/xmlschema/#interface"
       name="lbr5_7">

 <link name="segment_0">
    <visual>
      <geometry>
        <mesh filename="package://kuka_description/cad/segment_0_s.dae"/>
      </geometry>
    </visual>
    <collision>
      <geometry>
        <mesh filename="package://kuka_description/cad/segment_0_c.dae"/>
      </geometry>
    </collision>
  </link>

 <link name="segment_1">
    <visual>
      <geometry>
        <mesh filename="package://kuka_description/cad/segment_1_s.dae"/>
      </geometry>
    </visual>
    <collision>
      <geometry>
        <mesh filename="package://kuka_description/cad/segment_1_c.dae"/>
      </geometry>
    </collision>
  </link>

 <link name="segment_2">
    <visual>
      <geometry>
        <mesh filename="package://kuka_description/cad/segment_2_s.dae"/>
      </geometry>
    </visual>
    <collision>
      <geometry>
        <mesh filename="package://kuka_description/cad/segment_2_c.dae"/>
      </geometry>
    </collision>
  </link>

 <link name="segment_3">
    <visual>
      <geometry>
        <mesh filename="package://kuka_description/cad/segment_3_s.dae"/>
      </geometry>
    </visual>
    <collision>
      <geometry>
        <mesh filename="package://kuka_description/cad/segment_3_c.dae"/>
      </geometry>
    </collision>
  </link>

 <link name="segment_4">
    <visual>
      <geometry>
        <mesh filename="package://kuka_description/cad/segment_4_s.dae"/>
      </geometry>
    </visual>
    <collision>
      <geometry>
        <mesh filename="package://kuka_description/cad/segment_4_c.dae"/>
      </geometry>
    </collision>
  </link>

 <link name="segment_5">
    <visual>
      <geometry>
        <mesh filename="package://kuka_description/cad/segment_5_s.dae"/>
      </geometry>
    </visual>
    <collision>
      <geometry>
        <mesh filename="package://kuka_description/cad/segment_5_c.dae"/>
      </geometry>
    </collision>
  </link>

  <link name="segment_6">
    <visual>
      <geometry>
        <mesh filename="package://kuka_description/cad/segment_6_s.dae"/>
      </geometry>
    </visual>
    <collision>
      <geometry>
        <mesh filename="package://kuka_description/cad/segment_6_c.dae"/>
      </geometry>
    </collision>
  </link>

  <link name="segment_7">
    <visual>
      <geometry>
        <mesh filename="package://kuka_description/cad/segment_7_s.dae"/>
      </geometry>
    </visual>
    <collision>
      <geometry>
        <mesh filename="package://kuka_description/cad/segment_7_c.dae"/>
      </geometry>
    </collision>
  </link>

 <link name="end_effector_link">
  </link>


  <joint name="joint_0" type="continuous">
    <parent link="segment_0"/>
    <child link="segment_1"/>
    <axis xyz="0 0 1"/>
    <origin xyz="0 0 1.57"/>
  </joint>

  <joint name="joint_1" type="continuous">
    <parent link="segment_1"/>
    <child link="segment_2"/>
    <axis xyz="0 1 0"/>
    <origin xyz="0 0 1.85"/>
  </joint>

  <joint name="joint_2" type="continuous">
    <parent link="segment_2"/>
    <child link="segment_3"/>
    <axis xyz="0 0 1"/>
    <origin xyz="0 0 1.85"/>
  </joint>

  <joint name="joint_3" type="continuous">
    <parent link="segment_3"/>
    <child link="segment_4"/>
    <axis xyz="0 1 0"/>
    <origin xyz="0 0 2.15"/>
  </joint>

  <joint name="joint_4" type="continuous">
    <parent link="segment_4"/>
    <child link="segment_5"/>
    <axis xyz="0 0 1"/>
    <origin xyz="0 0 1.85"/>
  </joint>

  <joint name="joint_5" type="continuous">
    <parent link="segment_5"/>
    <child link="segment_6"/>
    <axis xyz="0 1 0"/>
    <origin xyz="0 0 2.15"/>
  </joint>

  <joint name="joint_6" type="continuous">
    <parent link="segment_6"/>
    <child link="segment_7"/>
    <axis xyz="0 0 1"/>
    <origin xyz="0 0 0.80"/>
  </joint>

  <joint name="joint_ee" type="fixed">
    <parent link="segment_7"/>
    <child link="end_effector_link"/>
    <axis xyz="0 0 1"/>
    <origin xyz="0 0 0.25"/>
  </joint>



</robot>

