<?xml version="1.0" ?>
<!-- =================================================================================== -->
<!-- |    This document was autogenerated by xacro from human_cio.urdf.xacro           | -->
<!-- |    EDITING THIS FILE BY HAND IS NOT RECOMMENDED                                 | -->
<!-- =================================================================================== -->
<robot name="human_cio" xmlns:controller="http://playerstage.sourceforge.net/gazebo/xmlschema/#controller" xmlns:interface="http://playerstage.sourceforge.net/gazebo/xmlschema/#interface" xmlns:sensor="http://playerstage.sourceforge.net/gazebo/xmlschema/#sensor" xmlns:xacro="http://playerstage.sourceforge.net/gazebo/xmlschema/#interface">
  <material name="Blue">
    <color rgba="0.0 0.0 0.8 1.0"/>
  </material>
  <material name="Green">
    <color rgba="0.0 0.8 0.0 1.0"/>
  </material>
  <material name="Grey">
    <color rgba="0.7 0.7 0.7 1.0"/>
  </material>
  <material name="Grey2">
    <color rgba="0.9 0.9 0.9 1.0"/>
  </material>
  <material name="Red">
    <color rgba="0.8 0.0 0.0 1.0"/>
  </material>
  <material name="White">
    <color rgba="1.0 1.0 1.0 1.0"/>
  </material>
  <material name="Black">
    <color rgba="0.1 0.1 0.1 1.0"/>
  </material>
  <material name="LightGrey">
    <color rgba="0.6 0.6 0.6 1.0"/>
  </material>
  <link name="root_link"/>

  <joint name="root_dummy_joint" type="fixed">
    <parent link="root_link"/>
    <child link="pelvis_link"/>
  </joint>

  <link name="pelvis_link">
    <visual>
      <origin rpy="0 0 0" xyz="0 0 0"/>
      <geometry>
        <mesh filename="package://human_description/meshes/pelvis.dae"/>
      </geometry>
      <material name="Grey2"/>
    </visual>
    <collision>
      <origin rpy="0 0 0" xyz="0 0 0"/>
      <geometry>
        <mesh filename="package://human_description/meshes/collision/pelvis.dae"/>
      </geometry>
    </collision>
    <inertial>
      <mass value="24.9873014159"/>
      <inertia ixx="0.219399825" ixy="0.000000009184695" ixz="0.000000062599005" iyy="0.21939959375" iyz="-0.000000006475555" izz="0.22992248625"/>
      <origin xyz="0 -0.00000001 0.0983925"/>
    </inertial>
  </link>
  <joint name="torso_z_joint" type="continuous">
    <axis xyz="0 0 1"/>
    <limit effort="15" lower="-0.7" upper="0.7" velocity="5"/>
    <origin rpy="0 0 0" xyz="0 0 0.26"/>
    <parent link="pelvis_link"/>
    <child link="torso_z_link"/>
  </joint>
  <joint name="torso_y_joint" type="continuous">
    <axis xyz="0 1 0"/>
    <limit effort="15" lower="-0.3" upper="0.3" velocity="5"/>
    <origin rpy="0 0 0" xyz="0 0 0"/>
    <parent link="torso_z_link"/>
    <child link="torso_y_link"/>
  </joint>
  <joint name="torso_x_joint" type="continuous">
    <axis xyz="1 0 0"/>
    <limit effort="15" lower="-1.0" upper="0" velocity="5"/>
    <origin rpy="0 0 0" xyz="0 0 0"/>
    <parent link="torso_y_link"/>
    <child link="torso_x_link"/>
  </joint>
  <link name="torso_z_link"/>
  <link name="torso_y_link"/>
  <link name="torso_x_link">
    <visual>
      <origin rpy="0 0 0" xyz="0 0 0"/>
      <geometry>
        <mesh filename="package://human_description/meshes/torso.dae"/>
      </geometry>
      <material name="Blue"/>
    </visual>
    <collision>
      <origin rpy="0 0 0" xyz="0 0 0"/>
      <geometry>
        <mesh filename="package://human_description/meshes/collision/torso.dae"/>
      </geometry>
    </collision>
    <inertial>
      <mass value="54.1902903318"/>
      <inertia ixx="1.0895931125" ixy="0.000001152997515" ixz="-0.000000460619845" iyy="1.4490895525" iyz="0.000000968452985" izz="0.679463005"/>
      <origin xyz="0 -0.00000025 0.22608234"/>
    </inertial>
  </link>
  <joint name="head_z_joint" type="continuous">
    <axis xyz="0 0 1"/>
    <limit effort="15" lower="-1.2" upper="1.2" velocity="5"/>
    <origin rpy="0 0 0" xyz="0 0 0.45"/>
    <parent link="torso_x_link"/>
    <child link="head_z_link"/>
  </joint>
  <joint name="head_y_joint" type="continuous">
    <axis xyz="0 1 0"/>
    <limit effort="15" lower="-0.8" upper="0.8" velocity="5"/>
    <origin rpy="0 0 0" xyz="0 0 0"/>
    <parent link="head_z_link"/>
    <child link="head_y_link"/>
  </joint>
  <joint name="head_x_joint" type="continuous">
    <axis xyz="1 0 0"/>
    <limit effort="15" lower="-1.57" upper="0.3" velocity="5"/>
    <origin rpy="0 0 0" xyz="0 0 0"/>
    <parent link="head_y_link"/>
    <child link="head_x_link"/>
  </joint>
  <link name="head_z_link"/>
  <link name="head_y_link"/>
  <link name="head_x_link">
    <visual>
      <origin rpy="0 0 0" xyz="0 0 0"/>
      <geometry>
        <mesh filename="package://human_description/meshes/head.dae"/>
      </geometry>
      <material name="Blue"/>
    </visual>
    <collision>
      <origin rpy="0 0 0" xyz="0 0 0"/>
      <geometry>
        <mesh filename="package://human_description/meshes/collision/head.dae"/>
      </geometry>
    </collision>
    <inertial>
      <mass value="16.0164526852"/>
      <inertia ixx="0.194835825625" ixy="-0.00000000913641" ixz="0.00000000531468" iyy="0.194835733125" iyz="-0.000000020301345" izz="0.06426014890625"/>
      <origin xyz="0.0 0.00000001 0.18566523"/>
    </inertial>
  </link>
  <joint name="head_endeffector_joint" type="continuous">
    <axis xyz="0 0 1"/>
    <limit effort="15" lower="-0.001" upper="0.001" velocity="5"/>
    <origin rpy="0 0 0" xyz="0 0 0.3"/>
    <parent link="head_x_link"/>
    <child link="head_endeffector_link"/>
  </joint>
  <link name="head_endeffector_link">
    <visual>
      <origin rpy="0 0 0" xyz="0 0 0"/>
      <geometry>
        <box size="0.001 0.001 0.001"/>
      </geometry>
      <material name="Blue"/>
    </visual>
    <collision>
      <origin rpy="0 0 0" xyz="0 0 0"/>
      <geometry>
        <box size="0.001 0.001 0.001"/>
      </geometry>
    </collision>
  </link>
  <joint name="upper_left_leg_z_joint" type="continuous">
    <axis xyz="0 0 1"/>
    <!--    <limit effort="15" lower="-1.57" upper="1.57" velocity="5"/>-->
    <limit effort="15" lower="-0.1" upper="1.57" velocity="5"/>
    <!--    <limit effort="15" lower="0" upper="0" velocity="5"/>-->
    <origin rpy="0 0 0" xyz="-0.1 0 0"/>
    <parent link="pelvis_link"/>
    <child link="upper_left_leg_z_link"/>
  </joint>
  <joint name="upper_left_leg_y_joint" type="continuous">
    <axis xyz="0 1 0"/>
    <!--    <limit effort="15" lower="-1.57" upper="1.57" velocity="5"/>-->
    <limit effort="15" lower="-0.1" upper="1.57" velocity="5"/>
    <!--    <limit effort="15" lower="0" upper="0" velocity="5"/>-->
    <origin rpy="0 0 0" xyz="0 0 0"/>
    <parent link="upper_left_leg_z_link"/>
    <child link="upper_left_leg_y_link"/>
  </joint>
  <joint name="upper_left_leg_x_joint" type="continuous">
    <axis xyz="1 0 0"/>
    <limit effort="15" lower="-1.2" upper="1.57" velocity="5"/>
    <origin rpy="0 0 0" xyz="0 0 0"/>
    <parent link="upper_left_leg_y_link"/>
    <child link="upper_left_leg_x_link"/>
  </joint>
  <link name="upper_left_leg_z_link"/>
  <link name="upper_left_leg_y_link"/>
  <link name="upper_left_leg_x_link">
    <visual>
      <origin rpy="0 0 0" xyz="0 0 0"/>
      <geometry>
        <mesh filename="package://human_description/meshes/upperLeftLeg.dae"/>
      </geometry>
      <material name="Blue"/>
    </visual>
    <collision>
      <origin rpy="0 0 0" xyz="0 0 0"/>
      <geometry>
        <mesh filename="package://human_description/meshes/collision/upperLeftLeg.dae"/>
      </geometry>
    </collision>
    <inertial>
      <mass value="11.28066677275"/>
      <inertia ixx="0.258606759375" ixy="0.000002463301455" ixz="0.00032211891975" iyy="0.258311314375" iyz="-0.000065609605275" izz="0.021073428046875"/>
      <origin xyz="-0.00364974 -0.00003172 -0.19576731"/>
    </inertial>
  </link>
  <joint name="lower_left_leg_joint" type="continuous">
    <axis xyz="1 0 0"/>
    <limit effort="15" lower="-2.4" upper="0" velocity="5"/>
    <origin rpy="0 0 0" xyz="0 0 -0.5"/>
    <parent link="upper_left_leg_x_link"/>
    <child link="lower_left_leg_link"/>
  </joint>
  <link name="lower_left_leg_link">
    <visual>
      <origin rpy="0 0 0" xyz="0 0 0"/>
      <geometry>
        <mesh filename="package://human_description/meshes/lowerLeftLeg.dae"/>
      </geometry>
      <material name="Blue"/>
    </visual>
    <collision>
      <origin rpy="0 0 0" xyz="0 0 0"/>
      <geometry>
        <mesh filename="package://human_description/meshes/collision/lowerLeftLeg.dae"/>
      </geometry>
    </collision>
    <inertial>
      <mass value="8.394054321"/>
      <inertia ixx="0.1879741409375" ixy="0.000000001719205" ixz="-0.00000000509231" iyy="0.1879741525" iyz="-0.00000001780773" izz="0.01166299402353"/>
      <origin xyz="0.0 -0.00029422 -0.20195734"/>
    </inertial>
  </link>
  <joint name="left_foot_x_joint" type="continuous">
    <axis xyz="1 0 0"/>
    <limit effort="15" lower="-1.57" upper="1.57" velocity="5"/>
    <!--    <limit effort="15" lower="-0.8" upper="0.6" velocity="5"/>-->
    <origin rpy="0 0 0" xyz="0 0 -0.52"/>
    <parent link="lower_left_leg_link"/>
    <child link="left_foot_x_link"/>
  </joint>
  <joint name="left_foot_y_joint" type="continuous">
    <axis xyz="0 1 0"/>
    <limit effort="15" lower="-1.57" upper="1.57" velocity="5"/>
    <!--    <limit effort="15" lower="0" upper="0" velocity="5"/>-->
    <origin rpy="0 0 0" xyz="0 0 0"/>
    <parent link="left_foot_x_link"/>
    <child link="left_foot_y_link"/>
  </joint>
  <joint name="left_foot_z_joint" type="continuous">
    <axis xyz="0 0 1"/>
    <!--    <limit effort="15" lower="-0.2" upper="0.2" velocity="5"/>-->
    <limit effort="15" lower="0" upper="0" velocity="5"/>
    <origin rpy="0 0 0" xyz="0 0 0"/>
    <parent link="left_foot_y_link"/>
    <child link="left_foot_z_link"/>
  </joint>
  <link name="left_foot_x_link"/>
  <link name="left_foot_y_link"/>
  <link name="left_foot_z_link">
    <visual>
      <origin rpy="0 0 0" xyz="0 0 0"/>
      <geometry>
        <mesh filename="package://human_description/meshes/leftFoot.dae"/>
      </geometry>
      <material name="Blue"/>
    </visual>
    <collision>
      <origin rpy="0 0 0" xyz="0 0 0"/>
      <geometry>
        <mesh filename="package://human_description/meshes/collision/leftFoot.dae"/>
      </geometry>
    </collision>
    <inertial>
      <mass value="2.24629475115"/>
      <inertia ixx="0.00997119431636" ixy="-0.00032381616821" ixz="0.00003556416949" iyy="0.00325251065432" iyz="0.00137797584221" izz="0.01040399675772"/>
      <origin xyz="-0.00160579 0.04884521 -0.0783361"/>
    </inertial>
  </link>
  <joint name="left_foot_endeffector_joint" type="continuous">
    <axis xyz="0 0 1"/>
    <limit effort="15" lower="0" upper="0" velocity="5"/>
    <origin rpy="0 0 0" xyz="0 0 -0.1"/>
    <parent link="left_foot_z_link"/>
    <child link="left_foot_endeffector_link"/>
  </joint>
  <link name="left_foot_endeffector_link">
    <visual>
      <origin rpy="0 0 0" xyz="0 0 0"/>
      <geometry>
        <box size="0.001 0.001 0.001"/>
      </geometry>
      <material name="Blue"/>
    </visual>
  </link>
  <joint name="upper_right_leg_z_joint" type="continuous">
    <axis xyz="0 0 1"/>
    <!--    <limit effort="15" lower="-1.57" upper="1.57" velocity="5"/>-->
    <limit effort="15" lower="-1.57" upper="0.1" velocity="5"/>
    <!--    <limit effort="15" lower="0" upper="0" velocity="5"/>-->
    <origin rpy="0 0 0" xyz="0.1 0 0"/>
    <parent link="pelvis_link"/>
    <child link="upper_right_leg_z_link"/>
  </joint>
  <joint name="upper_right_leg_y_joint" type="continuous">
    <axis xyz="0 1 0"/>
    <!--    <limit effort="15" lower="-1.57" upper="1.57" velocity="5"/>-->
    <limit effort="15" lower="-1.57" upper="0.1" velocity="5"/>
    <!--    <limit effort="15" lower="0" upper="0" velocity="5"/>-->
    <origin rpy="0 0 0" xyz="0 0 0"/>
    <parent link="upper_right_leg_z_link"/>
    <child link="upper_right_leg_y_link"/>
  </joint>
  <joint name="upper_right_leg_x_joint" type="continuous">
    <axis xyz="1 0 0"/>
    <limit effort="15" lower="-1.2" upper="1.57" velocity="5"/>
    <origin rpy="0 0 0" xyz="0 0 0"/>
    <parent link="upper_right_leg_y_link"/>
    <child link="upper_right_leg_x_link"/>
  </joint>
  <link name="upper_right_leg_z_link"/>
  <link name="upper_right_leg_y_link"/>
  <link name="upper_right_leg_x_link">
    <visual>
      <origin rpy="0 0 0" xyz="0 0 0"/>
      <geometry>
        <mesh filename="package://human_description/meshes/upperRightLeg.dae"/>
      </geometry>
      <material name="Blue"/>
    </visual>
    <collision>
      <origin rpy="0 0 0" xyz="0 0 0"/>
      <geometry>
        <mesh filename="package://human_description/meshes/collision/upperRightLeg.dae"/>
      </geometry>
    </collision>
    <inertial>
      <mass value="11.28066677275"/>
      <inertia ixx="0.258606759375" ixy="-0.000002463410605" ixz="-0.000322118806715" iyy="0.258311360625" iyz="-0.000065609865015" izz="0.021073428046875"/>
      <origin xyz="0.00364974 -0.00003172 -0.19576731"/>
    </inertial>
  </link>
  <joint name="lower_right_leg_joint" type="continuous">
    <axis xyz="1 0 0"/>
    <limit effort="15" lower="-2.4" upper="0" velocity="5"/>
    <origin rpy="0 0 0" xyz="0 0 -0.5"/>
    <parent link="upper_right_leg_x_link"/>
    <child link="lower_right_leg_link"/>
  </joint>
  <link name="lower_right_leg_link">
    <visual>
      <origin rpy="0 0 0" xyz="0 0 0"/>
      <geometry>
        <mesh filename="package://human_description/meshes/lowerRightLeg.dae"/>
      </geometry>
      <material name="Blue"/>
    </visual>
    <collision>
      <origin rpy="0 0 0" xyz="0 0 0"/>
      <geometry>
        <mesh filename="package://human_description/meshes/collision/lowerRightLeg.dae"/>
      </geometry>
    </collision>
    <inertial>
      <mass value="8.394054321"/>
      <inertia ixx="0.1879741409375" ixy="0.000000001719205" ixz="-0.00000000509231" iyy="0.1879741525" iyz="-0.00000001780773" izz="0.01166299402353"/>
      <origin xyz="0.0 -0.00029422 -0.20195734"/>
    </inertial>
  </link>
  <joint name="right_foot_x_joint" type="continuous">
    <axis xyz="1 0 0"/>
    <limit effort="15" lower="-1.57" upper="1.57" velocity="5"/>
    <!--    <limit effort="15" lower="-0.8" upper="0.6" velocity="5"/>-->
    <origin rpy="0 0 0" xyz="0 0 -0.52"/>
    <parent link="lower_right_leg_link"/>
    <child link="right_foot_x_link"/>
  </joint>
  <joint name="right_foot_y_joint" type="continuous">
    <axis xyz="0 1 0"/>
    <limit effort="15" lower="-1.57" upper="1.57" velocity="5"/>
    <!--    <limit effort="15" lower="0" upper="0" velocity="5"/>-->
    <origin rpy="0 0 0" xyz="0 0 0"/>
    <parent link="right_foot_x_link"/>
    <child link="right_foot_y_link"/>
  </joint>
  <joint name="right_foot_z_joint" type="continuous">
    <axis xyz="0 0 1"/>
    <!--    <limit effort="15" lower="-0.2" upper="0.2" velocity="5"/>-->
    <limit effort="15" lower="0" upper="0" velocity="5"/>
    <origin rpy="0 0 0" xyz="0 0 0"/>
    <parent link="right_foot_y_link"/>
    <child link="right_foot_z_link"/>
  </joint>
  <link name="right_foot_x_link"/>
  <link name="right_foot_y_link"/>
  <link name="right_foot_z_link">
    <visual>
      <origin rpy="0 0 0" xyz="0 0 0"/>
      <geometry>
        <mesh filename="package://human_description/meshes/rightFoot.dae"/>
      </geometry>
      <material name="Blue"/>
    </visual>
    <collision>
      <origin rpy="0 0 0" xyz="0 0 0"/>
      <geometry>
        <mesh filename="package://human_description/meshes/collision/rightFoot.dae"/>
      </geometry>
    </collision>
    <inertial>
      <mass value="2.24629475115"/>
      <inertia ixx="0.00997119287114" ixy="0.00032381614564" ixz="-0.0000355639042" iyy="0.003252511015625" iyz="0.00137797638426" izz="0.01040399675772"/>
      <origin xyz="0.00160579 0.04884521 -0.0783361"/>
    </inertial>
  </link>
  <joint name="right_foot_endeffector_joint" type="continuous">
    <axis xyz="0 0 1"/>
    <limit effort="15" lower="0" upper="0" velocity="5"/>
    <origin rpy="0 0 0" xyz="0 0 -0.1"/>
    <parent link="right_foot_z_link"/>
    <child link="right_foot_endeffector_link"/>
  </joint>
  <link name="right_foot_endeffector_link">
    <visual>
      <origin rpy="0 0 0" xyz="0 0 0"/>
      <geometry>
        <box size="0.001 0.001 0.001"/>
      </geometry>
      <material name="Blue"/>
    </visual>
  </link>
  <joint name="upper_left_arm_z_joint" type="continuous">
    <axis xyz="0 0 1"/>
    <limit effort="15" lower="-0.5" upper="0.5" velocity="5"/>
    <origin rpy="0 0 0" xyz="-0.23 0 0.33"/>
    <parent link="torso_x_link"/>
    <child link="upper_left_arm_z_link"/>
  </joint>
  <joint name="upper_left_arm_y_joint" type="continuous">
    <axis xyz="0 1 0"/>
    <limit effort="15" lower="0.0" upper="3.14" velocity="5"/>
    <origin rpy="0 0 0" xyz="0 0 0"/>
    <parent link="upper_left_arm_z_link"/>
    <child link="upper_left_arm_y_link"/>
  </joint>
  <joint name="upper_left_arm_x_joint" type="continuous">
    <axis xyz="1 0 0"/>
    <limit effort="15" lower="-1.0" upper="3.14" velocity="5"/>
    <origin rpy="0 0 0" xyz="0 0 0"/>
    <parent link="upper_left_arm_y_link"/>
    <child link="upper_left_arm_x_link"/>
  </joint>
  <link name="upper_left_arm_z_link"/>
  <link name="upper_left_arm_y_link"/>
  <link name="upper_left_arm_x_link">
    <visual>
      <origin rpy="0 0 0" xyz="0 0 0"/>
      <geometry>
        <mesh filename="package://human_description/meshes/upperLeftArm.dae"/>
      </geometry>
      <material name="Blue"/>
    </visual>
    <collision>
      <origin rpy="0 0 0" xyz="0 0 0"/>
      <geometry>
        <mesh filename="package://human_description/meshes/collision/upperLeftArm.dae"/>
      </geometry>
    </collision>
    <inertial>
      <mass value="5.0428574576"/>
      <inertia ixx="0.05868383265625" ixy="-0.0000000925777" ixz="-0.00160419461921" iyy="0.05870381265625" iyz="-0.000002301658445" izz="0.006071859706985"/>
      <origin xyz="-0.00338773 -0.00000063 -0.17172602"/>
    </inertial>
  </link>
  <joint name="lower_left_arm_joint" type="continuous">
    <axis xyz="1 0 0"/>
    <limit effort="15" lower="0" upper="3.14" velocity="5"/>
    <origin rpy="0 0 0" xyz="0 0 -0.35"/>
    <parent link="upper_left_arm_x_link"/>
    <child link="lower_left_arm_link"/>
  </joint>
  <link name="lower_left_arm_link">
    <visual>
      <origin rpy="0 0 0" xyz="0 0 0"/>
      <geometry>
        <mesh filename="package://human_description/meshes/lowerLeftArm.dae"/>
      </geometry>
      <material name="Blue"/>
    </visual>
    <collision>
      <origin rpy="0 0 0" xyz="0 0 0"/>
      <geometry>
        <mesh filename="package://human_description/meshes/collision/lowerLeftArm.dae"/>
      </geometry>
    </collision>
    <inertial>
      <mass value="4.1174112191"/>
      <inertia ixx="0.046870596953125" ixy="-0.000000000013135" ixz="0.00000000291116" iyy="0.0468705940625" iyz="-0.00000000721685" izz="0.00412573450193"/>
      <origin xyz="0.0 0.00000002 -0.14231966"/>
    </inertial>
  </link>
  <joint name="left_hand_z_joint" type="continuous">
    <axis xyz="0 0 1"/>
    <limit effort="15" lower="-1.0" upper="1.0" velocity="5"/>
    <origin rpy="0 0 0" xyz="0 0 -0.35"/>
    <parent link="lower_left_arm_link"/>
    <child link="left_hand_z_link"/>
  </joint>
  <joint name="left_hand_y_joint" type="continuous">
    <axis xyz="0 1 0"/>
    <limit effort="15" lower="-1.3" upper="1.5" velocity="5"/>
    <origin rpy="0 0 0" xyz="0 0 0"/>
    <parent link="left_hand_z_link"/>
    <child link="left_hand_y_link"/>
  </joint>
  <joint name="left_hand_x_joint" type="continuous">
    <axis xyz="1 0 0"/>
    <limit effort="15" lower="-0.5" upper="1.4" velocity="5"/>
    <origin rpy="0 0 0" xyz="0 0 0"/>
    <parent link="left_hand_y_link"/>
    <child link="left_hand_x_link"/>
  </joint>
  <link name="left_hand_z_link"/>
  <link name="left_hand_y_link"/>
  <link name="left_hand_x_link">
    <visual>
      <!--      <origin rpy="0 1.57 -1.57" xyz="0 0 0"/>-->
      <origin rpy="0 0 0" xyz="0 0 0"/>
      <geometry>
        <mesh filename="package://human_description/meshes/leftHand.dae"/>
      </geometry>
      <material name="Blue"/>
    </visual>
    <collision>
      <!--      <origin rpy="0 1.57 -1.57" xyz="0 0 0"/>-->
      <origin rpy="0 0 0" xyz="0 0 0"/>
      <geometry>
        <mesh filename="package://human_description/meshes/collision/leftHand.dae"/>
      </geometry>
    </collision>
    <inertial>
      <mass value="0.5669499677"/>
      <inertia ixx="0.00201160057137" ixy="-0.000016142435665" ixz="-0.00000510135428" iyy="0.00161538206057" iyz="0.00004737239241" izz="0.00044905660648"/>
      <origin xyz="-0.00417106 0.0042704 -0.05959476"/>
    </inertial>
  </link>
  <joint name="left_hand_endeffector_joint" type="continuous">
    <axis xyz="0 0 1"/>
    <limit effort="15" lower="-0.001" upper="0.001" velocity="5"/>
    <origin rpy="0 0 0" xyz="0 0 0"/>
    <parent link="left_hand_x_link"/>
    <child link="left_hand_endeffector_link"/>
  </joint>
  <link name="left_hand_endeffector_link">
    <visual>
      <origin rpy="0 0 0" xyz="0 0 0"/>
      <geometry>
        <box size="0.001 0.001 0.001"/>
      </geometry>
      <material name="Blue"/>
    </visual>
    <collision>
      <origin rpy="0 0 0" xyz="0 0 0"/>
      <geometry>
        <box size="0.001 0.001 0.001"/>
      </geometry>
    </collision>
  </link>
  <joint name="upper_right_arm_z_joint" type="continuous">
    <axis xyz="0 0 1"/>
    <limit effort="15" lower="-0.5" upper="0.5" velocity="5"/>
    <origin rpy="0 0 0" xyz="0.23 0 0.33"/>
    <parent link="torso_x_link"/>
    <child link="upper_right_arm_z_link"/>
  </joint>
  <joint name="upper_right_arm_y_joint" type="continuous">
    <axis xyz="0 1 0"/>
    <limit effort="15" lower="-3.14" upper="0.0" velocity="5"/>
    <origin rpy="0 0 0" xyz="0 0 0"/>
    <parent link="upper_right_arm_z_link"/>
    <child link="upper_right_arm_y_link"/>
  </joint>
  <joint name="upper_right_arm_x_joint" type="continuous">
    <axis xyz="1 0 0"/>
    <limit effort="15" lower="-1.0" upper="3.14" velocity="5"/>
    <origin rpy="0 0 0" xyz="0 0 0"/>
    <parent link="upper_right_arm_y_link"/>
    <child link="upper_right_arm_x_link"/>
  </joint>
  <link name="upper_right_arm_z_link"/>
  <link name="upper_right_arm_y_link"/>
  <link name="upper_right_arm_x_link">
    <visual>
      <origin rpy="0 0 0" xyz="0 0 0"/>
      <geometry>
        <mesh filename="package://human_description/meshes/upperRightArm.dae"/>
      </geometry>
      <material name="Blue"/>
    </visual>
    <collision>
      <origin rpy="0 0 0" xyz="0 0 0"/>
      <geometry>
        <mesh filename="package://human_description/meshes/collision/upperRightArm.dae"/>
      </geometry>
    </collision>
    <inertial>
      <mass value="5.0428574576"/>
      <inertia ixx="0.05868383265625" ixy="0.00000009260175" ixz="0.00160419479977" iyy="0.05870381265625" iyz="-0.000002301500825" izz="0.006071859706985"/>
      <origin xyz="0.00338773 -0.00000063 -0.17172602"/>
    </inertial>
  </link>
  <joint name="lower_right_arm_joint" type="continuous">
    <axis xyz="1 0 0"/>
    <limit effort="15" lower="0" upper="3.14" velocity="5"/>
    <origin rpy="0 0 0" xyz="0 0 -0.35"/>
    <parent link="upper_right_arm_x_link"/>
    <child link="lower_right_arm_link"/>
  </joint>
  <link name="lower_right_arm_link">
    <visual>
      <origin rpy="0 0 0" xyz="0 0 0"/>
      <geometry>
        <mesh filename="package://human_description/meshes/lowerRightArm.dae"/>
      </geometry>
      <material name="Blue"/>
    </visual>
    <collision>
      <origin rpy="0 0 0" xyz="0 0 0"/>
      <geometry>
        <mesh filename="package://human_description/meshes/collision/lowerRightArm.dae"/>
      </geometry>
    </collision>
    <inertial>
      <mass value="4.1174112191"/>
      <inertia ixx="0.046870596953125" ixy="-0.000000000013135" ixz="0.00000000291116" iyy="0.0468705940625" iyz="-0.00000000721685" izz="0.00412573450193"/>
      <origin xyz="0.0 0.00000002 -0.14231966"/>
    </inertial>
  </link>
  <joint name="right_hand_z_joint" type="continuous">
    <axis xyz="0 0 1"/>
    <limit effort="15" lower="-1.0" upper="1.0" velocity="5"/>
    <origin rpy="0 0 0" xyz="0 0 -0.35"/>
    <parent link="lower_right_arm_link"/>
    <child link="right_hand_z_link"/>
  </joint>
  <joint name="right_hand_y_joint" type="continuous">
    <axis xyz="0 1 0"/>
    <limit effort="15" lower="-1.5" upper="1.3" velocity="5"/>
    <origin rpy="0 0 0" xyz="0 0 0"/>
    <parent link="right_hand_z_link"/>
    <child link="right_hand_y_link"/>
  </joint>
  <joint name="right_hand_x_joint" type="continuous">
    <axis xyz="1 0 0"/>
    <limit effort="15" lower="-0.5" upper="1.4" velocity="5"/>
    <origin rpy="0 0 0" xyz="0 0 0"/>
    <parent link="right_hand_y_link"/>
    <child link="right_hand_x_link"/>
  </joint>
  <link name="right_hand_z_link"/>
  <link name="right_hand_y_link"/>
  <link name="right_hand_x_link">
    <visual>
      <!--      <origin rpy="0 -1.57 1.57" xyz="0 0 0"/>-->
      <origin rpy="0 0 0" xyz="0 0 0"/>
      <geometry>
        <mesh filename="package://human_description/meshes/rightHand.dae"/>
      </geometry>
      <material name="Blue"/>
    </visual>
    <collision>
      <!--      <origin rpy="0 -1.57 1.57" xyz="0 0 0"/>-->
      <origin rpy="0 0 0" xyz="0 0 0"/>
      <geometry>
        <mesh filename="package://human_description/meshes/collision/rightHand.dae"/>
      </geometry>
    </collision>
    <inertial>
      <mass value="0.5669499677"/>
      <inertia ixx="0.00201160057137" ixy="0.000016142435665" ixz="0.00000510133208" iyy="0.00161538206057" iyz="0.00004737239241" izz="0.00044905660648"/>
      <origin xyz="0.00417106 0.0042704 -0.05959476"/>
    </inertial>
  </link>
  <joint name="right_hand_endeffector_joint" type="continuous">
    <axis xyz="0 0 1"/>
    <limit effort="15" lower="-0.001" upper="0.001" velocity="5"/>
    <origin rpy="0 0 0" xyz="0 0 0"/>
    <parent link="right_hand_x_link"/>
    <child link="right_hand_endeffector_link"/>
  </joint>
  <link name="right_hand_endeffector_link">
    <visual>
      <origin rpy="0 0 0" xyz="0 0 0"/>
      <geometry>
        <box size="0.001 0.001 0.001"/>
      </geometry>
      <material name="Blue"/>
    </visual>
    <collision>
      <origin rpy="0 0 0" xyz="0 0 0"/>
      <geometry>
        <box size="0.001 0.001 0.001"/>
      </geometry>
    </collision>
  </link>
  <!--
  <link name="right_hand_object_link">
    <visual>
      <origin rpy="0 0 0" xyz="0.5 0.065 -1.6"/>
      <geometry>
        <mesh filename="package://move_itomp/meshes/door.dae"/>
      </geometry>
      <material name="Blue"/>
    </visual>
    <collision>
      <origin rpy="0 0 0" xyz="0.5 0.065 -1.6"/>
      <geometry>
        <box size="0.001 0.001 0.001"/>
      </geometry>
    </collision>
  </link>
  <joint name="door_joint" type="fixed">
    <origin rpy="3.141592 0 -1.570796" xyz="0 0 0"/>
    <parent link="right_hand_endeffector_link"/>
    <child link="right_hand_object_link"/>
  </joint>
-->
  <!--
  <link name="right_hand_object_link">
    <visual>
      <origin rpy="0 0 0" xyz="3.1245 -5.3 -1.0819"/>
      <geometry>
        <mesh filename="package://move_itomp/meshes/drawer2.dae"/>
      </geometry>
      <material name="Blue"/>
    </visual>
    <collision>
      <origin rpy="0 0 0" xyz="3.1245 -5.3 -1.0819"/>
      <geometry>
	<mesh filename="package://move_itomp/meshes/drawer2.dae"/>
      </geometry>
    </collision>
  </link>
  <link name="drawer_dummy"/>
  <joint name="drawer_joint" type="fixed">
    <origin rpy="0 -2.468985 0" xyz="0 0 0"/>
    <parent link="drawer_dummy"/>
    <child link="right_hand_object_link"/>
  </joint>
  <joint name="drawer_joint2" type="fixed">
    <origin rpy="0 0 0" xyz="0 0 0"/>
    <parent link="right_hand_endeffector_link"/>
    <child link="drawer_dummy"/>
  </joint>
-->
</robot>

