<?xml version="1.0"?>
<robot xmlns:sensor="http://playerstage.sourceforge.net/gazebo/xmlschema/#sensor"
       xmlns:controller="http://playerstage.sourceforge.net/gazebo/xmlschema/#controller"
       xmlns:interface="http://playerstage.sourceforge.net/gazebo/xmlschema/#interface"
       xmlns:xacro="http://playerstage.sourceforge.net/gazebo/xmlschema/#interface"
       name="rocketbox_male" >

  <material name="Blue">
    <color rgba="0.0 0.0 0.8 1.0"/>
  </material>
  <material name="Green">
    <color rgba="0.0 0.8 0.0 1.0"/>
  </material>
  <material name="Grey">
    <color rgba="0.7 0.7 0.7 1.0"/>
  </material>
  <material name="Grey2">
    <color rgba="0.9 0.9 0.9 1.0"/>
  </material>
  <material name="Red">
    <color rgba="0.8 0.0 0.0 1.0"/>
  </material>
  <material name="White">
    <color rgba="1.0 1.0 1.0 1.0"/>
  </material>
  <material name="Black">
    <color rgba="0.1 0.1 0.1 1.0"/>
  </material>
  <material name="LightGrey">
    <color rgba="0.6 0.6 0.6 1.0"/>
  </material>


  <link name="root_link"/>

  <joint name="root_dummy_joint" type="fixed">
    <parent link="root_link"/>
    <child link="pelvis_link"/>
  </joint>

  <link name="pelvis_link"/> 

  <joint name="pelvis1_z_joint" type="revolute">
    <axis xyz="0 0 1"/>
    <limit effort="15" lower="0" upper="0" velocity="5"/>
    <origin rpy="0 0 0" xyz="0 0.001956 0.144312"/>
    <parent link="pelvis_link"/>
    <child link="pelvis1_z_link"/>
  </joint>
  <joint name="pelvis1_y_joint" type="revolute">
    <axis xyz="0 1 0"/>
    <limit effort="15" lower="0" upper="0" velocity="5"/>
    <origin rpy="0 0 0" xyz="0 0 0"/>
    <parent link="pelvis1_z_link"/>
    <child link="pelvis1_y_link"/>
  </joint>
  <joint name="pelvis1_x_joint" type="revolute">
    <axis xyz="1 0 0"/>
    <limit effort="15" lower="0" upper="0" velocity="5"/>
    <origin rpy="0 0 0" xyz="0 0 0"/>
    <parent link="pelvis1_y_link"/>
    <child link="pelvis1_x_link"/>
  </joint>  
	  
  <link name="pelvis1_z_link"/>
  <link name="pelvis1_y_link"/>
  <link name="pelvis1_x_link"/>
	  
  <joint name="torso_z_joint" type="revolute">
    <axis xyz="0 0 1"/>
    <limit effort="15" lower="-0.7" upper="0.7" velocity="5"/>
    <origin rpy="0 0 0" xyz="0 0.008328 0.183624"/>
    <parent link="pelvis1_x_link"/>
    <child link="torso_z_link"/>
  </joint>
  <joint name="torso_y_joint" type="revolute">
    <axis xyz="0 1 0"/>
    <limit effort="15" lower="-0.3" upper="0.3" velocity="5"/>
    <origin rpy="0 0 0" xyz="0 0 0"/>
    <parent link="torso_z_link"/>
    <child link="torso_y_link"/>
  </joint>
  <joint name="torso_x_joint" type="revolute">
    <axis xyz="1 0 0"/>
    <limit effort="15" lower="-1.0" upper="0" velocity="5"/>
    <origin rpy="0 0 0" xyz="0 0 0"/>
    <parent link="torso_y_link"/>
    <child link="torso_x_link"/>
  </joint>  

  <link name="torso_z_link"/>
  <link name="torso_y_link"/>
  <link name="torso_x_link">
    <visual>
      <origin rpy="0 0 0" xyz="0 0 0"/>
      <geometry>
        <mesh filename="package://human_description/meshes/rocket_box/torso.obj"/>
      </geometry>
      <material name="Blue"/>
    </visual>
    <collision>
      <origin rpy="0 0 0" xyz="0 0 0"/>
      <geometry>
        <mesh filename="package://human_description/meshes/rocket_box/torso.obj"/>
      </geometry>
    </collision>
  </link>

<joint name="torso2_z_joint" type="revolute">
    <axis xyz="0 0 1"/>
    <limit effort="15" lower="0" upper="0" velocity="5"/>
    <origin rpy="0 0 0" xyz="0 0.013344 0.183324"/>
    <parent link="torso_x_link"/>
    <child link="torso2_z_link"/>
  </joint>
  <joint name="torso2_y_joint" type="revolute">
    <axis xyz="0 1 0"/>
    <limit effort="15" llower="0" upper="0" velocity="5"/>
    <origin rpy="0 0 0" xyz="0 0 0"/>
    <parent link="torso2_z_link"/>
    <child link="torso2_y_link"/>
  </joint>
  <joint name="torso2_x_joint" type="revolute">
    <axis xyz="1 0 0"/>
    <limit effort="15" lower="0" upper="0" velocity="5"/>
    <origin rpy="0 0 0" xyz="0 0 0"/>
    <parent link="torso2_y_link"/>
    <child link="torso2_x_link"/>
  </joint>

  <link name="torso2_z_link"/>
  <link name="torso2_y_link"/>
  <link name="torso2_x_link"/>
  
  
<joint name="torso3_z_joint" type="revolute">
    <axis xyz="0 0 1"/>
    <limit effort="15" lower="0" upper="0" velocity="5"/>
    <origin rpy="0 0 0" xyz="0 -0.009012 0.239532"/>
    <parent link="torso2_x_link"/>
    <child link="torso3_z_link"/>
  </joint>
  <joint name="torso3_y_joint" type="revolute">
    <axis xyz="0 1 0"/>
    <limit effort="15" lower="0" upper="0" velocity="5"/>
    <origin rpy="0 0 0" xyz="0 0 0"/>
    <parent link="torso3_z_link"/>
    <child link="torso3_y_link"/>
  </joint>
  <joint name="torso3_x_joint" type="revolute">
    <axis xyz="1 0 0"/>
    <limit effort="15" lower="0" upper="0" velocity="5"/>
    <origin rpy="0 0 0" xyz="0 0 0"/>
    <parent link="torso3_y_link"/>
    <child link="torso3_x_link"/>
  </joint>

  <link name="torso3_z_link"/>
  <link name="torso3_y_link"/>
  <link name="torso3_x_link"/>


  <joint name="head_z_joint" type="revolute">
    <axis xyz="0 0 1"/>
    <limit effort="15" lower="-1.2" upper="1.2" velocity="5"/>
    <origin rpy="0 0 0" xyz="0 -0.024384 0.079464"/>
    <parent link="torso3_x_link"/>
    <child link="head_z_link"/>
  </joint>
  <joint name="head_y_joint" type="revolute">
    <axis xyz="0 1 0"/>
    <limit effort="15" lower="-0.8" upper="0.8" velocity="5"/>
    <origin rpy="0 0 0" xyz="0 0 0"/>
    <parent link="head_z_link"/>
    <child link="head_y_link"/>
  </joint>
  <joint name="head_x_joint" type="revolute">
    <axis xyz="1 0 0"/>
    <limit effort="15" lower="-1.57" upper="0.3" velocity="5"/>
    <origin rpy="0 0 0" xyz="0 0 0"/>
    <parent link="head_y_link"/>
    <child link="head_x_link"/>
  </joint>

  <link name="head_z_link"/>
  <link name="head_y_link"/>
  <link name="head_x_link">
    <visual>
      <origin rpy="0 0 0" xyz="0 0 0"/>
      <geometry>
        <mesh filename="package://human_description/meshes/rocket_box/head.obj"/>
      </geometry>
      <material name="Blue"/>
    </visual>
    <collision>
      <origin rpy="0 0 0" xyz="0 0 0"/>
      <geometry>
        <mesh filename="package://human_description/meshes/rocket_box/head.obj"/>
      </geometry>
    </collision>
  </link>
  
  <joint name="head_endeffector_joint" type="fixed">
    <axis xyz="0 0 1"/>
    <limit effort="15" lower="-0.001" upper="0.001" velocity="5"/>
    <origin rpy="0 0 0" xyz="0 -0.03768 0.246336"/>
    <parent link="head_x_link"/>
    <child link="head_endeffector_link"/>
  </joint>

  <link name="head_endeffector_link">
    <visual>
      <origin rpy="0 0 0" xyz="0 0 0"/>
      <geometry>
        <box size="0.001 0.001 0.001"/>
      </geometry>
      <material name="Blue"/>
    </visual>
    <collision>
      <origin rpy="0 0 0" xyz="0 0 0"/>
      <geometry>
        <box size="0.001 0.001 0.001"/>
      </geometry>
    </collision>
  </link>


  <joint name="upper_left_leg_z_joint" type="revolute">
    <axis xyz="0 0 1"/>
    <limit effort="15" lower="-1.57" upper="1" velocity="5"/>
    <origin rpy="0 0 0" xyz="-0.106044 -0.010284 -0.327936"/>
    <parent link="torso_x_link"/>
    <child link="upper_left_leg_z_link"/>
  </joint>
  <joint name="upper_left_leg_y_joint" type="revolute">
    <axis xyz="0 1 0"/>
    <limit effort="15" lower="-1.57" upper="0.7" velocity="5"/>
    <origin rpy="0 0 0" xyz="0 0 0"/>
    <parent link="upper_left_leg_z_link"/>
    <child link="upper_left_leg_y_link"/>
  </joint>
  <joint name="upper_left_leg_x_joint" type="revolute">
    <axis xyz="1 0 0"/>
    <limit effort="15" lower="-1.2" upper="1.57" velocity="5"/>
    <origin rpy="0 0 0" xyz="0 0 0"/>
    <parent link="upper_left_leg_y_link"/>
    <child link="upper_left_leg_x_link"/>
  </joint>

  <link name="upper_left_leg_z_link"/>
  <link name="upper_left_leg_y_link"/>
  <link name="upper_left_leg_x_link">
    <visual>
      <origin rpy="0 0 0" xyz="0 0 0"/>
      <geometry>
        <mesh filename="package://human_description/meshes/rocket_box/l_lupperleg.obj"/>
      </geometry>
      <material name="Blue"/>
    </visual>
    <collision>
      <origin rpy="0 0 0" xyz="0 0 0"/>
      <geometry>
        <mesh filename="package://human_description/meshes/rocket_box/l_lupperleg.obj"/>
      </geometry>
    </collision>
  </link>

  <joint name="lower_left_leg_joint" type="revolute">
    <axis xyz="1 0 0"/>
    <limit effort="15" lower="-2.4" upper="0" velocity="5"/>
    <origin rpy="0 0 0" xyz="-0.025332 -0.01956 -0.477768"/>
    <parent link="upper_left_leg_x_link"/>
    <child link="lower_left_leg_link"/>
  </joint>

  <link name="lower_left_leg_link">
    <visual>
      <origin rpy="0 0 0" xyz="0 0 0"/>
      <geometry>
        <mesh filename="package://human_description/meshes/rocket_box/l_lowerleg.obj"/>
      </geometry>
      <material name="Blue"/>
    </visual>
    <collision>
      <origin rpy="0 0 0" xyz="0 0 0"/>
      <geometry>
        <mesh filename="package://human_description/meshes/rocket_box/l_lowerleg.obj"/>
      </geometry>
    </collision>
  </link>

  <joint name="left_foot_z_joint" type="revolute">
    <axis xyz="0 0 1"/>
    <limit effort="15" lower="-0.01" upper="0" velocity="5"/>
    <origin rpy="0 0 0" xyz="-0.008988 0.036996 -0.474504"/>
    <parent link="lower_left_leg_link"/>
    <child link="left_foot_z_link"/>
  </joint>
  <joint name="left_foot_y_joint" type="revolute">
    <axis xyz="0 1 0"/>
    <limit effort="15" lower="-0.5" upper="0.5" velocity="5"/>
    <origin rpy="0 0 0" xyz="0 0 0"/>
    <parent link="left_foot_z_link"/>
    <child link="left_foot_y_link"/>
  </joint>
  <joint name="left_foot_x_joint" type="revolute">
    <axis xyz="1 0 0"/>
    <limit effort="15" lower="-0.8" upper="0.6" velocity="5"/>
    <origin rpy="0 0 0" xyz="0 0 0"/>
    <parent link="left_foot_y_link"/>
    <child link="left_foot_x_link"/>
  </joint>

  <link name="left_foot_z_link"/>
  <link name="left_foot_y_link"/>
  <link name="left_foot_x_link">
    <visual>
      <origin rpy="0 0 0" xyz="0 0 0"/>
      <geometry>
        <mesh filename="package://human_description/meshes/rocket_box/l_foot.obj"/>
      </geometry>
      <material name="Blue"/>
    </visual>
    <collision>
      <origin rpy="0 0 0" xyz="0 0 0"/>
      <geometry>
        <mesh filename="package://human_description/meshes/rocket_box/l_foot.obj"/>
      </geometry>
    </collision>
  </link>
	
  <joint name="left_foot2_z_joint" type="revolute">
	<axis xyz="0 0 1"/>
	<limit effort="15" lower="-0" upper="0" velocity="5"/>
	<origin rpy="0 0 0" xyz="-0.040992 -0.160536 -0.119028"/>
	<parent link="left_foot_x_link"/>
	<child link="left_foot2_z_link"/>
  </joint>
  <joint name="left_foot2_y_joint" type="revolute">
    <axis xyz="0 1 0"/>
    <limit effort="15" lower="-0" upper="0" velocity="5"/>
    <origin rpy="0 0 0" xyz="0 0 0"/>
    <parent link="left_foot2_z_link"/>
    <child link="left_foot2_y_link"/>
  </joint>
  <joint name="left_foot2_x_joint" type="revolute">
    <axis xyz="1 0 0"/>
    <limit effort="15" lower="-0" upper="0" velocity="5"/>
    <origin rpy="0 0 0" xyz="0 0 0"/>
    <parent link="left_foot2_y_link"/>
    <child link="left_foot2_x_link"/>
  </joint>
  
  <link name="left_foot2_z_link"/>
  <link name="left_foot2_y_link"/>
  <link name="left_foot2_x_link"/>
	  
  <joint name="left_foot_endeffector_joint" type="fixed">
    <axis xyz="0 0 1"/>
    <limit effort="15" lower="-0.001" upper="0.001" velocity="5"/>
    <origin rpy="0 0 0" xyz="-0.024924 -0.097428 0.001788"/>
    <parent link="left_foot2_x_link"/>
    <child link="left_foot_endeffector_link"/>
  </joint>

  <link name="left_foot_endeffector_link">
    <visual>
      <origin rpy="0 0 0" xyz="0 0 0"/>
      <geometry>
        <box size="0.001 0.001 0.001"/>
      </geometry>
      <material name="Blue"/>
    </visual>
  </link>
  
  

  <joint name="upper_right_leg_z_joint" type="revolute">
    <axis xyz="0 0 1"/>
    <limit effort="15" lower="-1" upper="1.57" velocity="5"/>
    <origin rpy="0 0 0" xyz="0.106044 -0.010284 -0.327924"/>
    <parent link="torso_x_link"/>
    <child link="upper_right_leg_z_link"/>
  </joint>
  <joint name="upper_right_leg_y_joint" type="revolute">
    <axis xyz="0 1 0"/>
    <limit effort="15" lower="-0.7" upper="1.57" velocity="5"/>
    <origin rpy="0 0 0" xyz="0 0 0"/>
    <parent link="upper_right_leg_z_link"/>
    <child link="upper_right_leg_y_link"/>
  </joint>
  <joint name="upper_right_leg_x_joint" type="revolute">
    <axis xyz="1 0 0"/>
    <limit effort="15" lower="-1.2" upper="1.57" velocity="5"/>
    <origin rpy="0 0 0" xyz="0 0 0"/>
    <parent link="upper_right_leg_y_link"/>
    <child link="upper_right_leg_x_link"/>
  </joint>

  <link name="upper_right_leg_z_link"/>
  <link name="upper_right_leg_y_link"/>
  <link name="upper_right_leg_x_link">
    <visual>
      <origin rpy="0 0 0" xyz="0 0 0"/>
      <geometry>
        <mesh filename="package://human_description/meshes/rocket_box/r_upperleg.obj"/>
      </geometry>
      <material name="Blue"/>
    </visual>
    <collision>
      <origin rpy="0 0 0" xyz="0 0 0"/>
      <geometry>
        <mesh filename="package://human_description/meshes/rocket_box/r_upperleg.obj"/>
      </geometry>
    </collision>
  </link>

  <joint name="lower_right_leg_joint" type="revolute">
    <axis xyz="1 0 0"/>
    <limit effort="15" lower="-2.4" upper="0" velocity="5"/>
    <origin rpy="0 0 0" xyz="0.025332 -0.01956 -0.47778"/>
    <parent link="upper_right_leg_x_link"/>
    <child link="lower_right_leg_link"/>
  </joint>

  <link name="lower_right_leg_link">
    <visual>
      <origin rpy="0 0 0" xyz="0 0 0"/>
      <geometry>
        <mesh filename="package://human_description/meshes/rocket_box/r_lowerleg.obj"/>
      </geometry>
      <material name="Blue"/>
    </visual>
    <collision>
      <origin rpy="0 0 0" xyz="0 0 0"/>
      <geometry>
        <mesh filename="package://human_description/meshes/rocket_box/r_lowerleg.obj"/>
      </geometry>
    </collision>
  </link>

  <joint name="right_foot_z_joint" type="revolute">
    <axis xyz="0 0 1"/>
    <limit effort="15" lower="0" upper="0.001" velocity="5"/>
    <origin rpy="0 0 0" xyz="0.008988 0.036996 -0.474504"/>
    <parent link="lower_right_leg_link"/>
    <child link="right_foot_z_link"/>
  </joint>
  <joint name="right_foot_y_joint" type="revolute">
    <axis xyz="0 1 0"/>
    <limit effort="15" lower="-0.5" upper="0.5" velocity="5"/>
    <origin rpy="0 0 0" xyz="0 0 0"/>
    <parent link="right_foot_z_link"/>
    <child link="right_foot_y_link"/>
  </joint>
  <joint name="right_foot_x_joint" type="revolute">
    <axis xyz="1 0 0"/>
    <limit effort="15" lower="-0.8" upper="0.6" velocity="5"/>
    <origin rpy="0 0 0" xyz="0 0 0"/>
    <parent link="right_foot_y_link"/>
    <child link="right_foot_x_link"/>
  </joint>

  <link name="right_foot_z_link"/>
  <link name="right_foot_y_link"/>
  <link name="right_foot_x_link">
    <visual>
      <origin rpy="0 0 0" xyz="0 0 0"/>
      <geometry>
        <mesh filename="package://human_description/meshes/rocket_box/r_foot.obj"/>
      </geometry>
      <material name="Blue"/>
    </visual>
    <collision>
      <origin rpy="0 0 0" xyz="0 0 0"/>
      <geometry>
        <mesh filename="package://human_description/meshes/rocket_box/r_foot.obj"/>
      </geometry>
    </collision>
  </link>
  
  <joint name="right_foot2_z_joint" type="revolute">
	<axis xyz="0 0 1"/>
	<limit effort="15" lower="-0" upper="0" velocity="5"/>
	<origin rpy="0 0 0" xyz="0.040992 -0.160536 -0.119028"/>
	<parent link="right_foot_x_link"/>
	<child link="right_foot2_z_link"/>
  </joint>
  <joint name="right_foot2_y_joint" type="revolute">
    <axis xyz="0 1 0"/>
    <limit effort="15" lower="-0" upper="0" velocity="5"/>
    <origin rpy="0 0 0" xyz="0 0 0"/>
    <parent link="right_foot2_z_link"/>
    <child link="right_foot2_y_link"/>
  </joint>
  <joint name="right_foot2_x_joint" type="revolute">
    <axis xyz="1 0 0"/>
    <limit effort="15" lower="-0" upper="0" velocity="5"/>
    <origin rpy="0 0 0" xyz="0 0 0"/>
    <parent link="right_foot2_y_link"/>
    <child link="right_foot2_x_link"/>
  </joint>
  
  <link name="right_foot2_z_link"/>
  <link name="right_foot2_y_link"/>
  <link name="right_foot2_x_link"/>
	  
  <joint name="right_foot_endeffector_joint" type="fixed">
    <axis xyz="0 0 1"/>
    <limit effort="15" lower="-0.001" upper="0.001" velocity="5"/>
    <origin rpy="0 0 0" xyz="0.024924 -0.097428 0.001776"/>
    <parent link="right_foot2_x_link"/>
    <child link="right_foot_endeffector_link"/>
  </joint>

  <link name="right_foot_endeffector_link">
    <visual>
      <origin rpy="0 0 0" xyz="0 0 0"/>
      <geometry>
        <box size="0.001 0.001 0.001"/>
      </geometry>
      <material name="Blue"/>
    </visual>
  </link>

  <joint name="upper_left_specula_joint" type="revolute">
    <axis xyz="0 0 1"/>
    <limit effort="15" lower="-0" upper="0" velocity="5"/>
    <origin rpy="0 0 0" xyz="-0.0873828 0.0381 -0.153156"/>
    <parent link="head_x_link"/>
    <child link="upper_left_arm_specula_link"/>
  </joint>
  
  <link name="upper_left_arm_specula_link"/>
  
  <joint name="upper_left_arm_z_joint" type="revolute">
    <axis xyz="0 0 1"/>
    <limit effort="15" lower="-0.5" upper="0.5" velocity="5"/>
    <origin rpy="0 0 0" xyz="-0.169296 0 0"/>
    <parent link="upper_left_arm_specula_link"/>
    <child link="upper_left_arm_z_link"/>
  </joint>
  <joint name="upper_left_arm_y_joint" type="revolute">
    <axis xyz="0 1 0"/>
    <limit effort="15" lower="-3.14" upper="2.0" velocity="5"/>
    <origin rpy="0 0 0" xyz="0 0 0"/>
    <parent link="upper_left_arm_z_link"/>
    <child link="upper_left_arm_y_link"/>
  </joint>
  <joint name="upper_left_arm_x_joint" type="revolute">
    <axis xyz="1 0 0"/>
    <limit effort="15" lower="-1.0" upper="3.14" velocity="5"/>
    <origin rpy="0 0 0" xyz="0 0 0"/>
    <parent link="upper_left_arm_y_link"/>
    <child link="upper_left_arm_x_link"/>
  </joint>

  <link name="upper_left_arm_z_link"/>
  <link name="upper_left_arm_y_link"/>
  <link name="upper_left_arm_x_link">
    <visual>
      <origin rpy="0 0 0" xyz="0 0 0"/>
      <geometry>
        <mesh filename="package://human_description/meshes/rocket_box/l_upperarm.obj"/>
      </geometry>
      <material name="Blue"/>
    </visual>
    <collision>
      <origin rpy="0 0 0" xyz="0 0 0"/>
      <geometry>
        <mesh filename="package://human_description/meshes/rocket_box/l_upperarm.obj"/>
      </geometry>
    </collision>
  </link>

  <joint name="lower_left_arm_joint" type="revolute">
    <axis xyz="1 0 0"/>
    <limit effort="15" lower="0" upper="3.14" velocity="5"/>
    <origin rpy="0 0 0" xyz="-0.001464 -0.00114 -0.34296"/>
    <parent link="upper_left_arm_x_link"/>
    <child link="lower_left_arm_link"/>
  </joint>

  <link name="lower_left_arm_link">
    <visual>
      <origin rpy="0 0 0" xyz="0 0 0"/>
      <geometry>
        <mesh filename="package://human_description/meshes/rocket_box/l_forearm.obj"/>
      </geometry>
      <material name="Blue"/>
    </visual>
    <collision>
      <origin rpy="0 0 0" xyz="0 0 0"/>
      <geometry>
        <mesh filename="package://human_description/meshes/rocket_box/l_forearm.obj"/>
      </geometry>
    </collision>
  </link>

  <joint name="left_hand_z_joint" type="revolute">
    <axis xyz="0 0 1"/>
    <limit effort="15" lower="-1.0" upper="1.0" velocity="5"/>
    <origin rpy="0 0 0" xyz="-0.001728 -0.004992 -0.325056"/>
    <parent link="lower_left_arm_link"/>
    <child link="left_hand_z_link"/>
  </joint>
  <joint name="left_hand_y_joint" type="revolute">
    <axis xyz="0 1 0"/>
    <limit effort="15" lower="-1.3" upper="1.5" velocity="5"/>
    <origin rpy="0 0 0" xyz="0 0 0"/>
    <parent link="left_hand_z_link"/>
    <child link="left_hand_y_link"/>
  </joint>
  <joint name="left_hand_x_joint" type="revolute">
    <axis xyz="1 0 0"/>
    <limit effort="15" lower="-0.5" upper="1.4" velocity="5"/>
    <origin rpy="0 0 0" xyz="0 0 0"/>
    <parent link="left_hand_y_link"/>
    <child link="left_hand_x_link"/>
  </joint>

  <link name="left_hand_z_link"/>
  <link name="left_hand_y_link"/>
  <link name="left_hand_x_link">
    <visual>
      <origin rpy="0 0 0" xyz="0 0 0"/>
      <geometry>
        <mesh filename="package://human_description/meshes/rocket_box/l_hand.obj"/>
      </geometry>
      <material name="Blue"/>
    </visual>
    <collision>
      <origin rpy="0 0 0" xyz="0 0 0"/>
      <geometry>
        <mesh filename="package://human_description/meshes/rocket_box/l_hand.obj"/>
      </geometry>
    </collision>
  </link>

  <joint name="left_hand_endeffector_joint" type="revolute">
    <axis xyz="0 0 1"/>
    <limit effort="15" lower="-0.001" upper="0.001" velocity="5"/>
    <origin rpy="0 0 0" xyz="-0.009816 0.007404 -0.21684"/>
    <parent link="left_hand_x_link"/>
    <child link="left_hand_endeffector_link"/>
  </joint>

  <link name="left_hand_endeffector_link">
    <visual>
      <origin rpy="0 0 0" xyz="0 0 0"/>
      <geometry>
        <box size="0.001 0.001 0.001"/>
      </geometry>
      <material name="Blue"/>
    </visual>
    <collision>
      <origin rpy="0 0 0" xyz="0 0 0"/>
      <geometry>
        <box size="0.001 0.001 0.001"/>
      </geometry>
    </collision>
  </link>

  
  <joint name="upper_right_specula_joint" type="revolute">
    <axis xyz="1 0 0"/>
    <limit effort="15" lower="-0" upper="0" velocity="5"/>
    <origin rpy="0 0 0" xyz="0.0873852 0.0381 -0.153312"/>
    <parent link="head_x_link"/>
    <child link="upper_right_arm_specula_link"/>
  </joint>
    
  <link name="upper_right_arm_specula_link"/>
  
  <joint name="upper_right_arm_z_joint" type="revolute">
    <axis xyz="0 0 1"/>
    <limit effort="15" lower="-0.5" upper="0.5" velocity="5"/>
    <origin rpy="0 0 0" xyz="0.16926 0.003768 -0.0003"/>
    <parent link="upper_right_arm_specula_link"/>
    <child link="upper_right_arm_z_link"/>
  </joint>
  <joint name="upper_right_arm_y_joint" type="revolute">
    <axis xyz="0 1 0"/>
    <limit effort="15" lower="-2.0" upper="3.14" velocity="5"/>
    <origin rpy="0 0 0" xyz="0 0 0"/>
    <parent link="upper_right_arm_z_link"/>
    <child link="upper_right_arm_y_link"/>
  </joint>
  <joint name="upper_right_arm_x_joint" type="revolute">
    <axis xyz="1 0 0"/>
    <limit effort="15" lower="-1.0" upper="3.14" velocity="5"/>
    <origin rpy="0 0 0" xyz="0 0 0"/>
    <parent link="upper_right_arm_y_link"/>
    <child link="upper_right_arm_x_link"/>
  </joint>

  <link name="upper_right_arm_z_link"/>
  <link name="upper_right_arm_y_link"/>
  <link name="upper_right_arm_x_link">
    <visual>
      <origin rpy="0 0 0" xyz="0 0 0"/>
      <geometry>
        <mesh filename="package://human_description/meshes/rocket_box/r_upperarm.obj"/>
      </geometry>
      <material name="Blue"/>
    </visual>
    <collision>
      <origin rpy="0 0 0" xyz="0 0 0"/>
      <geometry>
        <mesh filename="package://human_description/meshes/rocket_box/r_upperarm.obj"/>
      </geometry>
    </collision>
  </link>

  <joint name="lower_right_arm_joint" type="revolute">
    <axis xyz="1 0 0"/>
    <limit effort="15" lower="0" upper="3.14" velocity="5"/>
    <origin rpy="0 0 0" xyz="-0.005592 -0.007404 -0.342828"/>
    <parent link="upper_right_arm_x_link"/>
    <child link="lower_right_arm_link"/>
  </joint>

  <link name="lower_right_arm_link">
    <visual>
      <origin rpy="0 0 0" xyz="0 0 0"/>
      <geometry>
        <mesh filename="package://human_description/meshes/rocket_box/r_forearm.obj"/>
      </geometry>
      <material name="Blue"/>
    </visual>
    <collision>
      <origin rpy="0 0 0" xyz="0 0 0"/>
      <geometry>
        <mesh filename="package://human_description/meshes/rocket_box/r_forearm.obj"/>
      </geometry>
    </collision>
  </link>

  <joint name="right_hand_z_joint" type="revolute">
    <axis xyz="0 0 1"/>
    <limit effort="15" lower="-1.0" upper="1.0" velocity="5"/>
    <origin rpy="0 0 0" xyz="-0.004728 -0.003084 -0.325056"/>
    <parent link="lower_right_arm_link"/>
    <child link="right_hand_z_link"/>
  </joint>
  <joint name="right_hand_y_joint" type="revolute">
    <axis xyz="0 1 0"/>
    <limit effort="15" lower="-1.5" upper="1.3" velocity="5"/>
    <origin rpy="0 0 0" xyz="0 0 0"/>
    <parent link="right_hand_z_link"/>
    <child link="right_hand_y_link"/>
  </joint>
  <joint name="right_hand_x_joint" type="revolute">
    <axis xyz="1 0 0"/>
    <limit effort="15" lower="-0.5" upper="1.4" velocity="5"/>
    <origin rpy="0 0 0" xyz="0 0 0"/>
    <parent link="right_hand_y_link"/>
    <child link="right_hand_x_link"/>
  </joint>

  <link name="right_hand_z_link"/>
  <link name="right_hand_y_link"/>
  <link name="right_hand_x_link">
    <visual>
      <origin rpy="0 0 0" xyz="0 0 0"/>
      <geometry>
        <mesh filename="package://human_description/meshes/rocket_box/r_hand.obj"/>
      </geometry>
      <material name="Blue"/>
    </visual>
    <collision>
      <origin rpy="0 0 0" xyz="0 0 0"/>
      <geometry>
        <mesh filename="package://human_description/meshes/rocket_box/r_hand.obj"/>
      </geometry>
    </collision>
  </link>

  <joint name="right_hand_endeffector_joint" type="revolute">
    <axis xyz="0 0 1"/>
    <limit effort="15" lower="-0.001" upper="0.001" velocity="5"/>
    <origin rpy="0 0 0" xyz="-0.000348 0.010884 -0.21684"/>
    <parent link="right_hand_x_link"/>
    <child link="right_hand_endeffector_link"/>
  </joint>

  <link name="right_hand_endeffector_link">
    <visual>
      <origin rpy="0 0 0" xyz="0 0 0"/>
      <geometry>
        <box size="0.001 0.001 0.001"/>
      </geometry>
      <material name="Blue"/>
    </visual>
    <collision>
      <origin rpy="0 0 0" xyz="0 0 0"/>
      <geometry>
        <box size="0.001 0.001 0.001"/>
      </geometry>
    </collision>
  </link>
  
  
<link name="left_foot_cp_1_link">
    <visual>
      <origin rpy="0 0 0" xyz="0 0 0"/>
      <geometry>
        <box size="0.001 0.001 0.001"/>
      </geometry>
      <material name="Blue"/>
    </visual>
    <inertial>
      <mass value="0"/>
      <inertia ixx="1" ixy="0" ixz="0" iyy="1" iyz="0" izz="0"/>
      <origin xyz="0 0 0"/>
    </inertial>
  </link>
  <link name="left_foot_cp_2_link">
    <visual>
      <origin rpy="0 0 0" xyz="0 0 0"/>
      <geometry>
        <box size="0.001 0.001 0.001"/>
      </geometry>
      <material name="Blue"/>
    </visual>
    <inertial>
      <mass value="0"/>
      <inertia ixx="1" ixy="0" ixz="0" iyy="1" iyz="0" izz="0"/>
      <origin xyz="0 0 0"/>
    </inertial>
  </link>
  <link name="left_foot_cp_3_link">
    <visual>
      <origin rpy="0 0 0" xyz="0 0 0"/>
      <geometry>
        <box size="0.001 0.001 0.001"/>
      </geometry>
      <material name="Blue"/>
    </visual>
    <inertial>
      <mass value="0"/>
      <inertia ixx="1" ixy="0" ixz="0" iyy="1" iyz="0" izz="0"/>
      <origin xyz="0 0 0"/>
    </inertial>
  </link>
  <link name="left_foot_cp_4_link">
    <visual>
      <origin rpy="0 0 0" xyz="0 0 0"/>
      <geometry>
        <box size="0.001 0.001 0.001"/>
      </geometry>
      <material name="Blue"/>
    </visual>
    <inertial>
      <mass value="0"/>
      <inertia ixx="1" ixy="0" ixz="0" iyy="1" iyz="0" izz="0"/>
      <origin xyz="0 0 0"/>
    </inertial>
  </link>
  <joint name="left_foot_cp_1_joint" type="revolute">
    <axis xyz="0 0 1"/>
    <limit effort="15" lower="0" upper="0" velocity="5"/>
    <origin rpy="0 0 0" xyz="-0.05 -0.05 -0.1"/>
    <parent link="left_foot2_x_link"/>
    <child link="left_foot_cp_1_link"/>
  </joint>
  <joint name="left_foot_cp_2_joint" type="revolute">
    <axis xyz="0 0 1"/>
    <limit effort="15" lower="0" upper="0" velocity="5"/>
    <origin rpy="0 0 0" xyz="0.05 -0.05 -0.1"/>
    <parent link="left_foot2_x_link"/>
    <child link="left_foot_cp_2_link"/>
  </joint>
  <joint name="left_foot_cp_3_joint" type="revolute">
    <axis xyz="0 0 1"/>
    <limit effort="15" lower="0" upper="0" velocity="5"/>
    <origin rpy="0 0 0" xyz="0.05 0.2 -0.1"/>
    <parent link="left_foot2_x_link"/>
    <child link="left_foot_cp_3_link"/>
  </joint>
  <joint name="left_foot_cp_4_joint" type="revolute">
    <axis xyz="0 0 1"/>
    <limit effort="15" lower="0" upper="0" velocity="5"/>
    <origin rpy="0 0 0" xyz="-0.05 0.2 -0.1"/>
    <parent link="left_foot2_x_link"/>
    <child link="left_foot_cp_4_link"/>
  </joint>
<link name="right_foot_cp_1_link">
    <visual>
      <origin rpy="0 0 0" xyz="0 0 0"/>
      <geometry>
        <box size="0.001 0.001 0.001"/>
      </geometry>
      <material name="Blue"/>
    </visual>
    <inertial>
      <mass value="0"/>
      <inertia ixx="1" ixy="0" ixz="0" iyy="1" iyz="0" izz="0"/>
      <origin xyz="0 0 0"/>
    </inertial>
  </link>
  <link name="right_foot_cp_2_link">
    <visual>
      <origin rpy="0 0 0" xyz="0 0 0"/>
      <geometry>
        <box size="0.001 0.001 0.001"/>
      </geometry>
      <material name="Blue"/>
    </visual>
    <inertial>
      <mass value="0"/>
      <inertia ixx="1" ixy="0" ixz="0" iyy="1" iyz="0" izz="0"/>
      <origin xyz="0 0 0"/>
    </inertial>
  </link>
  <link name="right_foot_cp_3_link">
    <visual>
      <origin rpy="0 0 0" xyz="0 0 0"/>
      <geometry>
        <box size="0.001 0.001 0.001"/>
      </geometry>
      <material name="Blue"/>
    </visual>
    <inertial>
      <mass value="0"/>
      <inertia ixx="1" ixy="0" ixz="0" iyy="1" iyz="0" izz="0"/>
      <origin xyz="0 0 0"/>
    </inertial>
  </link>
  <link name="right_foot_cp_4_link">
    <visual>
      <origin rpy="0 0 0" xyz="0 0 0"/>
      <geometry>
        <box size="0.001 0.001 0.001"/>
      </geometry>
      <material name="Blue"/>
    </visual>
    <inertial>
      <mass value="0"/>
      <inertia ixx="1" ixy="0" ixz="0" iyy="1" iyz="0" izz="0"/>
      <origin xyz="0 0 0"/>
    </inertial>
  </link>
  <joint name="right_foot_cp_1_joint" type="revolute">
    <axis xyz="0 0 1"/>
    <limit effort="15" lower="0" upper="0" velocity="5"/>
    <origin rpy="0 0 0" xyz="-0.05 -0.05 -0.1"/>
    <parent link="right_foot2_x_link"/>
    <child link="right_foot_cp_1_link"/>
  </joint>
  <joint name="right_foot_cp_2_joint" type="revolute">
    <axis xyz="0 0 1"/>
    <limit effort="15" lower="0" upper="0" velocity="5"/>
    <origin rpy="0 0 0" xyz="0.05 -0.05 -0.1"/>
    <parent link="right_foot2_x_link"/>
    <child link="right_foot_cp_2_link"/>
  </joint>
  <joint name="right_foot_cp_3_joint" type="revolute">
    <axis xyz="0 0 1"/>
    <limit effort="15" lower="0" upper="0" velocity="5"/>
    <origin rpy="0 0 0" xyz="0.05 0.2 -0.1"/>
    <parent link="right_foot2_x_link"/>
    <child link="right_foot_cp_3_link"/>
  </joint>
  <joint name="right_foot_cp_4_joint" type="revolute">
    <axis xyz="0 0 1"/>
    <limit effort="15" lower="0" upper="0" velocity="5"/>
    <origin rpy="0 0 0" xyz="-0.05 0.2 -0.1"/>
    <parent link="right_foot2_x_link"/>
    <child link="right_foot_cp_4_link"/>
  </joint>

<link name="left_hand_cp_1_link">
    <visual>
      <origin rpy="0 0 0" xyz="0 0 0"/>
      <geometry>
        <box size="0.001 0.001 0.001"/>
      </geometry>
      <material name="Blue"/>
    </visual>
    <inertial>
      <mass value="0"/>
      <inertia ixx="1" ixy="0" ixz="0" iyy="1" iyz="0" izz="0"/>
      <origin xyz="0 0 0"/>
    </inertial>
  </link>
  <link name="left_hand_cp_2_link">
    <visual>
      <origin rpy="0 0 0" xyz="0 0 0"/>
      <geometry>
        <box size="0.001 0.001 0.001"/>
      </geometry>
      <material name="Blue"/>
    </visual>
    <inertial>
      <mass value="0"/>
      <inertia ixx="1" ixy="0" ixz="0" iyy="1" iyz="0" izz="0"/>
      <origin xyz="0 0 0"/>
    </inertial>
  </link>
  <link name="left_hand_cp_3_link">
    <visual>
      <origin rpy="0 0 0" xyz="0 0 0"/>
      <geometry>
        <box size="0.001 0.001 0.001"/>
      </geometry>
      <material name="Blue"/>
    </visual>
    <inertial>
      <mass value="0"/>
      <inertia ixx="1" ixy="0" ixz="0" iyy="1" iyz="0" izz="0"/>
      <origin xyz="0 0 0"/>
    </inertial>
  </link>
  <link name="left_hand_cp_4_link">
    <visual>
      <origin rpy="0 0 0" xyz="0 0 0"/>
      <geometry>
        <box size="0.001 0.001 0.001"/>
      </geometry>
      <material name="Blue"/>
    </visual>
    <inertial>
      <mass value="0"/>
      <inertia ixx="1" ixy="0" ixz="0" iyy="1" iyz="0" izz="0"/>
      <origin xyz="0 0 0"/>
    </inertial>
  </link>
  <joint name="left_hand_cp_1_joint" type="revolute">
    <axis xyz="0 0 1"/>
    <limit effort="15" lower="0" upper="0" velocity="5"/>
    <origin rpy="0 0 0" xyz="-0.05 -0.05 -0.1"/>
    <parent link="left_hand_x_link"/>
    <child link="left_hand_cp_1_link"/>
  </joint>
  <joint name="left_hand_cp_2_joint" type="revolute">
    <axis xyz="0 0 1"/>
    <limit effort="15" lower="0" upper="0" velocity="5"/>
    <origin rpy="0 0 0" xyz="0.05 -0.05 -0.1"/>
    <parent link="left_hand_x_link"/>
    <child link="left_hand_cp_2_link"/>
  </joint>
  <joint name="left_hand_cp_3_joint" type="revolute">
    <axis xyz="0 0 1"/>
    <limit effort="15" lower="0" upper="0" velocity="5"/>
    <origin rpy="0 0 0" xyz="0.05 0.2 -0.1"/>
    <parent link="left_hand_x_link"/>
    <child link="left_hand_cp_3_link"/>
  </joint>
  <joint name="left_hand_cp_4_joint" type="revolute">
    <axis xyz="0 0 1"/>
    <limit effort="15" lower="0" upper="0" velocity="5"/>
    <origin rpy="0 0 0" xyz="-0.05 0.2 -0.1"/>
    <parent link="left_hand_x_link"/>
    <child link="left_hand_cp_4_link"/>
  </joint>
<link name="right_hand_cp_1_link">
    <visual>
      <origin rpy="0 0 0" xyz="0 0 0"/>
      <geometry>
        <box size="0.001 0.001 0.001"/>
      </geometry>
      <material name="Blue"/>
    </visual>
    <inertial>
      <mass value="0"/>
      <inertia ixx="1" ixy="0" ixz="0" iyy="1" iyz="0" izz="0"/>
      <origin xyz="0 0 0"/>
    </inertial>
  </link>
  <link name="right_hand_cp_2_link">
    <visual>
      <origin rpy="0 0 0" xyz="0 0 0"/>
      <geometry>
        <box size="0.001 0.001 0.001"/>
      </geometry>
      <material name="Blue"/>
    </visual>
    <inertial>
      <mass value="0"/>
      <inertia ixx="1" ixy="0" ixz="0" iyy="1" iyz="0" izz="0"/>
      <origin xyz="0 0 0"/>
    </inertial>
  </link>
  <link name="right_hand_cp_3_link">
    <visual>
      <origin rpy="0 0 0" xyz="0 0 0"/>
      <geometry>
        <box size="0.001 0.001 0.001"/>
      </geometry>
      <material name="Blue"/>
    </visual>
    <inertial>
      <mass value="0"/>
      <inertia ixx="1" ixy="0" ixz="0" iyy="1" iyz="0" izz="0"/>
      <origin xyz="0 0 0"/>
    </inertial>
  </link>
  <link name="right_hand_cp_4_link">
    <visual>
      <origin rpy="0 0 0" xyz="0 0 0"/>
      <geometry>
        <box size="0.001 0.001 0.001"/>
      </geometry>
      <material name="Blue"/>
    </visual>
    <inertial>
      <mass value="0"/>
      <inertia ixx="1" ixy="0" ixz="0" iyy="1" iyz="0" izz="0"/>
      <origin xyz="0 0 0"/>
    </inertial>
  </link>
  <joint name="right_hand_cp_1_joint" type="revolute">
    <axis xyz="0 0 1"/>
    <limit effort="15" lower="0" upper="0" velocity="5"/>
    <origin rpy="0 0 0" xyz="-0.05 -0.05 -0.1"/>
    <parent link="right_hand_x_link"/>
    <child link="right_hand_cp_1_link"/>
  </joint>
  <joint name="right_hand_cp_2_joint" type="revolute">
    <axis xyz="0 0 1"/>
    <limit effort="15" lower="0" upper="0" velocity="5"/>
    <origin rpy="0 0 0" xyz="0.05 -0.05 -0.1"/>
    <parent link="right_hand_x_link"/>
    <child link="right_hand_cp_2_link"/>
  </joint>
  <joint name="right_hand_cp_3_joint" type="revolute">
    <axis xyz="0 0 1"/>
    <limit effort="15" lower="0" upper="0" velocity="5"/>
    <origin rpy="0 0 0" xyz="0.05 0.2 -0.1"/>
    <parent link="right_hand_x_link"/>
    <child link="right_hand_cp_3_link"/>
  </joint>
  <joint name="right_hand_cp_4_joint" type="revolute">
    <axis xyz="0 0 1"/>
    <limit effort="15" lower="0" upper="0" velocity="5"/>
    <origin rpy="0 0 0" xyz="-0.05 0.2 -0.1"/>
    <parent link="right_hand_x_link"/>
    <child link="right_hand_cp_4_link"/>
  </joint>

</robot>

