<?xml version="1.0"?>
<robot xmlns:sensor="http://playerstage.sourceforge.net/gazebo/xmlschema/#sensor"
       xmlns:controller="http://playerstage.sourceforge.net/gazebo/xmlschema/#controller"
       xmlns:interface="http://playerstage.sourceforge.net/gazebo/xmlschema/#interface"
       xmlns:xacro="http://playerstage.sourceforge.net/gazebo/xmlschema/#interface"
       name="human" >

  <material name="Blue">
    <color rgba="0.0 0.0 0.8 1.0"/>
  </material>
  <material name="Green">
    <color rgba="0.0 0.8 0.0 1.0"/>
  </material>
  <material name="Grey">
    <color rgba="0.7 0.7 0.7 1.0"/>
  </material>
  <material name="Grey2">
    <color rgba="0.9 0.9 0.9 1.0"/>
  </material>
  <material name="Red">
    <color rgba="0.8 0.0 0.0 1.0"/>
  </material>
  <material name="White">
    <color rgba="1.0 1.0 1.0 1.0"/>
  </material>
  <material name="Black">
    <color rgba="0.1 0.1 0.1 1.0"/>
  </material>
  <material name="LightGrey">
    <color rgba="0.6 0.6 0.6 1.0"/>
  </material>

  <link name="root_link"/>
  <link name="base_prismatic_dummy1"/>
  <link name="base_prismatic_dummy2"/>
  <joint name="base_prismatic_joint_x" type="prismatic">
    <axis xyz="1 0 0"/>
    <limit effort="10000" lower="-5.0" upper="5.0" velocity="0.6"/>
    <safety_controller k_position="100" k_velocity="2000000" soft_lower_limit="-4.9" soft_upper_limit="4.9"/>
    <calibration falling="0.00536"/>
    <dynamics damping="20000.0"/>
    <origin rpy="0 0 0" xyz="0 0 0"/>
    <parent link="root_link"/>
    <child link="base_prismatic_dummy1"/>
  </joint>
  <joint name="base_prismatic_joint_y" type="prismatic">
    <axis xyz="0 1 0"/>
    <limit effort="10000" lower="-5.0" upper="5.0" velocity="0.6"/>
    <safety_controller k_position="100" k_velocity="2000000" soft_lower_limit="-4.9" soft_upper_limit="4.9"/>
    <calibration falling="0.00536"/>
    <dynamics damping="20000.0"/>
    <origin rpy="0 0 0" xyz="0 0 0"/>
    <parent link="base_prismatic_dummy1"/>
    <child link="base_prismatic_dummy2"/>
  </joint>
  <joint name="base_rotate_joint" type="continuous">
    <axis xyz="0 0 1"/>
    <limit effort="30" velocity="3.6"/>
    <safety_controller k_velocity="1"/>
    <calibration rising="0.0"/>
    <dynamics damping="0.1"/>
    <origin rpy="0 0 0" xyz="0 0 0"/>
    <parent link="base_prismatic_dummy2"/>
    <child link="pelvis_link"/>
  </joint>

  <link name="pelvis_link"/>
	  
  <joint name="pelvis1_z_joint" type="revolute">
    <axis xyz="0 0 1"/>
    <limit effort="15" lower="0" upper="0" velocity="5"/>
    <origin rpy="0 0 0" xyz="0 0.00163 0.12026"/>
    <parent link="pelvis_link"/>
    <child link="pelvis1_z_link"/>
  </joint>
  <joint name="pelvis1_y_joint" type="revolute">
    <axis xyz="0 1 0"/>
    <limit effort="15" lower="0" upper="0" velocity="5"/>
    <origin rpy="0 0 0" xyz="0 0 0"/>
    <parent link="pelvis1_z_link"/>
    <child link="pelvis1_y_link"/>
  </joint>
  <joint name="pelvis1_x_joint" type="revolute">
    <axis xyz="1 0 0"/>
    <limit effort="15" lower="0" upper="0" velocity="5"/>
    <origin rpy="0 0 0" xyz="0 0 0"/>
    <parent link="pelvis1_y_link"/>
    <child link="pelvis1_x_link"/>
  </joint>  
	  
  <link name="pelvis1_z_link"/>
  <link name="pelvis1_y_link"/>
  <link name="pelvis1_x_link"/>
	  
  <joint name="torso_z_joint" type="revolute">
    <axis xyz="0 0 1"/>
    <limit effort="15" lower="-0.7" upper="0.7" velocity="5"/>
    <origin rpy="0 0 0" xyz="0 0.00694 0.15302"/>
    <parent link="pelvis1_x_link"/>
    <child link="torso_z_link"/>
  </joint>
  <joint name="torso_y_joint" type="revolute">
    <axis xyz="0 1 0"/>
    <limit effort="15" lower="-0.3" upper="0.3" velocity="5"/>
    <origin rpy="0 0 0" xyz="0 0 0"/>
    <parent link="torso_z_link"/>
    <child link="torso_y_link"/>
  </joint>
  <joint name="torso_x_joint" type="revolute">
    <axis xyz="1 0 0"/>
    <limit effort="15" lower="-1.0" upper="0" velocity="5"/>
    <origin rpy="0 0 0" xyz="0 0 0"/>
    <parent link="torso_y_link"/>
    <child link="torso_x_link"/>
  </joint>  

  <link name="torso_z_link"/>
  <link name="torso_y_link"/>
  <link name="torso_x_link">
    <visual>
      <origin rpy="0 0 0" xyz="0 0 0"/>
      <geometry>
        <mesh filename="../rocketboxmale/torso.obj"/>
      </geometry>
      <material name="Blue"/>
    </visual>
    <collision>
      <origin rpy="0 0 0" xyz="0 0 0"/>
      <geometry>
        <mesh filename="../rocketboxmale/torso.obj"/>
      </geometry>
    </collision>
  </link>

<joint name="torso2_z_joint" type="revolute">
    <axis xyz="0 0 1"/>
    <limit effort="15" lower="0" upper="0" velocity="5"/>
    <origin rpy="0 0 0" xyz="0 0.01112 0.15277"/>
    <parent link="torso_x_link"/>
    <child link="torso2_z_link"/>
  </joint>
  <joint name="torso2_y_joint" type="revolute">
    <axis xyz="0 1 0"/>
    <limit effort="15" llower="0" upper="0" velocity="5"/>
    <origin rpy="0 0 0" xyz="0 0 0"/>
    <parent link="torso2_z_link"/>
    <child link="torso2_y_link"/>
  </joint>
  <joint name="torso2_x_joint" type="revolute">
    <axis xyz="1 0 0"/>
    <limit effort="15" lower="0" upper="0" velocity="5"/>
    <origin rpy="0 0 0" xyz="0 0 0"/>
    <parent link="torso2_y_link"/>
    <child link="torso2_x_link"/>
  </joint>

  <link name="torso2_z_link"/>
  <link name="torso2_y_link"/>
  <link name="torso2_x_link"/>
  
  
<joint name="torso3_z_joint" type="revolute">
    <axis xyz="0 0 1"/>
    <limit effort="15" lower="0" upper="0" velocity="5"/>
    <origin rpy="0 0 0" xyz="0 -0.00751 0.19961"/>
    <parent link="torso2_x_link"/>
    <child link="torso3_z_link"/>
  </joint>
  <joint name="torso3_y_joint" type="revolute">
    <axis xyz="0 1 0"/>
    <limit effort="15" lower="0" upper="0"" velocity="5"/>
    <origin rpy="0 0 0" xyz="0 0 0"/>
    <parent link="torso3_z_link"/>
    <child link="torso3_y_link"/>
  </joint>
  <joint name="torso3_x_joint" type="revolute">
    <axis xyz="1 0 0"/>
    <limit effort="15" lower="0" upper="0" velocity="5"/>
    <origin rpy="0 0 0" xyz="0 0 0"/>
    <parent link="torso3_y_link"/>
    <child link="torso3_x_link"/>
  </joint>

  <link name="torso3_z_link"/>
  <link name="torso3_y_link"/>
  <link name="torso3_x_link"/>


  <joint name="head_z_joint" type="revolute">
    <axis xyz="0 0 1"/>
    <limit effort="15" lower="-1.2" upper="1.2" velocity="5"/>
    <origin rpy="0 0 0" xyz="0 -0.02032 0.06622"/>
    <parent link="torso3_x_link"/>
    <child link="head_z_link"/>
  </joint>
  <joint name="head_y_joint" type="revolute">
    <axis xyz="0 1 0"/>
    <limit effort="15" lower="-0.8" upper="0.8" velocity="5"/>
    <origin rpy="0 0 0" xyz="0 0 0"/>
    <parent link="head_z_link"/>
    <child link="head_y_link"/>
  </joint>
  <joint name="head_x_joint" type="revolute">
    <axis xyz="1 0 0"/>
    <limit effort="15" lower="-1.57" upper="0.3" velocity="5"/>
    <origin rpy="0 0 0" xyz="0 0 0"/>
    <parent link="head_y_link"/>
    <child link="head_x_link"/>
  </joint>

  <link name="head_z_link"/>
  <link name="head_y_link"/>
  <link name="head_x_link">
    <visual>
      <origin rpy="0 0 0" xyz="0 0 0"/>
      <geometry>
        <mesh filename="../rocketboxmale/head.obj"/>
      </geometry>
      <material name="Blue"/>
    </visual>
    <collision>
      <origin rpy="0 0 0" xyz="0 0 0"/>
      <geometry>
        <mesh filename="../rocketboxmale/head.obj"/>
      </geometry>
    </collision>
  </link>
  
  <joint name="head_endeffector_joint" type="fixed">
    <axis xyz="0 0 1"/>
    <limit effort="15" lower="-0.001" upper="0.001" velocity="5"/>
    <origin rpy="0 0 0" xyz="0 -0.0314 0.20528"/>
    <parent link="head_x_link"/>
    <child link="head_endeffector_link"/>
  </joint>

  <link name="head_endeffector_link">
    <visual>
      <origin rpy="0 0 0" xyz="0 0 0"/>
      <geometry>
        <box size="0.001 0.001 0.001"/>
      </geometry>
      <material name="Blue"/>
    </visual>
    <collision>
      <origin rpy="0 0 0" xyz="0 0 0"/>
      <geometry>
        <box size="0.001 0.001 0.001"/>
      </geometry>
    </collision>
  </link>


  <joint name="upper_left_leg_z_joint" type="revolute">
    <axis xyz="0 0 1"/>
    <limit effort="15" lower="-1.57" upper="1" velocity="5"/>
    <origin rpy="0 0 0" xyz="-0.08837 -0.00857 -0.27328"/>
    <parent link="torso_x_link"/>
    <child link="upper_left_leg_z_link"/>
  </joint>
  <joint name="upper_left_leg_y_joint" type="revolute">
    <axis xyz="0 1 0"/>
    <limit effort="15" lower="-1.57" upper="0.7" velocity="5"/>
    <origin rpy="0 0 0" xyz="0 0 0"/>
    <parent link="upper_left_leg_z_link"/>
    <child link="upper_left_leg_y_link"/>
  </joint>
  <joint name="upper_left_leg_x_joint" type="revolute">
    <axis xyz="1 0 0"/>
    <limit effort="15" lower="-1.2" upper="1.57" velocity="5"/>
    <origin rpy="0 0 0" xyz="0 0 0"/>
    <parent link="upper_left_leg_y_link"/>
    <child link="upper_left_leg_x_link"/>
  </joint>

  <link name="upper_left_leg_z_link"/>
  <link name="upper_left_leg_y_link"/>
  <link name="upper_left_leg_x_link">
    <visual>
      <origin rpy="0 0 0" xyz="0 0 0"/>
      <geometry>
        <mesh filename="../rocketboxmale/l_lupperleg.obj"/>
      </geometry>
      <material name="Blue"/>
    </visual>
    <collision>
      <origin rpy="0 0 0" xyz="0 0 0"/>
      <geometry>
        <mesh filename="../rocketboxmale/l_lupperleg.obj"/>
      </geometry>
    </collision>
  </link>

  <joint name="lower_left_leg_joint" type="revolute">
    <axis xyz="1 0 0"/>
    <limit effort="15" lower="-2.4" upper="0" velocity="5"/>
    <origin rpy="0 0 0" xyz="-0.02111 -0.0163 -0.39814"/>
    <parent link="upper_left_leg_x_link"/>
    <child link="lower_left_leg_link"/>
  </joint>

  <link name="lower_left_leg_link">
    <visual>
      <origin rpy="0 0 0" xyz="0 0 0"/>
      <geometry>
        <mesh filename="../rocketboxmale/l_lowerleg.obj"/>
      </geometry>
      <material name="Blue"/>
    </visual>
    <collision>
      <origin rpy="0 0 0" xyz="0 0 0"/>
      <geometry>
        <mesh filename="../rocketboxmale/l_lowerleg.obj"/>
      </geometry>
    </collision>
  </link>

  <joint name="left_foot_z_joint" type="revolute">
    <axis xyz="0 0 1"/>
    <limit effort="15" lower="-0.01" upper="0" velocity="5"/>
    <origin rpy="0 0 0" xyz="-0.00749 0.03083 -0.39542"/>
    <parent link="lower_left_leg_link"/>
    <child link="left_foot_z_link"/>
  </joint>
  <joint name="left_foot_y_joint" type="revolute">
    <axis xyz="0 1 0"/>
    <limit effort="15" lower="-0.5" upper="0.5" velocity="5"/>
    <origin rpy="0 0 0" xyz="0 0 0"/>
    <parent link="left_foot_z_link"/>
    <child link="left_foot_y_link"/>
  </joint>
  <joint name="left_foot_x_joint" type="revolute">
    <axis xyz="1 0 0"/>
    <limit effort="15" lower="-0.8" upper="0.6" velocity="5"/>
    <origin rpy="0 0 0" xyz="0 0 0"/>
    <parent link="left_foot_y_link"/>
    <child link="left_foot_x_link"/>
  </joint>

  <link name="left_foot_z_link"/>
  <link name="left_foot_y_link"/>
  <link name="left_foot_x_link">
    <visual>
      <origin rpy="0 0 0" xyz="0 0 0"/>
      <geometry>
        <mesh filename="../rocketboxmale/l_foot.obj"/>
      </geometry>
      <material name="Blue"/>
    </visual>
    <collision>
      <origin rpy="0 0 0" xyz="0 0 0"/>
      <geometry>
        <mesh filename="../rocketboxmale/l_foot.obj"/>
      </geometry>
    </collision>
  </link>
	
  <joint name="left_foot2_z_joint" type="revolute">
	<axis xyz="0 0 1"/>
	<limit effort="15" lower="-0" upper="0" velocity="5"/>
	<origin rpy="0 0 0" xyz="-0.03416 -0.13378 -0.09919"/>
	<parent link="left_foot_x_link"/>
	<child link="left_foot2_z_link"/>
  </joint>
  <joint name="left_foot2_y_joint" type="revolute">
    <axis xyz="0 1 0"/>
    <limit effort="15" lower="-0" upper="0" velocity="5"/>
    <origin rpy="0 0 0" xyz="0 0 0"/>
    <parent link="left_foot2_z_link"/>
    <child link="left_foot2_y_link"/>
  </joint>
  <joint name="left_foot2_x_joint" type="revolute">
    <axis xyz="1 0 0"/>
    <limit effort="15" lower="-0" upper="0" velocity="5"/>
    <origin rpy="0 0 0" xyz="0 0 0"/>
    <parent link="left_foot2_y_link"/>
    <child link="left_foot2_x_link"/>
  </joint>
  
  <link name="left_foot2_z_link"/>
  <link name="left_foot2_y_link"/>
  <link name="left_foot2_x_link"/>
	  
  <joint name="left_foot_endeffector_joint" type="fixed">
    <axis xyz="0 0 1"/>
    <limit effort="15" lower="-0.001" upper="0.001" velocity="5"/>
    <origin rpy="0 0 0" xyz="-0.02077 -0.08119 0.00149"/>
    <parent link="left_foot2_x_link"/>
    <child link="left_foot_endeffector_link"/>
  </joint>

  <link name="left_foot_endeffector_link">
    <visual>
      <origin rpy="0 0 0" xyz="0 0 0"/>
      <geometry>
        <box size="0.001 0.001 0.001"/>
      </geometry>
      <material name="Blue"/>
    </visual>
  </link>
  
  

  <joint name="upper_right_leg_z_joint" type="revolute">
    <axis xyz="0 0 1"/>
    <limit effort="15" lower="-1" upper="1.57" velocity="5"/>
    <origin rpy="0 0 0" xyz="0.08837 -0.00857 -0.27327"/>
    <parent link="torso_x_link"/>
    <child link="upper_right_leg_z_link"/>
  </joint>
  <joint name="upper_right_leg_y_joint" type="revolute">
    <axis xyz="0 1 0"/>
    <limit effort="15" lower="-0.7" upper="1.57" velocity="5"/>
    <origin rpy="0 0 0" xyz="0 0 0"/>
    <parent link="upper_right_leg_z_link"/>
    <child link="upper_right_leg_y_link"/>
  </joint>
  <joint name="upper_right_leg_x_joint" type="revolute">
    <axis xyz="1 0 0"/>
    <limit effort="15" lower="-1.2" upper="1.57" velocity="5"/>
    <origin rpy="0 0 0" xyz="0 0 0"/>
    <parent link="upper_right_leg_y_link"/>
    <child link="upper_right_leg_x_link"/>
  </joint>

  <link name="upper_right_leg_z_link"/>
  <link name="upper_right_leg_y_link"/>
  <link name="upper_right_leg_x_link">
    <visual>
      <origin rpy="0 0 0" xyz="0 0 0"/>
      <geometry>
        <mesh filename="../rocketboxmale/r_upperleg.obj"/>
      </geometry>
      <material name="Blue"/>
    </visual>
    <collision>
      <origin rpy="0 0 0" xyz="0 0 0"/>
      <geometry>
        <mesh filename="../rocketboxmale/r_upperleg.obj"/>
      </geometry>
    </collision>
  </link>

  <joint name="lower_right_leg_joint" type="revolute">
    <axis xyz="1 0 0"/>
    <limit effort="15" lower="-2.4" upper="0" velocity="5"/>
    <origin rpy="0 0 0" xyz="0.02111 -0.0163 -0.39815"/>
    <parent link="upper_right_leg_x_link"/>
    <child link="lower_right_leg_link"/>
  </joint>

  <link name="lower_right_leg_link">
    <visual>
      <origin rpy="0 0 0" xyz="0 0 0"/>
      <geometry>
        <mesh filename="../rocketboxmale/r_lowerleg.obj"/>
      </geometry>
      <material name="Blue"/>
    </visual>
    <collision>
      <origin rpy="0 0 0" xyz="0 0 0"/>
      <geometry>
        <mesh filename="../rocketboxmale/r_lowerleg.obj"/>
      </geometry>
    </collision>
  </link>

  <joint name="right_foot_z_joint" type="revolute">
    <axis xyz="0 0 1"/>
    <limit effort="15" lower="0" upper="0.001" velocity="5"/>
    <origin rpy="0 0 0" xyz="0.00749 0.03083 -0.39542"/>
    <parent link="lower_right_leg_link"/>
    <child link="right_foot_z_link"/>
  </joint>
  <joint name="right_foot_y_joint" type="revolute">
    <axis xyz="0 1 0"/>
    <limit effort="15" lower="-0.5" upper="0.5" velocity="5"/>
    <origin rpy="0 0 0" xyz="0 0 0"/>
    <parent link="right_foot_z_link"/>
    <child link="right_foot_y_link"/>
  </joint>
  <joint name="right_foot_x_joint" type="revolute">
    <axis xyz="1 0 0"/>
    <limit effort="15" lower="-0.8" upper="0.6" velocity="5"/>
    <origin rpy="0 0 0" xyz="0 0 0"/>
    <parent link="right_foot_y_link"/>
    <child link="right_foot_x_link"/>
  </joint>

  <link name="right_foot_z_link"/>
  <link name="right_foot_y_link"/>
  <link name="right_foot_x_link">
    <visual>
      <origin rpy="0 0 0" xyz="0 0 0"/>
      <geometry>
        <mesh filename="../rocketboxmale/r_foot.obj"/>
      </geometry>
      <material name="Blue"/>
    </visual>
    <collision>
      <origin rpy="0 0 0" xyz="0 0 0"/>
      <geometry>
        <mesh filename="../rocketboxmale/r_foot.obj"/>
      </geometry>
    </collision>
  </link>
  
  <joint name="right_foot2_z_joint" type="revolute">
	<axis xyz="0 0 1"/>
	<limit effort="15" lower="-0" upper="0" velocity="5"/>
	<origin rpy="0 0 0" xyz="0.03416 -0.13378 -0.09919"/>
	<parent link="right_foot_x_link"/>
	<child link="right_foot2_z_link"/>
  </joint>
  <joint name="right_foot2_y_joint" type="revolute">
    <axis xyz="0 1 0"/>
    <limit effort="15" lower="-0" upper="0" velocity="5"/>
    <origin rpy="0 0 0" xyz="0 0 0"/>
    <parent link="right_foot2_z_link"/>
    <child link="right_foot2_y_link"/>
  </joint>
  <joint name="right_foot2_x_joint" type="revolute">
    <axis xyz="1 0 0"/>
    <limit effort="15" lower="-0" upper="0" velocity="5"/>
    <origin rpy="0 0 0" xyz="0 0 0"/>
    <parent link="right_foot2_y_link"/>
    <child link="right_foot2_x_link"/>
  </joint>
  
  <link name="right_foot2_z_link"/>
  <link name="right_foot2_y_link"/>
  <link name="right_foot2_x_link"/>
	  
  <joint name="right_foot_endeffector_joint" type="fixed">
    <axis xyz="0 0 1"/>
    <limit effort="15" lower="-0.001" upper="0.001" velocity="5"/>
    <origin rpy="0 0 0" xyz="0.02077 -0.08119 0.00148"/>
    <parent link="right_foot2_x_link"/>
    <child link="right_foot_endeffector_link"/>
  </joint>

  <link name="right_foot_endeffector_link">
    <visual>
      <origin rpy="0 0 0" xyz="0 0 0"/>
      <geometry>
        <box size="0.001 0.001 0.001"/>
      </geometry>
      <material name="Blue"/>
    </visual>
  </link>

  <joint name="upper_left_specula_joint" type="revolute">
    <axis xyz="0 0 1"/>
    <limit effort="15" lower="-0" upper="0" velocity="5"/>
    <origin rpy="0 0 0" xyz="-0.072819 0.03175 -0.12763"/>
    <parent link="head_x_link"/>
    <child link="upper_left_arm_specula_link"/>
  </joint>
  
  <link name="upper_left_arm_specula_link"/>
  
  <joint name="upper_left_arm_z_joint" type="revolute">
    <axis xyz="0 0 1"/>
    <limit effort="15" lower="-0.5" upper="0.5" velocity="5"/>
    <origin rpy="0 -1.5707 0" xyz="-0.14108 0 0"/>
    <parent link="upper_left_arm_specula_link"/>
    <child link="upper_left_arm_z_link"/>
  </joint>
  <joint name="upper_left_arm_y_joint" type="revolute">
    <axis xyz="0 1 0"/>
    <limit effort="15" lower="-3.14" upper="2.0" velocity="5"/>
    <origin rpy="0 0 0" xyz="0 0 0"/>
    <parent link="upper_left_arm_z_link"/>
    <child link="upper_left_arm_y_link"/>
  </joint>
  <joint name="upper_left_arm_x_joint" type="revolute">
    <axis xyz="1 0 0"/>
    <limit effort="15" lower="-1.0" upper="3.14" velocity="5"/>
    <origin rpy="0 0 0" xyz="0 0 0"/>
    <parent link="upper_left_arm_y_link"/>
    <child link="upper_left_arm_x_link"/>
  </joint>

  <link name="upper_left_arm_z_link"/>
  <link name="upper_left_arm_y_link"/>
  <link name="upper_left_arm_x_link">
    <visual>
      <origin rpy="0 0 0" xyz="0 0 0"/>
      <geometry>
        <mesh filename="../rocketboxmale/l_upperarm.obj"/>
      </geometry>
      <material name="Blue"/>
    </visual>
    <collision>
      <origin rpy="0 0 0" xyz="0 0 0"/>
      <geometry>
        <mesh filename="../rocketboxmale/l_upperarm.obj"/>
      </geometry>
    </collision>
  </link>

  <joint name="lower_left_arm_joint" type="revolute">
    <axis xyz="1 0 0"/>
    <limit effort="15" lower="0" upper="3.14" velocity="5"/>
    <origin rpy="0 0 0" xyz="-0.2858 -0.00095 -0.00122"/>
    <parent link="upper_left_arm_x_link"/>
    <child link="lower_left_arm_link"/>
  </joint>

  <link name="lower_left_arm_link">
    <visual>
      <origin rpy="0 0 0" xyz="0 0 0"/>
      <geometry>
        <mesh filename="../rocketboxmale/l_forearm.obj"/>
      </geometry>
      <material name="Blue"/>
    </visual>
    <collision>
      <origin rpy="0 0 0" xyz="0 0 0"/>
      <geometry>
        <mesh filename="../rocketboxmale/l_forearm.obj"/>
      </geometry>
    </collision>
  </link>

  <joint name="left_hand_z_joint" type="revolute">
    <axis xyz="0 0 1"/>
    <limit effort="15" lower="-1.0" upper="1.0" velocity="5"/>
    <origin rpy="0 0 0" xyz="-0.27088 -0.00416 -0.00144"/>
    <parent link="lower_left_arm_link"/>
    <child link="left_hand_z_link"/>
  </joint>
  <joint name="left_hand_y_joint" type="revolute">
    <axis xyz="0 1 0"/>
    <limit effort="15" lower="-1.3" upper="1.5" velocity="5"/>
    <origin rpy="0 0 0" xyz="0 0 0"/>
    <parent link="left_hand_z_link"/>
    <child link="left_hand_y_link"/>
  </joint>
  <joint name="left_hand_x_joint" type="revolute">
    <axis xyz="1 0 0"/>
    <limit effort="15" lower="-0.5" upper="1.4" velocity="5"/>
    <origin rpy="0 0 0" xyz="0 0 0"/>
    <parent link="left_hand_y_link"/>
    <child link="left_hand_x_link"/>
  </joint>

  <link name="left_hand_z_link"/>
  <link name="left_hand_y_link"/>
  <link name="left_hand_x_link">
    <visual>
      <origin rpy="0 0 0" xyz="0 0 0"/>
      <geometry>
        <mesh filename="../rocketboxmale/l_hand.obj"/>
      </geometry>
      <material name="Blue"/>
    </visual>
    <collision>
      <origin rpy="0 0 0" xyz="0 0 0"/>
      <geometry>
        <mesh filename="../rocketboxmale/l_hand.obj"/>
      </geometry>
    </collision>
  </link>

  <joint name="left_hand_endeffector_joint" type="revolute">
    <axis xyz="0 0 1"/>
    <limit effort="15" lower="-0.001" upper="0.001" velocity="5"/>
    <origin rpy="0 0 0" xyz="-0.1807 0.00617 -0.00818"/>
    <parent link="left_hand_x_link"/>
    <child link="left_hand_endeffector_link"/>
  </joint>

  <link name="left_hand_endeffector_link">
    <visual>
      <origin rpy="0 0 0" xyz="0 0 0"/>
      <geometry>
        <box size="0.001 0.001 0.001"/>
      </geometry>
      <material name="Blue"/>
    </visual>
    <collision>
      <origin rpy="0 0 0" xyz="0 0 0"/>
      <geometry>
        <box size="0.001 0.001 0.001"/>
      </geometry>
    </collision>
  </link>

  
  <joint name="upper_right_specula_joint" type="revolute">
    <axis xyz="0 0 1"/>
    <limit effort="15" lower="0" upper="0" velocity="5"/>
    <origin rpy="0 0 0" xyz="0.072821 0.03175 -0.12776"/>
    <parent link="head_x_link"/>
    <child link="upper_right_arm_specula_link"/>
  </joint>
    
  <link name="upper_right_arm_specula_link"/>
  
  <joint name="upper_right_arm_z_joint" type="revolute">
    <axis xyz="0 0 1"/>
    <limit effort="15" lower="-0.5" upper="0.5" velocity="5"/>
    <origin rpy="0 1.5707 0" xyz="0.14105 0.00314 -0.00025"/>
    <parent link="upper_right_arm_specula_link"/>
    <child link="upper_right_arm_z_link"/>
  </joint>
  <joint name="upper_right_arm_y_joint" type="revolute">
    <axis xyz="0 1 0"/>
    <limit effort="15" lower="-2.0" upper="3.14" velocity="5"/>
    <origin rpy="0 0 0" xyz="0 0 0"/>
    <parent link="upper_right_arm_z_link"/>
    <child link="upper_right_arm_y_link"/>
  </joint>
  <joint name="upper_right_arm_x_joint" type="revolute">
    <axis xyz="1 0 0"/>
    <limit effort="15" lower="-1.0" upper="3.14" velocity="5"/>
    <origin rpy="0 0 0" xyz="0 0 0"/>
    <parent link="upper_right_arm_y_link"/>
    <child link="upper_right_arm_x_link"/>
  </joint>

  <link name="upper_right_arm_z_link"/>
  <link name="upper_right_arm_y_link"/>
  <link name="upper_right_arm_x_link">
    <visual>
      <origin rpy="0 0 0" xyz="0 0 0"/>
      <geometry>
        <mesh filename="../rocketboxmale/r_upperarm.obj"/>
      </geometry>
      <material name="Blue"/>
    </visual>
    <collision>
      <origin rpy="0 0 0" xyz="0 0 0"/>
      <geometry>
        <mesh filename="../rocketboxmale/r_upperarm.obj"/>
      </geometry>
    </collision>
  </link>

  <joint name="lower_right_arm_joint" type="revolute">
    <axis xyz="1 0 0"/>
    <limit effort="15" lower="0" upper="3.14" velocity="5"/>
    <origin rpy="0 0 0" xyz="0.28569 -0.00617 -0.00466"/>
    <parent link="upper_right_arm_x_link"/>
    <child link="lower_right_arm_link"/>
  </joint>

  <link name="lower_right_arm_link">
    <visual>
      <origin rpy="0 0 0" xyz="0 0 0"/>
      <geometry>
        <mesh filename="../rocketboxmale/r_forearm.obj"/>
      </geometry>
      <material name="Blue"/>
    </visual>
    <collision>
      <origin rpy="0 0 0" xyz="0 0 0"/>
      <geometry>
        <mesh filename="../rocketboxmale/r_forearm.obj"/>
      </geometry>
    </collision>
  </link>

  <joint name="right_hand_z_joint" type="revolute">
    <axis xyz="0 0 1"/>
    <limit effort="15" lower="-1.0" upper="1.0" velocity="5"/>
    <origin rpy="0 0 0" xyz="0.27088 -0.00257 -0.00394"/>
    <parent link="lower_right_arm_link"/>
    <child link="right_hand_z_link"/>
  </joint>
  <joint name="right_hand_y_joint" type="revolute">
    <axis xyz="0 1 0"/>
    <limit effort="15" lower="-1.5" upper="1.3" velocity="5"/>
    <origin rpy="0 0 0" xyz="0 0 0"/>
    <parent link="right_hand_z_link"/>
    <child link="right_hand_y_link"/>
  </joint>
  <joint name="right_hand_x_joint" type="revolute">
    <axis xyz="1 0 0"/>
    <limit effort="15" lower="-0.5" upper="1.4" velocity="5"/>
    <origin rpy="0 0 0" xyz="0 0 0"/>
    <parent link="right_hand_y_link"/>
    <child link="right_hand_x_link"/>
  </joint>

  <link name="right_hand_z_link"/>
  <link name="right_hand_y_link"/>
  <link name="right_hand_x_link">
    <visual>
      <origin rpy="0 0 0" xyz="0 0 0"/>
      <geometry>
        <mesh filename="../rocketboxmale/r_hand.obj"/>
      </geometry>
      <material name="Blue"/>
    </visual>
    <collision>
      <origin rpy="0 0 0" xyz="0 0 0"/>
      <geometry>
        <mesh filename="../rocketboxmale/r_hand.obj"/>
      </geometry>
    </collision>
  </link>

  <joint name="right_hand_endeffector_joint" type="revolute">
    <axis xyz="0 0 1"/>
    <limit effort="15" lower="-0.001" upper="0.001" velocity="5"/>
    <origin rpy="0 0 0" xyz="0.1807 0.00907 -0.00029"/>
    <parent link="right_hand_x_link"/>
    <child link="right_hand_endeffector_link"/>
  </joint>

  <link name="right_hand_endeffector_link">
    <visual>
      <origin rpy="0 0 0" xyz="0 0 0"/>
      <geometry>
        <box size="0.001 0.001 0.001"/>
      </geometry>
      <material name="Blue"/>
    </visual>
    <collision>
      <origin rpy="0 0 0" xyz="0 0 0"/>
      <geometry>
        <box size="0.001 0.001 0.001"/>
      </geometry>
    </collision>
  </link>

</robot>

