<?xml version="1.0"?>
<robot xmlns:sensor="http://playerstage.sourceforge.net/gazebo/xmlschema/#sensor"
       xmlns:controller="http://playerstage.sourceforge.net/gazebo/xmlschema/#controller"
       xmlns:interface="http://playerstage.sourceforge.net/gazebo/xmlschema/#interface"
       xmlns:xacro="http://playerstage.sourceforge.net/gazebo/xmlschema/#interface"
       name="rocketbox_male" >

  <material name="Blue">
    <color rgba="0.0 0.0 0.8 1.0"/>
  </material>
  <material name="Green">
    <color rgba="0.0 0.8 0.0 1.0"/>
  </material>
  <material name="Grey">
    <color rgba="0.7 0.7 0.7 1.0"/>
  </material>
  <material name="Grey2">
    <color rgba="0.9 0.9 0.9 1.0"/>
  </material>
  <material name="Red">
    <color rgba="0.8 0.0 0.0 1.0"/>
  </material>
  <material name="White">
    <color rgba="1.0 1.0 1.0 1.0"/>
  </material>
  <material name="Black">
    <color rgba="0.1 0.1 0.1 1.0"/>
  </material>
  <material name="LightGrey">
    <color rgba="0.6 0.6 0.6 1.0"/>
  </material>

  <link name="root_link"/>
  <link name="base_prismatic_dummy1">
    <visual>
      <origin rpy="0 0 0" xyz="0 0 0"/>
      <geometry>
        <box size="0.001 0.001 0.001"/>
      </geometry>
      <material name="Blue"/>
    </visual>
  </link>
  <link name="base_prismatic_dummy2">
    <visual>
      <origin rpy="0 0 0" xyz="0 0 0"/>
      <geometry>
        <box size="0.001 0.001 0.001"/>
      </geometry>
      <material name="Blue"/>
    </visual>
  </link>
  <link name="base_prismatic_dummy3">
    <visual>
      <origin rpy="0 0 0" xyz="0 0 0"/>
      <geometry>
        <box size="0.001 0.001 0.001"/>
      </geometry>
      <material name="Blue"/>
    </visual>
  </link>
  <link name="base_revolute_dummy1">
    <visual>
      <origin rpy="0 0 0" xyz="0 0 0"/>
      <geometry>
        <box size="0.001 0.001 0.001"/>
      </geometry>
      <material name="Blue"/>
    </visual>
  </link>
  <link name="base_revolute_dummy2">
    <visual>
      <origin rpy="0 0 0" xyz="0 0 0"/>
      <geometry>
        <box size="0.001 0.001 0.001"/>
      </geometry>
      <material name="Blue"/>
    </visual>
  </link>
  <joint name="base_prismatic_joint_x" type="prismatic">
    <axis xyz="1 0 0"/>
    <limit effort="10000" lower="-6.0" upper="6.0" velocity="0.6"/>
    <safety_controller k_position="100" k_velocity="2000000" soft_lower_limit="-5.9" soft_upper_limit="5.9"/>
    <calibration falling="0.00536"/>
    <dynamics damping="20000.0"/>
    <origin rpy="0 0 0" xyz="0 0 1.218534"/>
    <parent link="root_link"/>
    <child link="base_prismatic_dummy1"/>
  </joint>
  <joint name="base_prismatic_joint_y" type="prismatic">
    <axis xyz="0 1 0"/>
    <limit effort="10000" lower="-6.0" upper="6.0" velocity="0.6"/>
    <safety_controller k_position="100" k_velocity="2000000" soft_lower_limit="-5.9" soft_upper_limit="5.9"/>
    <calibration falling="0.00536"/>
    <dynamics damping="20000.0"/>
    <origin rpy="0 0 0" xyz="0 0 0"/>
    <parent link="base_prismatic_dummy1"/>
    <child link="base_prismatic_dummy2"/>
  </joint>
  <joint name="base_prismatic_joint_z" type="prismatic">
    <axis xyz="0 0 1"/>
    <limit effort="10000" lower="-10.0" upper="10.0" velocity="0.6"/>
    <safety_controller k_position="100" k_velocity="2000000" soft_lower_limit="-10.0" soft_upper_limit="10.0"/>
    <calibration falling="0.00536"/>
    <dynamics damping="20000.0"/>
    <origin rpy="0 0 0" xyz="0 0 0"/>
    <parent link="base_prismatic_dummy2"/>
    <child link="base_prismatic_dummy3"/>
  </joint>
  <joint name="base_revolute_joint_x" type="continuous">
    <axis xyz="1 0 0"/>
    <origin rpy="0 0 0" xyz="0 0 0"/>
    <parent link="base_prismatic_dummy3"/>
    <child link="base_revolute_dummy1"/>
  </joint>
  <joint name="base_revolute_joint_y" type="continuous">
    <axis xyz="0 1 0"/>
    <origin rpy="0 0 0" xyz="0 0 0"/>
    <parent link="base_revolute_dummy1"/>
    <child link="base_revolute_dummy2"/>
  </joint>
  <joint name="base_revolute_joint_z" type="continuous">
    <axis xyz="0 0 1"/>
    <origin rpy="0 0 0" xyz="0 0 0"/>
    <parent link="base_revolute_dummy2"/>
    <child link="pelvis_link"/>
  </joint>  
  <link name="pelvis_link">
    <inertial>
      <mass value="24.9873014159"/>
      <inertia ixx="0.219399825" ixy="0.000000009184695" ixz="0.000000062599005" iyy="0.21939959375" iyz="-0.000000006475555" izz="0.22992248625"/>
      <origin xyz="0 -0.00000001 0.0983925"/>
    </inertial>
  </link>	  
  <joint name="torso_z_joint" type="revolute">
    <axis xyz="0 0 1"/>
    <limit effort="15" lower="-0.7" upper="0.7" velocity="5"/>
    <origin rpy="0 0 0" xyz="0 0.010284 0.327936"/>
    <parent link="pelvis_link"/>
    <child link="torso_z_link"/>
  </joint>
  <joint name="torso_y_joint" type="revolute">
    <axis xyz="0 1 0"/>
    <limit effort="15" lower="-0.3" upper="0.3" velocity="5"/>
    <origin rpy="0 0 0" xyz="0 0 0"/>
    <parent link="torso_z_link"/>
    <child link="torso_y_link"/>
  </joint>
  <joint name="torso_x_joint" type="revolute">
    <axis xyz="1 0 0"/>
    <limit effort="15" lower="-1.0" upper="0" velocity="5"/>
    <origin rpy="0 0 0" xyz="0 0 0"/>
    <parent link="torso_y_link"/>
    <child link="torso_x_link"/>
  </joint>  

  <link name="torso_z_link"/>
  <link name="torso_y_link"/>
  <link name="torso_x_link">
    <visual>
      <origin rpy="0 0 0" xyz="0 0 0"/>
      <geometry>
        <mesh filename="package://human_description/meshes/rocket_box/torso.obj"/>
      </geometry>
      <material name="Blue"/>
    </visual>
    <collision>
      <origin rpy="0 0 0" xyz="0 0 0"/>
      <geometry>
        <mesh filename="package://human_description/meshes/rocket_box/torso.obj"/>
      </geometry>
    </collision>
    <inertial>
      <mass value="54.1902903318"/>
      <inertia ixx="1.0895931125" ixy="0.000001152997515" ixz="-0.000000460619845" iyy="1.4490895525" iyz="0.000000968452985" izz="0.679463005"/>
      <origin xyz="0 -0.00000025 0.22608234"/>
    </inertial>
  </link>  
  
  <joint name="head_z_joint" type="revolute">
    <axis xyz="0 0 1"/>
    <limit effort="15" lower="-1.2" upper="1.2" velocity="5"/>
    <origin rpy="0 0 0" xyz="0 -0.020052 .502320"/>
    <parent link="torso_x_link"/>
    <child link="head_z_link"/>
  </joint>
  <joint name="head_y_joint" type="revolute">
    <axis xyz="0 1 0"/>
    <limit effort="15" lower="-0.8" upper="0.8" velocity="5"/>
    <origin rpy="0 0 0" xyz="0 0 0"/>
    <parent link="head_z_link"/>
    <child link="head_y_link"/>
  </joint>
  <joint name="head_x_joint" type="revolute">
    <axis xyz="1 0 0"/>
    <limit effort="15" lower="-1.57" upper="0.3" velocity="5"/>
    <origin rpy="0 0 0" xyz="0 0 0"/>
    <parent link="head_y_link"/>
    <child link="head_x_link"/>
  </joint>

  <link name="head_z_link"/>
  <link name="head_y_link"/>
  <link name="head_x_link">
    <visual>
      <origin rpy="0 0 0" xyz="0 0 0"/>
      <geometry>
        <mesh filename="package://human_description/meshes/rocket_box/head.obj"/>
      </geometry>
      <material name="Blue"/>
    </visual>
    <collision>
      <origin rpy="0 0 0" xyz="0 0 0"/>
      <geometry>
        <mesh filename="package://human_description/meshes/rocket_box/head.obj"/>
      </geometry>
    </collision>
    <inertial>
      <mass value="16.0164526852"/>
      <inertia ixx="0.194835825625" ixy="-0.00000000913641" ixz="0.00000000531468" iyy="0.194835733125" iyz="-0.000000020301345" izz="0.06426014890625"/>
      <origin xyz="0.0 0.00000001 0.18566523"/>
    </inertial>
  </link>
  
  <joint name="head_endeffector_joint" type="fixed">
    <axis xyz="0 0 1"/>
    <limit effort="15" lower="-0.001" upper="0.001" velocity="5"/>
    <origin rpy="0 0 0" xyz="0 -0.03768 0.246336"/>
    <parent link="head_x_link"/>
    <child link="head_endeffector_link"/>
  </joint>

  <link name="head_endeffector_link">
    <visual>
      <origin rpy="0 0 0" xyz="0 0 0"/>
      <geometry>
        <box size="0.001 0.001 0.001"/>
      </geometry>
      <material name="Blue"/>
    </visual>
    <collision>
      <origin rpy="0 0 0" xyz="0 0 0"/>
      <geometry>
        <box size="0.001 0.001 0.001"/>
      </geometry>
    </collision>
  </link>


  <joint name="upper_left_leg_z_joint" type="revolute">
    <axis xyz="0 0 1"/>
    <limit effort="15" lower="-1.57" upper="1" velocity="5"/>
    <origin rpy="0 0 0" xyz="-0.106044 -0.001956 -0.144312"/>
    <parent link="pelvis_link"/>
    <child link="upper_left_leg_z_link"/>
  </joint>
  <joint name="upper_left_leg_y_joint" type="revolute">
    <axis xyz="0 1 0"/>
    <limit effort="15" lower="-1.57" upper="0.7" velocity="5"/>
    <origin rpy="0 0 0" xyz="0 0 0"/>
    <parent link="upper_left_leg_z_link"/>
    <child link="upper_left_leg_y_link"/>
  </joint>
  <joint name="upper_left_leg_x_joint" type="revolute">
    <axis xyz="1 0 0"/>
    <limit effort="15" lower="-1.2" upper="1.57" velocity="5"/>
    <origin rpy="0 0 0" xyz="0 0 0"/>
    <parent link="upper_left_leg_y_link"/>
    <child link="upper_left_leg_x_link"/>
  </joint>

  <link name="upper_left_leg_z_link"/>
  <link name="upper_left_leg_y_link"/>
  <link name="upper_left_leg_x_link">
    <visual>
      <origin rpy="0 0 0" xyz="0 0 0"/>
      <geometry>
        <mesh filename="package://human_description/meshes/rocket_box/l_lupperleg.obj"/>
      </geometry>
      <material name="Blue"/>
    </visual>
    <collision>
      <origin rpy="0 0 0" xyz="0 0 0"/>
      <geometry>
        <mesh filename="package://human_description/meshes/rocket_box/l_lupperleg.obj"/>
      </geometry>
    </collision>
    <inertial>
      <mass value="11.28066677275"/>
      <inertia ixx="0.258606759375" ixy="0.000002463301455" ixz="0.00032211891975" iyy="0.258311314375" iyz="-0.000065609605275" izz="0.021073428046875"/>
      <origin xyz="-0.00364974 -0.00003172 -0.19576731"/>
    </inertial>
  </link>

  <joint name="lower_left_leg_joint" type="revolute">
    <axis xyz="1 0 0"/>
    <limit effort="15" lower="-2.4" upper="0" velocity="5"/>
    <origin rpy="0 0 0" xyz="-0.025332 -0.01956 -0.477768"/>
    <parent link="upper_left_leg_x_link"/>
    <child link="lower_left_leg_link"/>
  </joint>

  <link name="lower_left_leg_link">
    <visual>
      <origin rpy="0 0 0" xyz="0 0 0"/>
      <geometry>
        <mesh filename="package://human_description/meshes/rocket_box/l_lowerleg.obj"/>
      </geometry>
      <material name="Blue"/>
    </visual>
    <collision>
      <origin rpy="0 0 0" xyz="0 0 0"/>
      <geometry>
        <mesh filename="package://human_description/meshes/rocket_box/l_lowerleg.obj"/>
      </geometry>
    </collision>
    <inertial>
      <mass value="8.394054321"/>
      <inertia ixx="0.1879741409375" ixy="0.000000001719205" ixz="-0.00000000509231" iyy="0.1879741525" iyz="-0.00000001780773" izz="0.01166299402353"/>
      <origin xyz="0.0 -0.00029422 -0.20195734"/>
    </inertial>
  </link>

  <joint name="left_foot_z_joint" type="revolute">
    <axis xyz="0 0 1"/>
    <limit effort="15" lower="-0.01" upper="0" velocity="5"/>
    <origin rpy="0 0 0" xyz="-0.008988 0.036996 -0.474504"/>
    <parent link="lower_left_leg_link"/>
    <child link="left_foot_z_link"/>
  </joint>
  <joint name="left_foot_y_joint" type="revolute">
    <axis xyz="0 1 0"/>
    <limit effort="15" lower="-0.5" upper="0.5" velocity="5"/>
    <origin rpy="0 0 0" xyz="0 0 0"/>
    <parent link="left_foot_z_link"/>
    <child link="left_foot_y_link"/>
  </joint>
  <joint name="left_foot_x_joint" type="revolute">
    <axis xyz="1 0 0"/>
    <limit effort="15" lower="-0.8" upper="0.6" velocity="5"/>
    <origin rpy="0 0 0" xyz="0 0 0"/>
    <parent link="left_foot_y_link"/>
    <child link="left_foot_x_link"/>
  </joint>

  <link name="left_foot_z_link"/>
  <link name="left_foot_y_link"/>
  <link name="left_foot_x_link">
    <visual>
      <origin rpy="0 0 0" xyz="0 0 0"/>
      <geometry>
        <mesh filename="package://human_description/meshes/rocket_box/l_foot.obj"/>
      </geometry>
      <material name="Blue"/>
    </visual>
    <collision>
      <origin rpy="0 0 0" xyz="0 0 0"/>
      <geometry>
        <mesh filename="package://human_description/meshes/rocket_box/l_foot.obj"/>
      </geometry>
    </collision>
    <inertial>
      <mass value="2.24629475115"/>
      <inertia ixx="0.00997119431636" ixy="-0.00032381616821" ixz="0.00003556416949" iyy="0.00325251065432" iyz="0.00137797584221" izz="0.01040399675772"/>
      <origin xyz="-0.00160579 0.04884521 -0.0783361"/>
    </inertial>
  </link>
	
	  
  <joint name="left_foot_endeffector_joint" type="revolute">
    <axis xyz="0 0 1"/>
    <limit effort="15" lower="0.0" upper="0.0" velocity="5"/>
    <origin rpy="0 0 0" xyz="0 0 -0.120162"/>
    <parent link="left_foot_x_link"/>
    <child link="left_foot_endeffector_link"/>
  </joint>

  <link name="left_foot_endeffector_link">
    <visual>
      <origin rpy="0 0 0" xyz="0 0 0"/>
      <geometry>
        <box size="0.001 0.001 0.001"/>
      </geometry>
      <material name="Blue"/>
    </visual>
  </link>
  
  

  <joint name="upper_right_leg_z_joint" type="revolute">
    <axis xyz="0 0 1"/>
    <limit effort="15" lower="-1" upper="1.57" velocity="5"/>
    <origin rpy="0 0 0" xyz="0.106044 -0.001956 -0.144300"/> 
    <parent link="pelvis_link"/>
    <child link="upper_right_leg_z_link"/>
  </joint>
  <joint name="upper_right_leg_y_joint" type="revolute">
    <axis xyz="0 1 0"/>
    <limit effort="15" lower="-0.7" upper="1.57" velocity="5"/>
    <origin rpy="0 0 0" xyz="0 0 0"/>
    <parent link="upper_right_leg_z_link"/>
    <child link="upper_right_leg_y_link"/>
  </joint>
  <joint name="upper_right_leg_x_joint" type="revolute">
    <axis xyz="1 0 0"/>
    <limit effort="15" lower="-1.2" upper="1.57" velocity="5"/>
    <origin rpy="0 0 0" xyz="0 0 0"/>
    <parent link="upper_right_leg_y_link"/>
    <child link="upper_right_leg_x_link"/>
  </joint>

  <link name="upper_right_leg_z_link"/>
  <link name="upper_right_leg_y_link"/>
  <link name="upper_right_leg_x_link">
    <visual>
      <origin rpy="0 0 0" xyz="0 0 0"/>
      <geometry>
        <mesh filename="package://human_description/meshes/rocket_box/r_upperleg.obj"/>
      </geometry>
      <material name="Blue"/>
    </visual>
    <collision>
      <origin rpy="0 0 0" xyz="0 0 0"/>
      <geometry>
        <mesh filename="package://human_description/meshes/rocket_box/r_upperleg.obj"/>
      </geometry>
    </collision>
    <inertial>
      <mass value="11.28066677275"/>
      <inertia ixx="0.258606759375" ixy="-0.000002463410605" ixz="-0.000322118806715" iyy="0.258311360625" iyz="-0.000065609865015" izz="0.021073428046875"/>
      <origin xyz="0.00364974 -0.00003172 -0.19576731"/>
    </inertial>
  </link>

  <joint name="lower_right_leg_joint" type="revolute">
    <axis xyz="1 0 0"/>
    <limit effort="15" lower="-2.4" upper="0" velocity="5"/>
    <origin rpy="0 0 0" xyz="0.025332 -0.01956 -0.47778"/>
    <parent link="upper_right_leg_x_link"/>
    <child link="lower_right_leg_link"/>
  </joint>

  <link name="lower_right_leg_link">
    <visual>
      <origin rpy="0 0 0" xyz="0 0 0"/>
      <geometry>
        <mesh filename="package://human_description/meshes/rocket_box/r_lowerleg.obj"/>
      </geometry>
      <material name="Blue"/>
    </visual>
    <collision>
      <origin rpy="0 0 0" xyz="0 0 0"/>
      <geometry>
        <mesh filename="package://human_description/meshes/rocket_box/r_lowerleg.obj"/>
      </geometry>
    </collision>
    <inertial>
      <mass value="8.394054321"/>
      <inertia ixx="0.1879741409375" ixy="0.000000001719205" ixz="-0.00000000509231" iyy="0.1879741525" iyz="-0.00000001780773" izz="0.01166299402353"/>
      <origin xyz="0.0 -0.00029422 -0.20195734"/>
    </inertial>
  </link>

  <joint name="right_foot_z_joint" type="revolute">
    <axis xyz="0 0 1"/>
    <limit effort="15" lower="0" upper="0.001" velocity="5"/>
    <origin rpy="0 0 0" xyz="0.008988 0.036996 -0.474504"/>
    <parent link="lower_right_leg_link"/>
    <child link="right_foot_z_link"/>
  </joint>
  <joint name="right_foot_y_joint" type="revolute">
    <axis xyz="0 1 0"/>
    <limit effort="15" lower="-0.5" upper="0.5" velocity="5"/>
    <origin rpy="0 0 0" xyz="0 0 0"/>
    <parent link="right_foot_z_link"/>
    <child link="right_foot_y_link"/>
  </joint>
  <joint name="right_foot_x_joint" type="revolute">
    <axis xyz="1 0 0"/>
    <limit effort="15" lower="-0.8" upper="0.6" velocity="5"/>
    <origin rpy="0 0 0" xyz="0 0 0"/>
    <parent link="right_foot_y_link"/>
    <child link="right_foot_x_link"/>
  </joint>

  <link name="right_foot_z_link"/>
  <link name="right_foot_y_link"/>
  <link name="right_foot_x_link">
    <visual>
      <origin rpy="0 0 0" xyz="0 0 0"/>
      <geometry>
        <mesh filename="package://human_description/meshes/rocket_box/r_foot.obj"/>
      </geometry>
      <material name="Blue"/>
    </visual>
    <collision>
      <origin rpy="0 0 0" xyz="0 0 0"/>
      <geometry>
        <mesh filename="package://human_description/meshes/rocket_box/r_foot.obj"/>
      </geometry>
    </collision>
    <inertial>
      <mass value="2.24629475115"/>
      <inertia ixx="0.00997119287114" ixy="0.00032381614564" ixz="-0.0000355639042" iyy="0.003252511015625" iyz="0.00137797638426" izz="0.01040399675772"/>
      <origin xyz="0.00160579 0.04884521 -0.0783361"/>
    </inertial>
  </link>
  	  
  <joint name="right_foot_endeffector_joint" type="revolute">
    <axis xyz="0 0 1"/>
    <limit effort="15" lower="0.0" upper="0.0" velocity="5"/>
    <origin rpy="0 0 0" xyz="0 0 -0.120162"/>
    <parent link="right_foot_x_link"/>
    <child link="right_foot_endeffector_link"/>
  </joint>

  <link name="right_foot_endeffector_link">
    <visual>
      <origin rpy="0 0 0" xyz="0 0 0"/>
      <geometry>
        <box size="0.001 0.001 0.001"/>
      </geometry>
      <material name="Blue"/>
    </visual>
  </link>

  <joint name="upper_left_specula_joint" type="revolute">
    <axis xyz="0 0 1"/>
    <limit effort="15" lower="-0" upper="0" velocity="5"/>
    <origin rpy="0 0 0" xyz="-0.0873828 0.0381 -0.153156"/>
    <parent link="head_x_link"/>
    <child link="upper_left_arm_specula_link"/>
  </joint>
  
  <link name="upper_left_arm_specula_link"/>
  
  <joint name="upper_left_arm_z_joint" type="revolute">
    <axis xyz="0 0 1"/>
    <limit effort="15" lower="-0.5" upper="0.5" velocity="5"/>
    <origin rpy="0 0 0" xyz="-0.169296 0 0"/>
    <parent link="upper_left_arm_specula_link"/>
    <child link="upper_left_arm_z_link"/>
  </joint>
  <joint name="upper_left_arm_y_joint" type="revolute">
    <axis xyz="0 1 0"/>
    <limit effort="15" lower="-3.14" upper="2.0" velocity="5"/>
    <origin rpy="0 0 0" xyz="0 0 0"/>
    <parent link="upper_left_arm_z_link"/>
    <child link="upper_left_arm_y_link"/>
  </joint>
  <joint name="upper_left_arm_x_joint" type="revolute">
    <axis xyz="1 0 0"/>
    <limit effort="15" lower="-1.0" upper="3.14" velocity="5"/>
    <origin rpy="0 0 0" xyz="0 0 0"/>
    <parent link="upper_left_arm_y_link"/>
    <child link="upper_left_arm_x_link"/>
  </joint>

  <link name="upper_left_arm_z_link"/>
  <link name="upper_left_arm_y_link"/>
  <link name="upper_left_arm_x_link">
    <visual>
      <origin rpy="0 0 0" xyz="0 0 0"/>
      <geometry>
        <mesh filename="package://human_description/meshes/rocket_box/l_upperarm.obj"/>
      </geometry>
      <material name="Blue"/>
    </visual>
    <collision>
      <origin rpy="0 0 0" xyz="0 0 0"/>
      <geometry>
        <mesh filename="package://human_description/meshes/rocket_box/l_upperarm.obj"/>
      </geometry>
    </collision>
    <inertial>
      <mass value="5.0428574576"/>
      <inertia ixx="0.05868383265625" ixy="-0.0000000925777" ixz="-0.00160419461921" iyy="0.05870381265625" iyz="-0.000002301658445" izz="0.006071859706985"/>
      <origin xyz="-0.00338773 -0.00000063 -0.17172602"/>
    </inertial>
  </link>

  <joint name="lower_left_arm_joint" type="revolute">
    <axis xyz="1 0 0"/>
    <limit effort="15" lower="0" upper="3.14" velocity="5"/>
    <origin rpy="0 0 0" xyz="-0.001464 -0.00114 -0.34296"/>
    <parent link="upper_left_arm_x_link"/>
    <child link="lower_left_arm_link"/>
  </joint>

  <link name="lower_left_arm_link">
    <visual>
      <origin rpy="0 0 0" xyz="0 0 0"/>
      <geometry>
        <mesh filename="package://human_description/meshes/rocket_box/l_forearm.obj"/>
      </geometry>
      <material name="Blue"/>
    </visual>
    <collision>
      <origin rpy="0 0 0" xyz="0 0 0"/>
      <geometry>
        <mesh filename="package://human_description/meshes/rocket_box/l_forearm.obj"/>
      </geometry>
    </collision>
    <inertial>
      <mass value="4.1174112191"/>
      <inertia ixx="0.046870596953125" ixy="-0.000000000013135" ixz="0.00000000291116" iyy="0.0468705940625" iyz="-0.00000000721685" izz="0.00412573450193"/>
      <origin xyz="0.0 0.00000002 -0.14231966"/>
    </inertial>
  </link>

  <joint name="left_hand_z_joint" type="revolute">
    <axis xyz="0 0 1"/>
    <limit effort="15" lower="-1.0" upper="1.0" velocity="5"/>
    <origin rpy="0 0 0" xyz="-0.001728 -0.004992 -0.325056"/>
    <parent link="lower_left_arm_link"/>
    <child link="left_hand_z_link"/>
  </joint>
  <joint name="left_hand_y_joint" type="revolute">
    <axis xyz="0 1 0"/>
    <limit effort="15" lower="-1.3" upper="1.5" velocity="5"/>
    <origin rpy="0 0 0" xyz="0 0 0"/>
    <parent link="left_hand_z_link"/>
    <child link="left_hand_y_link"/>
  </joint>
  <joint name="left_hand_x_joint" type="revolute">
    <axis xyz="1 0 0"/>
    <limit effort="15" lower="-0.5" upper="1.4" velocity="5"/>
    <origin rpy="0 0 0" xyz="0 0 0"/>
    <parent link="left_hand_y_link"/>
    <child link="left_hand_x_link"/>
  </joint>

  <link name="left_hand_z_link"/>
  <link name="left_hand_y_link"/>
  <link name="left_hand_x_link">
    <visual>
      <origin rpy="0 0 0" xyz="0 0 0"/>
      <geometry>
        <mesh filename="package://human_description/meshes/rocket_box/l_hand.obj"/>
      </geometry>
      <material name="Blue"/>
    </visual>
    <collision>
      <origin rpy="0 0 0" xyz="0 0 0"/>
      <geometry>
        <mesh filename="package://human_description/meshes/rocket_box/l_hand.obj"/>
      </geometry>
    </collision>
    <inertial>
      <mass value="0.5669499677"/>
      <inertia ixx="0.00201160057137" ixy="-0.000016142435665" ixz="-0.00000510135428" iyy="0.00161538206057" iyz="0.00004737239241" izz="0.00044905660648"/>
      <origin xyz="-0.00417106 0.0042704 -0.05959476"/>
    </inertial>
  </link>

  <joint name="left_hand_endeffector_joint" type="revolute">
    <axis xyz="0 0 1"/>
    <limit effort="15" lower="-0.001" upper="0.001" velocity="5"/>
    <origin rpy="0 0 0" xyz="-0.009816 0.007404 -0.21684"/>
    <parent link="left_hand_x_link"/>
    <child link="left_hand_endeffector_link"/>
  </joint>

  <link name="left_hand_endeffector_link">
    <visual>
      <origin rpy="0 0 0" xyz="0 0 0"/>
      <geometry>
        <box size="0.001 0.001 0.001"/>
      </geometry>
      <material name="Blue"/>
    </visual>
    <collision>
      <origin rpy="0 0 0" xyz="0 0 0"/>
      <geometry>
        <box size="0.001 0.001 0.001"/>
      </geometry>
    </collision>
  </link>

  
  <joint name="upper_right_specula_joint" type="revolute">
    <axis xyz="1 0 0"/>
    <limit effort="15" lower="-0" upper="0" velocity="5"/>
    <origin rpy="0 0 0" xyz="0.0873852 0.0381 -0.153312"/>
    <parent link="head_x_link"/>
    <child link="upper_right_arm_specula_link"/>
  </joint>
    
  <link name="upper_right_arm_specula_link"/>
  
  <joint name="upper_right_arm_z_joint" type="revolute">
    <axis xyz="0 0 1"/>
    <limit effort="15" lower="-0.5" upper="0.5" velocity="5"/>
    <origin rpy="0 0 0" xyz="0.16926 0.003768 -0.0003"/>
    <parent link="upper_right_arm_specula_link"/>
    <child link="upper_right_arm_z_link"/>
  </joint>
  <joint name="upper_right_arm_y_joint" type="revolute">
    <axis xyz="0 1 0"/>
    <limit effort="15" lower="-2.0" upper="3.14" velocity="5"/>
    <origin rpy="0 0 0" xyz="0 0 0"/>
    <parent link="upper_right_arm_z_link"/>
    <child link="upper_right_arm_y_link"/>
  </joint>
  <joint name="upper_right_arm_x_joint" type="revolute">
    <axis xyz="1 0 0"/>
    <limit effort="15" lower="-1.0" upper="3.14" velocity="5"/>
    <origin rpy="0 0 0" xyz="0 0 0"/>
    <parent link="upper_right_arm_y_link"/>
    <child link="upper_right_arm_x_link"/>
  </joint>

  <link name="upper_right_arm_z_link"/>
  <link name="upper_right_arm_y_link"/>
  <link name="upper_right_arm_x_link">
    <visual>
      <origin rpy="0 0 0" xyz="0 0 0"/>
      <geometry>
        <mesh filename="package://human_description/meshes/rocket_box/r_upperarm.obj"/>
      </geometry>
      <material name="Blue"/>
    </visual>
    <collision>
      <origin rpy="0 0 0" xyz="0 0 0"/>
      <geometry>
        <mesh filename="package://human_description/meshes/rocket_box/r_upperarm.obj"/>
      </geometry>
    </collision>
    <inertial>
      <mass value="5.0428574576"/>
      <inertia ixx="0.05868383265625" ixy="0.00000009260175" ixz="0.00160419479977" iyy="0.05870381265625" iyz="-0.000002301500825" izz="0.006071859706985"/>
      <origin xyz="0.00338773 -0.00000063 -0.17172602"/>
    </inertial>
  </link>

  <joint name="lower_right_arm_joint" type="revolute">
    <axis xyz="1 0 0"/>
    <limit effort="15" lower="0" upper="3.14" velocity="5"/>
    <origin rpy="0 0 0" xyz="-0.005592 -0.007404 -0.342828"/>
    <parent link="upper_right_arm_x_link"/>
    <child link="lower_right_arm_link"/>
  </joint>

  <link name="lower_right_arm_link">
    <visual>
      <origin rpy="0 0 0" xyz="0 0 0"/>
      <geometry>
        <mesh filename="package://human_description/meshes/rocket_box/r_forearm.obj"/>
      </geometry>
      <material name="Blue"/>
    </visual>
    <collision>
      <origin rpy="0 0 0" xyz="0 0 0"/>
      <geometry>
        <mesh filename="package://human_description/meshes/rocket_box/r_forearm.obj"/>
      </geometry>
    </collision>
    <inertial>
      <mass value="4.1174112191"/>
      <inertia ixx="0.046870596953125" ixy="-0.000000000013135" ixz="0.00000000291116" iyy="0.0468705940625" iyz="-0.00000000721685" izz="0.00412573450193"/>
      <origin xyz="0.0 0.00000002 -0.14231966"/>
    </inertial>
  </link>

  <joint name="right_hand_z_joint" type="revolute">
    <axis xyz="0 0 1"/>
    <limit effort="15" lower="-1.0" upper="1.0" velocity="5"/>
    <origin rpy="0 0 0" xyz="-0.004728 -0.003084 -0.325056"/>
    <parent link="lower_right_arm_link"/>
    <child link="right_hand_z_link"/>
  </joint>
  <joint name="right_hand_y_joint" type="revolute">
    <axis xyz="0 1 0"/>
    <limit effort="15" lower="-1.5" upper="1.3" velocity="5"/>
    <origin rpy="0 0 0" xyz="0 0 0"/>
    <parent link="right_hand_z_link"/>
    <child link="right_hand_y_link"/>
  </joint>
  <joint name="right_hand_x_joint" type="revolute">
    <axis xyz="1 0 0"/>
    <limit effort="15" lower="-0.5" upper="1.4" velocity="5"/>
    <origin rpy="0 0 0" xyz="0 0 0"/>
    <parent link="right_hand_y_link"/>
    <child link="right_hand_x_link"/>
  </joint>

  <link name="right_hand_z_link"/>
  <link name="right_hand_y_link"/>
  <link name="right_hand_x_link">
    <visual>
      <origin rpy="0 0 0" xyz="0 0 0"/>
      <geometry>
        <mesh filename="package://human_description/meshes/rocket_box/r_hand.obj"/>
      </geometry>
      <material name="Blue"/>
    </visual>
    <collision>
      <origin rpy="0 0 0" xyz="0 0 0"/>
      <geometry>
        <mesh filename="package://human_description/meshes/rocket_box/r_hand.obj"/>
      </geometry>
    </collision>
    <inertial>
      <mass value="0.5669499677"/>
      <inertia ixx="0.00201160057137" ixy="0.000016142435665" ixz="0.00000510133208" iyy="0.00161538206057" iyz="0.00004737239241" izz="0.00044905660648"/>
      <origin xyz="0.00417106 0.0042704 -0.05959476"/>
    </inertial>
  </link>

  <joint name="right_hand_endeffector_joint" type="revolute">
    <axis xyz="0 0 1"/>
    <limit effort="15" lower="-0.001" upper="0.001" velocity="5"/>
    <origin rpy="0 0 0" xyz="-0.000348 0.010884 -0.21684"/>
    <parent link="right_hand_x_link"/>
    <child link="right_hand_endeffector_link"/>
  </joint>

  <link name="right_hand_endeffector_link">
    <visual>
      <origin rpy="0 0 0" xyz="0 0 0"/>
      <geometry>
        <box size="0.001 0.001 0.001"/>
      </geometry>
      <material name="Blue"/>
    </visual>
    <collision>
      <origin rpy="0 0 0" xyz="0 0 0"/>
      <geometry>
        <box size="0.001 0.001 0.001"/>
      </geometry>
    </collision>
  </link>
  
  
<link name="left_foot_cp_1_link">
    <visual>
      <origin rpy="0 0 0" xyz="0 0 0"/>
      <geometry>
        <box size="0.001 0.001 0.001"/>
      </geometry>
      <material name="Blue"/>
    </visual>
    <inertial>
      <mass value="0"/>
      <inertia ixx="1" ixy="0" ixz="0" iyy="1" iyz="0" izz="0"/>
      <origin xyz="0 0 0"/>
    </inertial>
  </link>
  <link name="left_foot_cp_2_link">
    <visual>
      <origin rpy="0 0 0" xyz="0 0 0"/>
      <geometry>
        <box size="0.001 0.001 0.001"/>
      </geometry>
      <material name="Blue"/>
    </visual>
    <inertial>
      <mass value="0"/>
      <inertia ixx="1" ixy="0" ixz="0" iyy="1" iyz="0" izz="0"/>
      <origin xyz="0 0 0"/>
    </inertial>
  </link>
  <link name="left_foot_cp_3_link">
    <visual>
      <origin rpy="0 0 0" xyz="0 0 0"/>
      <geometry>
        <box size="0.001 0.001 0.001"/>
      </geometry>
      <material name="Blue"/>
    </visual>
    <inertial>
      <mass value="0"/>
      <inertia ixx="1" ixy="0" ixz="0" iyy="1" iyz="0" izz="0"/>
      <origin xyz="0 0 0"/>
    </inertial>
  </link>
  <link name="left_foot_cp_4_link">
    <visual>
      <origin rpy="0 0 0" xyz="0 0 0"/>
      <geometry>
        <box size="0.001 0.001 0.001"/>
      </geometry>
      <material name="Blue"/>
    </visual>
    <inertial>
      <mass value="0"/>
      <inertia ixx="1" ixy="0" ixz="0" iyy="1" iyz="0" izz="0"/>
      <origin xyz="0 0 0"/>
    </inertial>
  </link>
  <joint name="left_foot_cp_1_joint" type="revolute">
    <axis xyz="0 0 1"/>
    <limit effort="15" lower="0" upper="0" velocity="5"/>
    <origin rpy="0 0 0" xyz="0.08027 0.27372 0.0"/>
    <parent link="left_foot_endeffector_link"/>
    <child link="left_foot_cp_1_link"/>
  </joint>
  <joint name="left_foot_cp_2_joint" type="revolute">
    <axis xyz="0 0 1"/>
    <limit effort="15" lower="0" upper="0" velocity="5"/>
    <origin rpy="0 0 0" xyz="-0.09166 0.27372 0.0"/>
    <parent link="left_foot_endeffector_link"/>
    <child link="left_foot_cp_2_link"/>
  </joint>
  <joint name="left_foot_cp_3_joint" type="revolute">
    <axis xyz="0 0 1"/>
    <limit effort="15" lower="0" upper="0" velocity="5"/>
    <origin rpy="0 0 0" xyz="-0.09166 -0.07769 0.0"/>
    <parent link="left_foot_endeffector_link"/>
    <child link="left_foot_cp_3_link"/>
  </joint>
  <joint name="left_foot_cp_4_joint" type="revolute">
    <axis xyz="0 0 1"/>
    <limit effort="15" lower="0" upper="0" velocity="5"/>
    <origin rpy="0 0 0" xyz="0.08027 -0.07769 0.0"/>
    <parent link="left_foot_endeffector_link"/>
    <child link="left_foot_cp_4_link"/>
  </joint>
<link name="right_foot_cp_1_link">
    <visual>
      <origin rpy="0 0 0" xyz="0 0 0"/>
      <geometry>
        <box size="0.001 0.001 0.001"/>
      </geometry>
      <material name="Blue"/>
    </visual>
    <inertial>
      <mass value="0"/>
      <inertia ixx="1" ixy="0" ixz="0" iyy="1" iyz="0" izz="0"/>
      <origin xyz="0 0 0"/>
    </inertial>
  </link>
  <link name="right_foot_cp_2_link">
    <visual>
      <origin rpy="0 0 0" xyz="0 0 0"/>
      <geometry>
        <box size="0.001 0.001 0.001"/>
      </geometry>
      <material name="Blue"/>
    </visual>
    <inertial>
      <mass value="0"/>
      <inertia ixx="1" ixy="0" ixz="0" iyy="1" iyz="0" izz="0"/>
      <origin xyz="0 0 0"/>
    </inertial>
  </link>
  <link name="right_foot_cp_3_link">
    <visual>
      <origin rpy="0 0 0" xyz="0 0 0"/>
      <geometry>
        <box size="0.001 0.001 0.001"/>
      </geometry>
      <material name="Blue"/>
    </visual>
    <inertial>
      <mass value="0"/>
      <inertia ixx="1" ixy="0" ixz="0" iyy="1" iyz="0" izz="0"/>
      <origin xyz="0 0 0"/>
    </inertial>
  </link>
  <link name="right_foot_cp_4_link">
    <visual>
      <origin rpy="0 0 0" xyz="0 0 0"/>
      <geometry>
        <box size="0.001 0.001 0.001"/>
      </geometry>
      <material name="Blue"/>
    </visual>
    <inertial>
      <mass value="0"/>
      <inertia ixx="1" ixy="0" ixz="0" iyy="1" iyz="0" izz="0"/>
      <origin xyz="0 0 0"/>
    </inertial>
  </link>
  <joint name="right_foot_cp_1_joint" type="revolute">
    <axis xyz="0 0 1"/>
    <limit effort="15" lower="0" upper="0" velocity="5"/>
    <origin rpy="0 0 0" xyz="0.10495 0.2684 0.0"/>
    <parent link="right_foot_endeffector_link"/>
    <child link="right_foot_cp_1_link"/>
  </joint>
  <joint name="right_foot_cp_2_joint" type="revolute">
    <axis xyz="0 0 1"/>
    <limit effort="15" lower="0" upper="0" velocity="5"/>
    <origin rpy="0 0 0" xyz="-0.06698 0.2684 0.0"/>
    <parent link="right_foot_endeffector_link"/>
    <child link="right_foot_cp_2_link"/>
  </joint>
  <joint name="right_foot_cp_3_joint" type="revolute">
    <axis xyz="0 0 1"/>
    <limit effort="15" lower="0" upper="0" velocity="5"/>
    <origin rpy="0 0 0" xyz="-0.06698 -0.08301 0.0"/>
    <parent link="right_foot_endeffector_link"/>
    <child link="right_foot_cp_3_link"/>
  </joint>
  <joint name="right_foot_cp_4_joint" type="revolute">
    <axis xyz="0 0 1"/>
    <limit effort="15" lower="0" upper="0" velocity="5"/>
    <origin rpy="0 0 0" xyz="0.10495 -0.08301 0.0"/>
    <parent link="right_foot_endeffector_link"/>
    <child link="right_foot_cp_4_link"/>
  </joint>

<link name="left_hand_cp_1_link">
    <visual>
      <origin rpy="0 0 0" xyz="0 0 0"/>
      <geometry>
        <box size="0.001 0.001 0.001"/>
      </geometry>
      <material name="Blue"/>
    </visual>
    <inertial>
      <mass value="0"/>
      <inertia ixx="1" ixy="0" ixz="0" iyy="1" iyz="0" izz="0"/>
      <origin xyz="0 0 0"/>
    </inertial>
  </link>
  <link name="left_hand_cp_2_link">
    <visual>
      <origin rpy="0 0 0" xyz="0 0 0"/>
      <geometry>
        <box size="0.001 0.001 0.001"/>
      </geometry>
      <material name="Blue"/>
    </visual>
    <inertial>
      <mass value="0"/>
      <inertia ixx="1" ixy="0" ixz="0" iyy="1" iyz="0" izz="0"/>
      <origin xyz="0 0 0"/>
    </inertial>
  </link>
  <link name="left_hand_cp_3_link">
    <visual>
      <origin rpy="0 0 0" xyz="0 0 0"/>
      <geometry>
        <box size="0.001 0.001 0.001"/>
      </geometry>
      <material name="Blue"/>
    </visual>
    <inertial>
      <mass value="0"/>
      <inertia ixx="1" ixy="0" ixz="0" iyy="1" iyz="0" izz="0"/>
      <origin xyz="0 0 0"/>
    </inertial>
  </link>
  <link name="left_hand_cp_4_link">
    <visual>
      <origin rpy="0 0 0" xyz="0 0 0"/>
      <geometry>
        <box size="0.001 0.001 0.001"/>
      </geometry>
      <material name="Blue"/>
    </visual>
    <inertial>
      <mass value="0"/>
      <inertia ixx="1" ixy="0" ixz="0" iyy="1" iyz="0" izz="0"/>
      <origin xyz="0 0 0"/>
    </inertial>
  </link>
  <joint name="left_hand_cp_1_joint" type="revolute">
    <axis xyz="0 0 1"/>
    <limit effort="15" lower="0" upper="0" velocity="5"/>
    <origin rpy="0 0 0" xyz="0.01757 0.0606 -0.22569"/>
    <parent link="left_hand_x_link"/>
    <child link="left_hand_cp_1_link"/>
  </joint>
  <joint name="left_hand_cp_2_joint" type="revolute">
    <axis xyz="0 0 1"/>
    <limit effort="15" lower="0" upper="0" velocity="5"/>
    <origin rpy="0 0 0" xyz="0.01757 -0.06468 -0.22569"/>
    <parent link="left_hand_x_link"/>
    <child link="left_hand_cp_2_link"/>
  </joint>
  <joint name="left_hand_cp_3_joint" type="revolute">
    <axis xyz="0 0 1"/>
    <limit effort="15" lower="0" upper="0" velocity="5"/>
    <origin rpy="0 0 0" xyz="0.01757 -0.06468 -0.02705"/>
    <parent link="left_hand_x_link"/>
    <child link="left_hand_cp_3_link"/>
  </joint>
  <joint name="left_hand_cp_4_joint" type="revolute">
    <axis xyz="0 0 1"/>
    <limit effort="15" lower="0" upper="0" velocity="5"/>
    <origin rpy="0 0 0" xyz="0.01757 0.0606 -0.02705"/>
    <parent link="left_hand_x_link"/>
    <child link="left_hand_cp_4_link"/>
  </joint>
<link name="right_hand_cp_1_link">
    <visual>
      <origin rpy="0 0 0" xyz="0 0 0"/>
      <geometry>
        <box size="0.001 0.001 0.001"/>
      </geometry>
      <material name="Blue"/>
    </visual>
    <inertial>
      <mass value="0"/>
      <inertia ixx="1" ixy="0" ixz="0" iyy="1" iyz="0" izz="0"/>
      <origin xyz="0 0 0"/>
    </inertial>
  </link>
  <link name="right_hand_cp_2_link">
    <visual>
      <origin rpy="0 0 0" xyz="0 0 0"/>
      <geometry>
        <box size="0.001 0.001 0.001"/>
      </geometry>
      <material name="Blue"/>
    </visual>
    <inertial>
      <mass value="0"/>
      <inertia ixx="1" ixy="0" ixz="0" iyy="1" iyz="0" izz="0"/>
      <origin xyz="0 0 0"/>
    </inertial>
  </link>
  <link name="right_hand_cp_3_link">
    <visual>
      <origin rpy="0 0 0" xyz="0 0 0"/>
      <geometry>
        <box size="0.001 0.001 0.001"/>
      </geometry>
      <material name="Blue"/>
    </visual>
    <inertial>
      <mass value="0"/>
      <inertia ixx="1" ixy="0" ixz="0" iyy="1" iyz="0" izz="0"/>
      <origin xyz="0 0 0"/>
    </inertial>
  </link>
  <link name="right_hand_cp_4_link">
    <visual>
      <origin rpy="0 0 0" xyz="0 0 0"/>
      <geometry>
        <box size="0.001 0.001 0.001"/>
      </geometry>
      <material name="Blue"/>
    </visual>
    <inertial>
      <mass value="0"/>
      <inertia ixx="1" ixy="0" ixz="0" iyy="1" iyz="0" izz="0"/>
      <origin xyz="0 0 0"/>
    </inertial>
  </link>
  <joint name="right_hand_cp_1_joint" type="revolute">
    <axis xyz="0 0 1"/>
    <limit effort="15" lower="0" upper="0" velocity="5"/>
    <origin rpy="0 0 0" xyz="-0.01229 0.05553 -0.01712"/>
    <parent link="right_hand_x_link"/>
    <child link="right_hand_cp_1_link"/>
  </joint>
  <joint name="right_hand_cp_2_joint" type="revolute">
    <axis xyz="0 0 1"/>
    <limit effort="15" lower="0" upper="0" velocity="5"/>
    <origin rpy="0 0 0" xyz="-0.01229 -0.06975 -0.01712"/>
    <parent link="right_hand_x_link"/>
    <child link="right_hand_cp_2_link"/>
  </joint>
  <joint name="right_hand_cp_3_joint" type="revolute">
    <axis xyz="0 0 1"/>
    <limit effort="15" lower="0" upper="0" velocity="5"/>
    <origin rpy="0 0 0" xyz="-0.01229 -0.06975 -0.21577"/>
    <parent link="right_hand_x_link"/>
    <child link="right_hand_cp_3_link"/>
  </joint>
  <joint name="right_hand_cp_4_joint" type="revolute">
    <axis xyz="0 0 1"/>
    <limit effort="15" lower="0" upper="0" velocity="5"/>
    <origin rpy="0 0 0" xyz="-0.01229 0.05553 -0.21577"/>
    <parent link="right_hand_x_link"/>
    <child link="right_hand_cp_4_link"/>
  </joint>

</robot>

