<?xml version="1.0"?>
<robot xmlns:sensor="http://playerstage.sourceforge.net/gazebo/xmlschema/#sensor"
       xmlns:controller="http://playerstage.sourceforge.net/gazebo/xmlschema/#controller"
       xmlns:interface="http://playerstage.sourceforge.net/gazebo/xmlschema/#interface"
       xmlns:xacro="http://playerstage.sourceforge.net/gazebo/xmlschema/#interface"
       name="rocketbox_male" >

  <material name="Blue">
    <color rgba="0.0 0.0 0.8 1.0"/>
  </material>
  <material name="Green">
    <color rgba="0.0 0.8 0.0 1.0"/>
  </material>
  <material name="Grey">
    <color rgba="0.7 0.7 0.7 1.0"/>
  </material>
  <material name="Grey2">
    <color rgba="0.9 0.9 0.9 1.0"/>
  </material>
  <material name="Red">
    <color rgba="0.8 0.0 0.0 1.0"/>
  </material>
  <material name="White">
    <color rgba="1.0 1.0 1.0 1.0"/>
  </material>
  <material name="Black">
    <color rgba="0.1 0.1 0.1 1.0"/>
  </material>
  <material name="LightGrey">
    <color rgba="0.6 0.6 0.6 1.0"/>
  </material>

  <link name="root_link"/>
  <link name="base_prismatic_dummy1"/>
  <link name="base_prismatic_dummy2"/>
  <link name="base_prismatic_dummy3"/>
  <link name="base_revolute_dummy1"/>
  <link name="base_revolute_dummy2"/>

  <joint name="base_prismatic_joint_x" type="prismatic">
    <axis xyz="1 0 0"/>
    <limit effort="10000" lower="-60.0" upper="60.0" velocity="0.6"/>
    <safety_controller k_position="100" k_velocity="2000000" soft_lower_limit="-59.9" soft_upper_limit="59.9"/>
    <calibration falling="0.00536"/>
    <dynamics damping="20000.0"/>
    <origin rpy="0 0 0" xyz="0 0 1.21"/>
    <parent link="root_link"/>
    <child link="base_prismatic_dummy1"/>
  </joint>
  <joint name="base_prismatic_joint_y" type="prismatic">
    <axis xyz="0 1 0"/>
    <limit effort="10000" lower="-60.0" upper="60.0" velocity="0.6"/>
    <safety_controller k_position="100" k_velocity="2000000" soft_lower_limit="-59.9" soft_upper_limit="59.9"/>
    <calibration falling="0.00536"/>
    <dynamics damping="20000.0"/>
    <origin rpy="0 0 0" xyz="0 0 0"/>
    <parent link="base_prismatic_dummy1"/>
    <child link="base_prismatic_dummy2"/>
  </joint>
  <joint name="base_prismatic_joint_z" type="prismatic">
    <axis xyz="0 0 1"/>
    <limit effort="10000" lower="-100.0" upper="100.0" velocity="0.6"/>
    <safety_controller k_position="100" k_velocity="2000000" soft_lower_limit="-99.9" soft_upper_limit="99.9"/>
    <calibration falling="0.00536"/>
    <dynamics damping="20000.0"/>
    <origin rpy="0 0 0" xyz="0 0 0"/>
    <parent link="base_prismatic_dummy2"/>
    <child link="base_prismatic_dummy3"/>
  </joint>
  <joint name="base_revolute_joint_x" type="continuous">
    <axis xyz="1 0 0"/>
    <origin rpy="0 0 0" xyz="0 0 0"/>
    <parent link="base_prismatic_dummy3"/>
    <child link="base_revolute_dummy1"/>
  </joint>
  <joint name="base_revolute_joint_y" type="continuous">
    <axis xyz="0 1 0"/>
    <origin rpy="0 0 0" xyz="0 0 0"/>
    <parent link="base_revolute_dummy1"/>
    <child link="base_revolute_dummy2"/>
  </joint>
  <joint name="base_revolute_joint_z" type="continuous">
    <axis xyz="0 0 1"/>
    <origin rpy="0 0 0" xyz="0 0 0"/>
    <parent link="base_revolute_dummy2"/>
    <child link="pelvis_link"/>
  </joint>  
  <link name="pelvis_link">
    <inertial>
      <mass value="11.5"/>
      <inertia ixx="0.22" ixy="0.0" ixz="0.0" iyy="0.22" iyz="0.0" izz="0.23"/>
      <origin xyz="0 0 0.10"/>
    </inertial>
  </link>	  
  <joint name="torso_z_joint" type="continuous">
    <axis xyz="0 0 1"/>
    <limit effort="15" lower="-0.7" upper="0.7" velocity="5"/>
    <origin rpy="0 0 0" xyz="0 0.0 0.33"/>
    <parent link="pelvis_link"/>
    <child link="torso_z_link"/>
  </joint>
  <joint name="torso_y_joint" type="continuous">
    <axis xyz="0 1 0"/>
    <limit effort="15" lower="-0.3" upper="0.3" velocity="5"/>
    <origin rpy="0 0 0" xyz="0 0 0"/>
    <parent link="torso_z_link"/>
    <child link="torso_y_link"/>
  </joint>
  <joint name="torso_x_joint" type="continuous">
    <axis xyz="1 0 0"/>
    <limit effort="15" lower="-1.0" upper="0" velocity="5"/>
    <origin rpy="0 0 0" xyz="0 0 0"/>
    <parent link="torso_y_link"/>
    <child link="torso_x_link"/>
  </joint>  

  <link name="torso_z_link"/>
  <link name="torso_y_link"/>
  <link name="torso_x_link">
    <visual>
      <origin rpy="0 0 0" xyz="0 0 0"/>
      <geometry>
        <mesh filename="package://human_description/meshes/rocket_box/torso.obj"/>
      </geometry>
      <material name="Blue"/>
    </visual>
    <collision>
      <origin rpy="0 0 0" xyz="0 0 0"/>
      <geometry>
        <mesh filename="package://human_description/meshes/rocket_box/torso.obj"/>
      </geometry>
    </collision>
    <inertial>
      <mass value="20.0"/>
      <inertia ixx="1.09" ixy="0.0" ixz="0.0" iyy="1.45" iyz="0.0" izz="0.68"/>
      <origin xyz="0 0 0.23"/>
    </inertial>
  </link>  
  
  <joint name="head_z_joint" type="continuous">
    <axis xyz="0 0 1"/>
    <limit effort="15" lower="-1.2" upper="1.2" velocity="5"/>
    <origin rpy="0 0 0" xyz="0 0 0.5"/>
    <parent link="torso_x_link"/>
    <child link="head_z_link"/>
  </joint>
  <joint name="head_y_joint" type="continuous">
    <axis xyz="0 1 0"/>
    <limit effort="15" lower="-0.8" upper="0.8" velocity="5"/>
    <origin rpy="0 0 0" xyz="0 0 0"/>
    <parent link="head_z_link"/>
    <child link="head_y_link"/>
  </joint>
  <joint name="head_x_joint" type="continuous">
    <axis xyz="1 0 0"/>
    <limit effort="15" lower="-1.57" upper="0.3" velocity="5"/>
    <origin rpy="0 0 0" xyz="0 0 0"/>
    <parent link="head_y_link"/>
    <child link="head_x_link"/>
  </joint>

  <link name="head_z_link"/>
  <link name="head_y_link"/>
  <link name="head_x_link">
    <visual>
      <origin rpy="0 0 0" xyz="0 0 0"/>
      <geometry>
        <mesh filename="package://human_description/meshes/rocket_box/head.obj"/>
      </geometry>
      <material name="Blue"/>
    </visual>
    <collision>
      <origin rpy="0 0 0" xyz="0 0 0"/>
      <geometry>
        <mesh filename="package://human_description/meshes/rocket_box/head.obj"/>
      </geometry>
    </collision>
    <inertial>
      <mass value="4.0"/>
      <inertia ixx="0.19" ixy="0.0" ixz="0.0" iyy="0.19" iyz="0.0" izz="0.06"/>
      <origin xyz="0.0 0.0 0.19"/>
    </inertial>
  </link>
  
  <joint name="head_endeffector_joint" type="fixed">
    <axis xyz="0 0 1"/>
    <limit effort="15" lower="-0.001" upper="0.001" velocity="5"/>
    <origin rpy="0 0 0" xyz="0 -0.04 0.25"/>
    <parent link="head_x_link"/>
    <child link="head_endeffector_link"/>
  </joint>

  <link name="head_endeffector_link"/>

  <joint name="upper_left_leg_z_joint" type="continuous">
    <axis xyz="0 0 1"/>
    <limit effort="15" lower="-1.57" upper="1" velocity="5"/>
    <origin rpy="0 0 0" xyz="-0.10 0.0 -0.14"/>
    <parent link="pelvis_link"/>
    <child link="upper_left_leg_z_link"/>
  </joint>
  <joint name="upper_left_leg_y_joint" type="continuous">
    <axis xyz="0 1 0"/>
    <limit effort="15" lower="-1.57" upper="0.7" velocity="5"/>
    <origin rpy="0 0 0" xyz="0 0 0"/>
    <parent link="upper_left_leg_z_link"/>
    <child link="upper_left_leg_y_link"/>
  </joint>
  <joint name="upper_left_leg_x_joint" type="continuous">
    <axis xyz="1 0 0"/>
    <limit effort="15" lower="-1.2" upper="1.57" velocity="5"/>
    <origin rpy="0 0 0" xyz="0 0 0"/>
    <parent link="upper_left_leg_y_link"/>
    <child link="upper_left_leg_x_link"/>
  </joint>

  <link name="upper_left_leg_z_link"/>
  <link name="upper_left_leg_y_link"/>
  <link name="upper_left_leg_x_link">
    <visual>
      <origin rpy="0 0 0" xyz="0 0 0"/>
      <geometry>
        <mesh filename="package://human_description/meshes/rocket_box/l_lupperleg.obj"/>
      </geometry>
      <material name="Blue"/>
    </visual>
    <collision>
      <origin rpy="0 0 0" xyz="0 0 0"/>
      <geometry>
        <mesh filename="package://human_description/meshes/rocket_box/l_lupperleg.obj"/>
      </geometry>
    </collision>
    <inertial>
      <mass value="4.5"/>
      <inertia ixx="0.26" ixy="0.0" ixz="0.0" iyy="0.26" iyz="0.0" izz="0.02"/>
      <origin xyz="0.0 0.0 -0.20"/>
    </inertial>
  </link>

  <joint name="lower_left_leg_joint" type="continuous">
    <axis xyz="1 0 0"/>
    <limit effort="15" lower="-2.4" upper="0" velocity="5"/>
    <origin rpy="0 0 0" xyz="-0.03 -0.02 -0.48"/>
    <parent link="upper_left_leg_x_link"/>
    <child link="lower_left_leg_link"/>
  </joint>

  <link name="lower_left_leg_link">
    <visual>
      <origin rpy="0 0 0" xyz="0 0 0"/>
      <geometry>
        <mesh filename="package://human_description/meshes/rocket_box/l_lowerleg.obj"/>
      </geometry>
      <material name="Blue"/>
    </visual>
    <collision>
      <origin rpy="0 0 0" xyz="0 0 0"/>
      <geometry>
        <mesh filename="package://human_description/meshes/rocket_box/l_lowerleg.obj"/>
      </geometry>
    </collision>
    <inertial>
      <mass value="3.0"/>
      <inertia ixx="0.19" ixy="0.0" ixz="0.0" iyy="0.19" iyz="0.0" izz="0.01"/>
      <origin xyz="0.0 0.0 -0.20"/>
    </inertial>
  </link>

  <joint name="left_foot_z_joint" type="continuous">
    <axis xyz="0 0 1"/>
    <limit effort="15" lower="-0.01" upper="0" velocity="5"/>
    <origin rpy="0 0 0" xyz="-0.01 0.04 -0.47"/>
    <parent link="lower_left_leg_link"/>
    <child link="left_foot_z_link"/>
  </joint>
  <joint name="left_foot_y_joint" type="continuous">
    <axis xyz="0 1 0"/>
    <limit effort="15" lower="-0.5" upper="0.5" velocity="5"/>
    <origin rpy="0 0 0" xyz="0 0 0"/>
    <parent link="left_foot_z_link"/>
    <child link="left_foot_y_link"/>
  </joint>
  <joint name="left_foot_x_joint" type="continuous">
    <axis xyz="1 0 0"/>
    <limit effort="15" lower="-0.8" upper="0.6" velocity="5"/>
    <origin rpy="0 0 0" xyz="0 0 0"/>
    <parent link="left_foot_y_link"/>
    <child link="left_foot_x_link"/>
  </joint>

  <link name="left_foot_z_link"/>
  <link name="left_foot_y_link"/>
  <link name="left_foot_x_link">
    <visual>
      <origin rpy="0 0 0" xyz="0 0 0"/>
      <geometry>
        <mesh filename="package://human_description/meshes/rocket_box/l_foot.obj"/>
      </geometry>
      <material name="Blue"/>
    </visual>
    <collision>
      <origin rpy="0 0 0" xyz="0 0 0"/>
      <geometry>
        <mesh filename="package://human_description/meshes/rocket_box/l_foot.obj"/>
      </geometry>
    </collision>
    <inertial>
      <mass value="1.0"/>
      <inertia ixx="0.01" ixy="0.0" ixz="0.0" iyy="0.01" iyz="0.0" izz="0.01"/>
      <origin xyz="0.0 0.04 -0.08"/>
    </inertial>
  </link>
	
	  
  <joint name="left_foot_endeffector_joint" type="revolute">
    <axis xyz="0 0 1"/>
    <limit effort="15" lower="0.0" upper="0.0" velocity="5"/>
    <origin rpy="0 0 0" xyz="0 0 -0.12"/>
    <parent link="left_foot_x_link"/>
    <child link="left_foot_endeffector_link"/>
  </joint>

  <link name="left_foot_endeffector_link"/>  

  <joint name="upper_right_leg_z_joint" type="continuous">
    <axis xyz="0 0 1"/>
    <limit effort="15" lower="-1" upper="1.57" velocity="5"/>
    <origin rpy="0 0 0" xyz="0.10 0.0 -0.14"/> 
    <parent link="pelvis_link"/>
    <child link="upper_right_leg_z_link"/>
  </joint>
  <joint name="upper_right_leg_y_joint" type="continuous">
    <axis xyz="0 1 0"/>
    <limit effort="15" lower="-0.7" upper="1.57" velocity="5"/>
    <origin rpy="0 0 0" xyz="0 0 0"/>
    <parent link="upper_right_leg_z_link"/>
    <child link="upper_right_leg_y_link"/>
  </joint>
  <joint name="upper_right_leg_x_joint" type="continuous">
    <axis xyz="1 0 0"/>
    <limit effort="15" lower="-1.2" upper="1.57" velocity="5"/>
    <origin rpy="0 0 0" xyz="0 0 0"/>
    <parent link="upper_right_leg_y_link"/>
    <child link="upper_right_leg_x_link"/>
  </joint>

  <link name="upper_right_leg_z_link"/>
  <link name="upper_right_leg_y_link"/>
  <link name="upper_right_leg_x_link">
    <visual>
      <origin rpy="0 0 0" xyz="0 0 0"/>
      <geometry>
        <mesh filename="package://human_description/meshes/rocket_box/r_upperleg.obj"/>
      </geometry>
      <material name="Blue"/>
    </visual>
    <collision>
      <origin rpy="0 0 0" xyz="0 0 0"/>
      <geometry>
        <mesh filename="package://human_description/meshes/rocket_box/r_upperleg.obj"/>
      </geometry>
    </collision>
    <inertial>
      <mass value="4.5"/>
      <inertia ixx="0.26" ixy="0.0" ixz="0.0" iyy="0.26" iyz="0.0" izz="0.02"/>
      <origin xyz="0.0 0.0 -0.20"/>
    </inertial>
  </link>

  <joint name="lower_right_leg_joint" type="continuous">
    <axis xyz="1 0 0"/>
    <limit effort="15" lower="-2.4" upper="0" velocity="5"/>
    <origin rpy="0 0 0" xyz="0.03 -0.02 -0.48"/>
    <parent link="upper_right_leg_x_link"/>
    <child link="lower_right_leg_link"/>
  </joint>

  <link name="lower_right_leg_link">
    <visual>
      <origin rpy="0 0 0" xyz="0 0 0"/>
      <geometry>
        <mesh filename="package://human_description/meshes/rocket_box/r_lowerleg.obj"/>
      </geometry>
      <material name="Blue"/>
    </visual>
    <collision>
      <origin rpy="0 0 0" xyz="0 0 0"/>
      <geometry>
        <mesh filename="package://human_description/meshes/rocket_box/r_lowerleg.obj"/>
      </geometry>
    </collision>
    <inertial>
      <mass value="3.0"/>
      <inertia ixx="0.19" ixy="0.0" ixz="0.0" iyy="0.19" iyz="0.0" izz="0.01"/>
      <origin xyz="0.0 0.0 -0.20"/>
    </inertial>
  </link>

  <joint name="right_foot_z_joint" type="continuous">
    <axis xyz="0 0 1"/>
    <limit effort="15" lower="0" upper="0.001" velocity="5"/>
    <origin rpy="0 0 0" xyz="0.01 0.04 -0.47"/>
    <parent link="lower_right_leg_link"/>
    <child link="right_foot_z_link"/>
  </joint>
  <joint name="right_foot_y_joint" type="continuous">
    <axis xyz="0 1 0"/>
    <limit effort="15" lower="-0.5" upper="0.5" velocity="5"/>
    <origin rpy="0 0 0" xyz="0 0 0"/>
    <parent link="right_foot_z_link"/>
    <child link="right_foot_y_link"/>
  </joint>
  <joint name="right_foot_x_joint" type="continuous">
    <axis xyz="1 0 0"/>
    <limit effort="15" lower="-0.8" upper="0.6" velocity="5"/>
    <origin rpy="0 0 0" xyz="0 0 0"/>
    <parent link="right_foot_y_link"/>
    <child link="right_foot_x_link"/>
  </joint>

  <link name="right_foot_z_link"/>
  <link name="right_foot_y_link"/>
  <link name="right_foot_x_link">
    <visual>
      <origin rpy="0 0 0" xyz="0 0 0"/>
      <geometry>
        <mesh filename="package://human_description/meshes/rocket_box/r_foot.obj"/>
      </geometry>
      <material name="Blue"/>
    </visual>
    <collision>
      <origin rpy="0 0 0" xyz="0 0 0"/>
      <geometry>
        <mesh filename="package://human_description/meshes/rocket_box/r_foot.obj"/>
      </geometry>
    </collision>
    <inertial>
      <mass value="1.0"/>
      <inertia ixx="0.01" ixy="0.0" ixz="0.0" iyy="0.01" iyz="0.0" izz="0.01"/>
      <origin xyz="0.0 0.04 -0.08"/>
    </inertial>
  </link>
  	  
  <joint name="right_foot_endeffector_joint" type="revolute">
    <axis xyz="0 0 1"/>
    <limit effort="15" lower="0.0" upper="0.0" velocity="5"/>
    <origin rpy="0 0 0" xyz="0 0 -0.12"/>
    <parent link="right_foot_x_link"/>
    <child link="right_foot_endeffector_link"/>
  </joint>

  <link name="right_foot_endeffector_link"/>

  <joint name="upper_left_specula_joint" type="continuous">
    <axis xyz="0 0 1"/>
    <limit effort="15" lower="-0" upper="0" velocity="5"/>
    <origin rpy="0 0 0" xyz="-0.12 0.04 0.35"/>
    <parent link="torso_x_link"/>
    <child link="upper_left_arm_specula_link"/>
  </joint>
  
  <link name="upper_left_arm_specula_link"/>
  
  <joint name="upper_left_arm_z_joint" type="continuous">
    <axis xyz="0 0 1"/>
    <limit effort="15" lower="-0.5" upper="0.5" velocity="5"/>
    <origin rpy="0 0 0" xyz="-0.17 0 0"/>
    <parent link="upper_left_arm_specula_link"/>
    <child link="upper_left_arm_z_link"/>
  </joint>
  <joint name="upper_left_arm_y_joint" type="continuous">
    <axis xyz="0 1 0"/>
    <limit effort="15" lower="-3.14" upper="2.0" velocity="5"/>
    <origin rpy="0 0 0" xyz="0 0 0"/>
    <parent link="upper_left_arm_z_link"/>
    <child link="upper_left_arm_y_link"/>
  </joint>
  <joint name="upper_left_arm_x_joint" type="continuous">
    <axis xyz="1 0 0"/>
    <limit effort="15" lower="-1.0" upper="3.14" velocity="5"/>
    <origin rpy="0 0 0" xyz="0 0 0"/>
    <parent link="upper_left_arm_y_link"/>
    <child link="upper_left_arm_x_link"/>
  </joint>

  <link name="upper_left_arm_z_link"/>
  <link name="upper_left_arm_y_link"/>
  <link name="upper_left_arm_x_link">
    <visual>
      <origin rpy="0 0 0" xyz="0 0 0"/>
      <geometry>
        <mesh filename="package://human_description/meshes/rocket_box/l_upperarm.obj"/>
      </geometry>
      <material name="Blue"/>
    </visual>
    <collision>
      <origin rpy="0 0 0" xyz="0 0 0"/>
      <geometry>
        <mesh filename="package://human_description/meshes/rocket_box/l_upperarm.obj"/>
      </geometry>
    </collision>
    <inertial>
      <mass value="2.0"/>
      <inertia ixx="0.06" ixy="0.0" ixz="0.0" iyy="0.06" iyz="0.0" izz="0.01"/>
      <origin xyz="0.0 0.0 -0.17"/>
    </inertial>
  </link>

  <joint name="lower_left_arm_joint" type="continuous">
    <axis xyz="1 0 0"/>
    <limit effort="15" lower="0" upper="3.14" velocity="5"/>
    <origin rpy="0 0 0" xyz="0.0 0.0 -0.34"/>
    <parent link="upper_left_arm_x_link"/>
    <child link="lower_left_arm_link"/>
  </joint>

  <link name="lower_left_arm_link">
    <visual>
      <origin rpy="0 0 0" xyz="0 0 0"/>
      <geometry>
        <mesh filename="package://human_description/meshes/rocket_box/l_forearm.obj"/>
      </geometry>
      <material name="Blue"/>
    </visual>
    <collision>
      <origin rpy="0 0 0" xyz="0 0 0"/>
      <geometry>
        <mesh filename="package://human_description/meshes/rocket_box/l_forearm.obj"/>
      </geometry>
    </collision>
    <inertial>
      <mass value="1.5"/>
      <inertia ixx="0.05" ixy="0.0" ixz="0.0" iyy="0.05" iyz="0.0" izz="0.01"/>
      <origin xyz="0.0 0.0 -0.14"/>
    </inertial>
  </link>

  <joint name="left_hand_z_joint" type="continuous">
    <axis xyz="0 0 1"/>
    <limit effort="15" lower="-1.0" upper="1.0" velocity="5"/>
    <origin rpy="0 0 0" xyz="0.0 0.0 -0.32"/>
    <parent link="lower_left_arm_link"/>
    <child link="left_hand_z_link"/>
  </joint>
  <joint name="left_hand_y_joint" type="continuous">
    <axis xyz="0 1 0"/>
    <limit effort="15" lower="-1.3" upper="1.5" velocity="5"/>
    <origin rpy="0 0 0" xyz="0 0 0"/>
    <parent link="left_hand_z_link"/>
    <child link="left_hand_y_link"/>
  </joint>
  <joint name="left_hand_x_joint" type="continuous">
    <axis xyz="1 0 0"/>
    <limit effort="15" lower="-0.5" upper="1.4" velocity="5"/>
    <origin rpy="0 0 0" xyz="0 0 0"/>
    <parent link="left_hand_y_link"/>
    <child link="left_hand_x_link"/>
  </joint>

  <link name="left_hand_z_link"/>
  <link name="left_hand_y_link"/>
  <link name="left_hand_x_link">
    <visual>
      <origin rpy="0 0 0" xyz="0 0 0"/>
      <geometry>
        <mesh filename="package://human_description/meshes/rocket_box/l_hand.obj"/>
      </geometry>
      <material name="Blue"/>
    </visual>
    <collision>
      <origin rpy="0 0 0" xyz="0 0 0"/>
      <geometry>
        <mesh filename="package://human_description/meshes/rocket_box/l_hand.obj"/>
      </geometry>
    </collision>
    <inertial>
      <mass value="0.25"/>
      <inertia ixx="0.002" ixy="0.0" ixz="0.0" iyy="0.002" iyz="0.0" izz="0.001"/>
      <origin xyz="0.0 0.0 -0.06"/>
    </inertial>
  </link>

  <joint name="left_hand_endeffector_joint" type="revolute">
    <axis xyz="0 0 1"/>
    <limit effort="15" lower="-0.001" upper="0.001" velocity="5"/>
    <origin rpy="-1.570796 0 1.570796" xyz="0.015 -0.01 -0.08"/>
        <parent link="left_hand_x_link"/>
    <child link="left_hand_endeffector_link"/>
  </joint>

  <link name="left_hand_endeffector_link"/>
  
  <joint name="upper_right_specula_joint" type="continuous">
    <axis xyz="0 0 1"/>
    <limit effort="15" lower="-0" upper="0" velocity="5"/>
    <origin rpy="0 0 0" xyz="0.12 0.04 0.35"/>
    <parent link="torso_x_link"/>
    <child link="upper_right_arm_specula_link"/>
  </joint>
    
  <link name="upper_right_arm_specula_link"/>
  
  <joint name="upper_right_arm_z_joint" type="continuous">
    <axis xyz="0 0 1"/>
    <limit effort="15" lower="-0.5" upper="0.5" velocity="5"/>
    <origin rpy="0 0 0" xyz="0.17 0.0 0.0"/>
    <parent link="upper_right_arm_specula_link"/>
    <child link="upper_right_arm_z_link"/>
  </joint>
  <joint name="upper_right_arm_y_joint" type="continuous">
    <axis xyz="0 1 0"/>
    <limit effort="15" lower="-2.0" upper="3.14" velocity="5"/>
    <origin rpy="0 0 0" xyz="0 0 0"/>
    <parent link="upper_right_arm_z_link"/>
    <child link="upper_right_arm_y_link"/>
  </joint>
  <joint name="upper_right_arm_x_joint" type="continuous">
    <axis xyz="1 0 0"/>
    <limit effort="15" lower="-1.0" upper="3.14" velocity="5"/>
    <origin rpy="0 0 0" xyz="0 0 0"/>
    <parent link="upper_right_arm_y_link"/>
    <child link="upper_right_arm_x_link"/>
  </joint>

  <link name="upper_right_arm_z_link"/>
  <link name="upper_right_arm_y_link"/>
  <link name="upper_right_arm_x_link">
    <visual>
      <origin rpy="0 0 0" xyz="0 0 0"/>
      <geometry>
        <mesh filename="package://human_description/meshes/rocket_box/r_upperarm.obj"/>
      </geometry>
      <material name="Blue"/>
    </visual>
    <collision>
      <origin rpy="0 0 0" xyz="0 0 0"/>
      <geometry>
        <mesh filename="package://human_description/meshes/rocket_box/r_upperarm.obj"/>
      </geometry>
    </collision>
    <inertial>
      <mass value="2.0"/>
      <inertia ixx="0.06" ixy="0.0" ixz="0.0" iyy="0.06" iyz="0.0" izz="0.01"/>
      <origin xyz="0.0 0.0 -0.17"/>
    </inertial>
  </link>

  <joint name="lower_right_arm_joint" type="continuous">
    <axis xyz="1 0 0"/>
    <limit effort="15" lower="0" upper="3.14" velocity="5"/>
    <origin rpy="0 0 0" xyz="0.0 0.0 -0.34"/>
    <parent link="upper_right_arm_x_link"/>
    <child link="lower_right_arm_link"/>
  </joint>

  <link name="lower_right_arm_link">
    <visual>
      <origin rpy="0 0 0" xyz="0 0 0"/>
      <geometry>
        <mesh filename="package://human_description/meshes/rocket_box/r_forearm.obj"/>
      </geometry>
      <material name="Blue"/>
    </visual>
    <collision>
      <origin rpy="0 0 0" xyz="0 0 0"/>
      <geometry>
        <mesh filename="package://human_description/meshes/rocket_box/r_forearm.obj"/>
      </geometry>
    </collision>
    <inertial>
      <mass value="1.5"/>
      <inertia ixx="0.05" ixy="0.0" ixz="0.0" iyy="0.05" iyz="0.0" izz="0.01"/>
      <origin xyz="0.0 0.0 -0.14"/>
    </inertial>
  </link>

  <joint name="right_hand_z_joint" type="continuous">
    <axis xyz="0 0 1"/>
    <limit effort="15" lower="-1.0" upper="1.0" velocity="5"/>
    <origin rpy="0 0 0" xyz="0.0 0.0 -0.32"/>
    <parent link="lower_right_arm_link"/>
    <child link="right_hand_z_link"/>
  </joint>
  <joint name="right_hand_y_joint" type="continuous">
    <axis xyz="0 1 0"/>
    <limit effort="15" lower="-1.5" upper="1.3" velocity="5"/>
    <origin rpy="0 0 0" xyz="0 0 0"/>
    <parent link="right_hand_z_link"/>
    <child link="right_hand_y_link"/>
  </joint>
  <joint name="right_hand_x_joint" type="continuous">
    <axis xyz="1 0 0"/>
    <limit effort="15" lower="-0.5" upper="1.4" velocity="5"/>
    <origin rpy="0 0 0" xyz="0 0 0"/>
    <parent link="right_hand_y_link"/>
    <child link="right_hand_x_link"/>
  </joint>

  <link name="right_hand_z_link"/>
  <link name="right_hand_y_link"/>
  <link name="right_hand_x_link">
    <visual>
      <origin rpy="0 0 0" xyz="0 0 0"/>
      <geometry>
        <mesh filename="package://human_description/meshes/rocket_box/r_hand.obj"/>
      </geometry>
      <material name="Blue"/>
    </visual>
    <collision>
      <origin rpy="0 0 0" xyz="0 0 0"/>
      <geometry>
        <mesh filename="package://human_description/meshes/rocket_box/r_hand.obj"/>
      </geometry>
    </collision>
    <inertial>
      <mass value="0.25"/>
      <inertia ixx="0.002" ixy="0.0" ixz="0.0" iyy="0.002" iyz="0.0" izz="0.001"/>
      <origin xyz="0.0 0.0 -0.06"/>
    </inertial>
  </link>

  <joint name="right_hand_endeffector_joint" type="revolute">
    <axis xyz="0 0 1"/>
    <limit effort="15" lower="-0.001" upper="0.001" velocity="5"/>
    <origin rpy="-1.570796 0 -1.570796" xyz="-0.015 -0.01 -0.08"/>
    <parent link="right_hand_x_link"/>
    <child link="right_hand_endeffector_link"/>
  </joint>

  <link name="right_hand_endeffector_link"/>
  
  <link name="left_foot_cp_1_link"/>
  <link name="left_foot_cp_2_link"/>
  <link name="left_foot_cp_3_link"/>
  <link name="left_foot_cp_4_link"/>

  <joint name="left_foot_cp_1_joint" type="revolute">
    <axis xyz="0 0 1"/>
    <limit effort="15" lower="0" upper="0" velocity="5"/>
    <origin rpy="0 0 0" xyz="0.08 0.27 0.0"/>
    <parent link="left_foot_endeffector_link"/>
    <child link="left_foot_cp_1_link"/>
  </joint>
  <joint name="left_foot_cp_2_joint" type="revolute">
    <axis xyz="0 0 1"/>
    <limit effort="15" lower="0" upper="0" velocity="5"/>
    <origin rpy="0 0 0" xyz="-0.08 0.27 0.0"/>
    <parent link="left_foot_endeffector_link"/>
    <child link="left_foot_cp_2_link"/>
  </joint>
  <joint name="left_foot_cp_3_joint" type="revolute">
    <axis xyz="0 0 1"/>
    <limit effort="15" lower="0" upper="0" velocity="5"/>
    <origin rpy="0 0 0" xyz="-0.08 -0.08 0.0"/>
    <parent link="left_foot_endeffector_link"/>
    <child link="left_foot_cp_3_link"/>
  </joint>
  <joint name="left_foot_cp_4_joint" type="revolute">
    <axis xyz="0 0 1"/>
    <limit effort="15" lower="0" upper="0" velocity="5"/>
    <origin rpy="0 0 0" xyz="0.08 -0.08 0.0"/>
    <parent link="left_foot_endeffector_link"/>
    <child link="left_foot_cp_4_link"/>
  </joint>

  <link name="right_foot_cp_1_link"/>
  <link name="right_foot_cp_2_link"/>
  <link name="right_foot_cp_3_link"/>
  <link name="right_foot_cp_4_link"/>

  <joint name="right_foot_cp_1_joint" type="revolute">
    <axis xyz="0 0 1"/>
    <limit effort="15" lower="0" upper="0" velocity="5"/>
    <origin rpy="0 0 0" xyz="0.08 0.27 0.0"/>
    <parent link="right_foot_endeffector_link"/>
    <child link="right_foot_cp_1_link"/>
  </joint>
  <joint name="right_foot_cp_2_joint" type="revolute">
    <axis xyz="0 0 1"/>
    <limit effort="15" lower="0" upper="0" velocity="5"/>
    <origin rpy="0 0 0" xyz="-0.08 0.27 0.0"/>
    <parent link="right_foot_endeffector_link"/>
    <child link="right_foot_cp_2_link"/>
  </joint>
  <joint name="right_foot_cp_3_joint" type="revolute">
    <axis xyz="0 0 1"/>
    <limit effort="15" lower="0" upper="0" velocity="5"/>
    <origin rpy="0 0 0" xyz="-0.08 -0.08 0.0"/>
    <parent link="right_foot_endeffector_link"/>
    <child link="right_foot_cp_3_link"/>
  </joint>
  <joint name="right_foot_cp_4_joint" type="revolute">
    <axis xyz="0 0 1"/>
    <limit effort="15" lower="0" upper="0" velocity="5"/>
    <origin rpy="0 0 0" xyz="0.08 -0.08 0.0"/>
    <parent link="right_foot_endeffector_link"/>
    <child link="right_foot_cp_4_link"/>
  </joint>

  <link name="left_hand_cp_1_link"/>
  <link name="left_hand_cp_2_link"/>
  <link name="left_hand_cp_3_link"/>
  <link name="left_hand_cp_4_link"/>

  <joint name="left_hand_cp_1_joint" type="revolute">
    <axis xyz="0 0 1"/>
    <limit effort="15" lower="0" upper="0" velocity="5"/>
    <origin rpy="0 0 0" xyz="0.06 0.14 0"/>
    <parent link="left_hand_endeffector_link"/>
    <child link="left_hand_cp_1_link"/>
  </joint>
  <joint name="left_hand_cp_2_joint" type="revolute">
    <axis xyz="0 0 1"/>
    <limit effort="15" lower="0" upper="0" velocity="5"/>
    <origin rpy="0 0 0" xyz="-0.06 0.14 0"/>
    <parent link="left_hand_endeffector_link"/>
    <child link="left_hand_cp_2_link"/>
  </joint>
  <joint name="left_hand_cp_3_joint" type="revolute">
    <axis xyz="0 0 1"/>
    <limit effort="15" lower="0" upper="0" velocity="5"/>
    <origin rpy="0 0 0" xyz="-0.06 -0.05 0"/>
    <parent link="left_hand_endeffector_link"/>
    <child link="left_hand_cp_3_link"/>
  </joint>
  <joint name="left_hand_cp_4_joint" type="revolute">
    <axis xyz="0 0 1"/>
    <limit effort="15" lower="0" upper="0" velocity="5"/>
    <origin rpy="0 0 0" xyz="0.06 -0.05 0"/>
    <parent link="left_hand_endeffector_link"/>
    <child link="left_hand_cp_4_link"/>
  </joint>

  <link name="right_hand_cp_1_link"/>
  <link name="right_hand_cp_2_link"/>
  <link name="right_hand_cp_3_link"/>
  <link name="right_hand_cp_4_link"/>

  <joint name="right_hand_cp_1_joint" type="revolute">
    <axis xyz="0 0 1"/>
    <limit effort="15" lower="0" upper="0" velocity="5"/>
    <origin rpy="0 0 0" xyz="0.06 0.14 0"/>
    <parent link="right_hand_endeffector_link"/>
    <child link="right_hand_cp_1_link"/>
  </joint>
  <joint name="right_hand_cp_2_joint" type="revolute">
    <axis xyz="0 0 1"/>
    <limit effort="15" lower="0" upper="0" velocity="5"/>
    <origin rpy="0 0 0" xyz="-0.06 0.14 0"/>
    <parent link="right_hand_endeffector_link"/>
    <child link="right_hand_cp_2_link"/>
  </joint>
  <joint name="right_hand_cp_3_joint" type="revolute">
    <axis xyz="0 0 1"/>
    <limit effort="15" lower="0" upper="0" velocity="5"/>
    <origin rpy="0 0 0" xyz="-0.06 -0.05 0"/>
    <parent link="right_hand_endeffector_link"/>
    <child link="right_hand_cp_3_link"/>
  </joint>
  <joint name="right_hand_cp_4_joint" type="revolute">
    <axis xyz="0 0 1"/>
    <limit effort="15" lower="0" upper="0" velocity="5"/>
    <origin rpy="0 0 0" xyz="0.06 -0.05 0"/>
    <parent link="right_hand_endeffector_link"/>
    <child link="right_hand_cp_4_link"/>
  </joint>

</robot>

