<?xml version="1.0"?>
<robot xmlns:sensor="http://playerstage.sourceforge.net/gazebo/xmlschema/#sensor"
       xmlns:controller="http://playerstage.sourceforge.net/gazebo/xmlschema/#controller"
       xmlns:interface="http://playerstage.sourceforge.net/gazebo/xmlschema/#interface"
       xmlns:xacro="http://playerstage.sourceforge.net/gazebo/xmlschema/#interface"
       name="zoey" >

  <material name="Blue">
    <color rgba="0.0 0.0 0.8 1.0"/>
  </material>
  <material name="Green">
    <color rgba="0.0 0.8 0.0 1.0"/>
  </material>
  <material name="Grey">
    <color rgba="0.7 0.7 0.7 1.0"/>
  </material>
  <material name="Grey2">
    <color rgba="0.9 0.9 0.9 1.0"/>
  </material>
  <material name="Red">
    <color rgba="0.8 0.0 0.0 1.0"/>
  </material>
  <material name="White">
    <color rgba="1.0 1.0 1.0 1.0"/>
  </material>
  <material name="Black">
    <color rgba="0.1 0.1 0.1 1.0"/>
  </material>
  <material name="LightGrey">
    <color rgba="0.6 0.6 0.6 1.0"/>
  </material>

  <link name="root_link"/>
  <link name="base_prismatic_dummy1"/>
  <link name="base_prismatic_dummy2"/>
  <joint name="base_prismatic_joint_x" type="prismatic">
    <axis xyz="1 0 0"/>
    <limit effort="10000" lower="-5.0" upper="5.0" velocity="0.6"/>
    <safety_controller k_position="100" k_velocity="2000000" soft_lower_limit="-4.9" soft_upper_limit="4.9"/>
    <calibration falling="0.00536"/>
    <dynamics damping="20000.0"/>
    <origin rpy="0 0 0" xyz="0 0 1.12"/>
    <parent link="root_link"/>
    <child link="base_prismatic_dummy1"/>
  </joint>
  <joint name="base_prismatic_joint_y" type="prismatic">
    <axis xyz="0 1 0"/>
    <limit effort="10000" lower="-5.0" upper="5.0" velocity="0.6"/>
    <safety_controller k_position="100" k_velocity="2000000" soft_lower_limit="-4.9" soft_upper_limit="4.9"/>
    <calibration falling="0.00536"/>
    <dynamics damping="20000.0"/>
    <origin rpy="0 0 0" xyz="0 0 0"/>
    <parent link="base_prismatic_dummy1"/>
    <child link="base_prismatic_dummy2"/>
  </joint>
  <joint name="base_rotate_joint" type="continuous">
    <axis xyz="0 0 1"/>
    <limit effort="30" velocity="3.6"/>
    <safety_controller k_velocity="1"/>
    <calibration rising="0.0"/>
    <dynamics damping="0.1"/>
    <origin rpy="0 0 0" xyz="0 0 0"/>
    <parent link="base_prismatic_dummy2"/>
    <child link="pelvis_link"/>
  </joint>

  <link name="pelvis_link">
    <visual>
      <origin rpy="0 0 0" xyz="0 0 0"/>
      <geometry>
        <mesh filename="package://human_description/meshes/zoey/pelvis.dae" scale="0.00001 0.00001 0.00001"/>
      </geometry>
      <material name="Grey2"/>
    </visual>
    <collision>
      <origin rpy="0 0 0" xyz="0 0 0"/>
      <geometry>
        <mesh filename="package://human_description/meshes/zoey/pelvis.dae" scale="0.00001 0.00001 0.00001"/>
      </geometry>
    </collision>
  </link>

  <joint name="torso_z_joint" type="revolute">
    <axis xyz="0 0 1"/>
    <limit effort="15" lower="-0.7" upper="0.7" velocity="5"/>
    <origin rpy="0 0 0" xyz="0 0.005864 0.074074"/>
    <parent link="pelvis_link"/>
    <child link="torso_z_link"/>
  </joint>
  <joint name="torso_y_joint" type="revolute">
    <axis xyz="0 1 0"/>
    <limit effort="15" lower="-0.3" upper="0.3" velocity="5"/>
    <origin rpy="0 0 0" xyz="0 0 0"/>
    <parent link="torso_z_link"/>
    <child link="torso_y_link"/>
  </joint>
  <joint name="torso_x_joint" type="revolute">
    <axis xyz="1 0 0"/>
    <limit effort="15" lower="-1.0" upper="0" velocity="5"/>
    <origin rpy="0 0 0" xyz="0 0 0"/>
    <parent link="torso_y_link"/>
    <child link="torso_x_link"/>
  </joint>  
  <joint name="torso_up_joint" type="revolute">
    <axis xyz="1 0 0"/>    
    <limit effort="15" lower="-0.001" upper="0.001" velocity="5"/>
    <origin rpy="0 0 0" xyz="0 -0.011188 0.131306"/>
    <parent link="torso_x_link"/>
    <child link="torso_up_link"/>
  </joint>

  <link name="torso_z_link"/>
  <link name="torso_y_link"/>
  <link name="torso_x_link">
    <visual>
      <origin rpy="0 0 0" xyz="0 0 0"/>
      <geometry>
        <mesh filename="package://human_description/meshes/zoey/torso.dae" scale="0.00001 0.00001 0.00001"/>
      </geometry>
      <material name="Blue"/>
    </visual>
    <collision>
      <origin rpy="0 0 0" xyz="0 0 0"/>
      <geometry>
        <mesh filename="package://human_description/meshes/zoey/torso.dae" scale="0.00001 0.00001 0.00001"/>
      </geometry>
    </collision>
  </link>
  <link name="torso_up_link"/>

  <joint name="head_z_joint" type="revolute">
    <axis xyz="0 0 1"/>
    <limit effort="15" lower="-1.2" upper="1.2" velocity="5"/>
    <origin rpy="0 0 0" xyz="0 -0.031 0.216978"/>
    <parent link="torso_up_link"/>
    <child link="head_z_link"/>
  </joint>
  <joint name="head_y_joint" type="revolute">
    <axis xyz="0 1 0"/>
    <limit effort="15" lower="-0.8" upper="0.8" velocity="5"/>
    <origin rpy="0 0 0" xyz="0 0 0"/>
    <parent link="head_z_link"/>
    <child link="head_y_link"/>
  </joint>
  <joint name="head_x_joint" type="revolute">
    <axis xyz="1 0 0"/>
    <limit effort="15" lower="-1.57" upper="0.3" velocity="5"/>
    <origin rpy="0 0 0" xyz="0 0 0"/>
    <parent link="head_y_link"/>
    <child link="head_x_link"/>
  </joint>

  <link name="head_z_link"/>
  <link name="head_y_link"/>
  <link name="head_x_link">
    <visual>
      <origin rpy="0 0 0" xyz="0 0 0"/>
      <geometry>
        <mesh filename="package://human_description/meshes/zoey/head.dae" scale="100 100 100"/>
      </geometry>
      <material name="Blue"/>
    </visual>
    <collision>
      <origin rpy="0 0 0" xyz="0 0 0"/>
      <geometry>
        <mesh filename="package://human_description/meshes/zoey/head.dae" scale="100 100 100"/>
      </geometry>
    </collision>
  </link>


  <joint name="upper_left_leg_z_joint" type="revolute">
    <axis xyz="0 0 1"/>
    <limit effort="15" lower="-1.57" upper="1" velocity="5"/>
    <origin rpy="0 0 0" xyz="-0.069112 0 0"/>
    <parent link="pelvis_link"/>
    <child link="upper_left_leg_z_link"/>
  </joint>
  <joint name="upper_left_leg_y_joint" type="revolute">
    <axis xyz="0 1 0"/>
    <limit effort="15" lower="-1.57" upper="0.7" velocity="5"/>
    <origin rpy="0 0 0" xyz="0 0 0"/>
    <parent link="upper_left_leg_z_link"/>
    <child link="upper_left_leg_y_link"/>
  </joint>
  <joint name="upper_left_leg_x_joint" type="revolute">
    <axis xyz="1 0 0"/>
    <limit effort="15" lower="-1.2" upper="1.57" velocity="5"/>
    <origin rpy="0 0 0" xyz="0 0 0"/>
    <parent link="upper_left_leg_y_link"/>
    <child link="upper_left_leg_x_link"/>
  </joint>

  <link name="upper_left_leg_z_link"/>
  <link name="upper_left_leg_y_link"/>
  <link name="upper_left_leg_x_link">
    <visual>
      <origin rpy="0 0 0" xyz="0 0 0"/>
      <geometry>
        <mesh filename="package://human_description/meshes/zoey/l_lupperleg.dae" scale="100 100 100"/>
      </geometry>
      <material name="Blue"/>
    </visual>
    <collision>
      <origin rpy="0 0 0" xyz="0 0 0"/>
      <geometry>
        <mesh filename="package://human_description/meshes/zoey/l_lupperleg.dae" scale="100 100 100"/>
      </geometry>
    </collision>
  </link>

  <joint name="lower_left_leg_joint" type="revolute">
    <axis xyz="1 0 0"/>
    <limit effort="15" lower="-2.4" upper="0" velocity="5"/>
    <origin rpy="0 0 0" xyz="0.011634 -0.010252 -0.331082"/>
    <parent link="upper_left_leg_x_link"/>
    <child link="lower_left_leg_link"/>
  </joint>

  <link name="lower_left_leg_link">
    <visual>
      <origin rpy="0 0 0" xyz="0 0 0"/>
      <geometry>
        <mesh filename="package://human_description/meshes/zoey/l_lowerleg.dae" scale="100 100 100"/>
      </geometry>
      <material name="Blue"/>
    </visual>
    <collision>
      <origin rpy="0 0 0" xyz="0 0 0"/>
      <geometry>
        <mesh filename="package://human_description/meshes/zoey/l_lowerleg.dae" scale="100 100 100"/>
      </geometry>
    </collision>
  </link>

  <joint name="left_foot_z_joint" type="revolute">
    <axis xyz="0 0 1"/>
    <limit effort="15" lower="-0.01" upper="0" velocity="5"/>
    <origin rpy="0 0 0" xyz="0.011414 -0.01328 -0.324846"/>
    <parent link="lower_left_leg_link"/>
    <child link="left_foot_z_link"/>
  </joint>
  <joint name="left_foot_y_joint" type="revolute">
    <axis xyz="0 1 0"/>
    <limit effort="15" lower="-0.5" upper="0.5" velocity="5"/>
    <origin rpy="0 0 0" xyz="0 0 0"/>
    <parent link="left_foot_z_link"/>
    <child link="left_foot_y_link"/>
  </joint>
  <joint name="left_foot_x_joint" type="revolute">
    <axis xyz="1 0 0"/>
    <limit effort="15" lower="-0.8" upper="0.6" velocity="5"/>
    <origin rpy="0 0 0" xyz="0 0 0"/>
    <parent link="left_foot_y_link"/>
    <child link="left_foot_x_link"/>
  </joint>

  <link name="left_foot_z_link"/>
  <link name="left_foot_y_link"/>
  <link name="left_foot_x_link">
    <visual>
      <origin rpy="0 0 0" xyz="0 0 0"/>
      <geometry>
        <mesh filename="package://human_description/meshes/zoey/l_foot.dae" scale="100 100 100"/>
      </geometry>
      <material name="Blue"/>
    </visual>
    <collision>
      <origin rpy="0 0 0" xyz="0 0 0"/>
      <geometry>
        <mesh filename="package://human_description/meshes/zoey/l_foot.dae" scale="100 100 100"/>
      </geometry>
    </collision>
  </link>

  <joint name="upper_right_leg_z_joint" type="revolute">
    <axis xyz="0 0 1"/>
    <limit effort="15" lower="-1" upper="1.57" velocity="5"/>
    <origin rpy="0 0 0" xyz="0.069112 0 0"/>
    <parent link="pelvis_link"/>
    <child link="upper_right_leg_z_link"/>
  </joint>
  <joint name="upper_right_leg_y_joint" type="revolute">
    <axis xyz="0 1 0"/>
    <limit effort="15" lower="-0.7" upper="1.57" velocity="5"/>
    <origin rpy="0 0 0" xyz="0 0 0"/>
    <parent link="upper_right_leg_z_link"/>
    <child link="upper_right_leg_y_link"/>
  </joint>
  <joint name="upper_right_leg_x_joint" type="revolute">
    <axis xyz="1 0 0"/>
    <limit effort="15" lower="-1.2" upper="1.57" velocity="5"/>
    <origin rpy="0 0 0" xyz="0 0 0"/>
    <parent link="upper_right_leg_y_link"/>
    <child link="upper_right_leg_x_link"/>
  </joint>

  <link name="upper_right_leg_z_link"/>
  <link name="upper_right_leg_y_link"/>
  <link name="upper_right_leg_x_link">
    <visual>
      <origin rpy="0 0 0" xyz="0 0 0"/>
      <geometry>
        <mesh filename="package://human_description/meshes/zoey/r_upperleg.dae"/>
      </geometry>
      <material name="Blue"/>
    </visual>
    <collision>
      <origin rpy="0 0 0" xyz="0 0 0"/>
      <geometry>
        <mesh filename="package://human_description/meshes/zoey/r_upperleg.dae"/>
      </geometry>
    </collision>
  </link>

  <joint name="lower_right_leg_joint" type="revolute">
    <axis xyz="1 0 0"/>
    <limit effort="15" lower="-2.4" upper="0" velocity="5"/>
    <origin rpy="0 0 0" xyz="-0.011634 -0.010452 -0.331082"/>
    <parent link="upper_right_leg_x_link"/>
    <child link="lower_right_leg_link"/>
  </joint>

  <link name="lower_right_leg_link">
    <visual>
      <origin rpy="0 0 0" xyz="0 0 0"/>
      <geometry>
        <mesh filename="package://human_description/meshes/zoey/r_lowerleg.dae"/>
      </geometry>
      <material name="Blue"/>
    </visual>
    <collision>
      <origin rpy="0 0 0" xyz="0 0 0"/>
      <geometry>
        <mesh filename="package://human_description/meshes/zoey/r_lowerleg.dae"/>
      </geometry>
    </collision>
  </link>

  <joint name="right_foot_z_joint" type="revolute">
    <axis xyz="0 0 1"/>
    <limit effort="15" lower="0" upper="0.001" velocity="5"/>
    <origin rpy="0 0 0" xyz="-0.011414 -0.01328 -0.324846"/>
    <parent link="lower_right_leg_link"/>
    <child link="right_foot_z_link"/>
  </joint>
  <joint name="right_foot_y_joint" type="revolute">
    <axis xyz="0 1 0"/>
    <limit effort="15" lower="-0.5" upper="0.5" velocity="5"/>
    <origin rpy="0 0 0" xyz="0 0 0"/>
    <parent link="right_foot_z_link"/>
    <child link="right_foot_y_link"/>
  </joint>
  <joint name="right_foot_x_joint" type="revolute">
    <axis xyz="1 0 0"/>
    <limit effort="15" lower="-0.8" upper="0.6" velocity="5"/>
    <origin rpy="0 0 0" xyz="0 0 0"/>
    <parent link="right_foot_y_link"/>
    <child link="right_foot_x_link"/>
  </joint>

  <link name="right_foot_z_link"/>
  <link name="right_foot_y_link"/>
  <link name="right_foot_x_link">
    <visual>
      <origin rpy="0 0 0" xyz="0 0 0"/>
      <geometry>
        <mesh filename="package://human_description/meshes/zoey/r_foot.dae"/>
      </geometry>
      <material name="Blue"/>
    </visual>
    <collision>
      <origin rpy="0 0 0" xyz="0 0 0"/>
      <geometry>
        <mesh filename="package://human_description/meshes/zoey/r_foot.dae"/>
      </geometry>
    </collision>
  </link>

  <joint name="upper_left_specula_joint" type="revolute">
    <axis xyz="0 0 1"/>
    <limit effort="15" lower="-0.5" upper="0.5" velocity="5"/>
    <origin rpy="0 0 0" xyz="-0.03 -0.00434 0.19102"/>
    <parent link="torso_up_link"/>
    <child link="upper_left_arm_specula_link"/>
  </joint>
  
  <link name="upper_left_arm_specula_link"/>
  
  <joint name="upper_left_arm_z_joint" type="revolute">
    <axis xyz="0 0 1"/>
    <limit effort="15" lower="-0.5" upper="0.5" velocity="5"/>
    <origin rpy="0 0 0" xyz="-0.074958 -0.026976 -0.033798"/>
    <parent link="upper_left_arm_specula_link"/>
    <child link="upper_left_arm_z_link"/>
  </joint>
  <joint name="upper_left_arm_y_joint" type="revolute">
    <axis xyz="0 1 0"/>
    <limit effort="15" lower="-3.14" upper="2.0" velocity="5"/>
    <origin rpy="0 0 0" xyz="0 0 0"/>
    <parent link="upper_left_arm_z_link"/>
    <child link="upper_left_arm_y_link"/>
  </joint>
  <joint name="upper_left_arm_x_joint" type="revolute">
    <axis xyz="1 0 0"/>
    <limit effort="15" lower="-1.0" upper="3.14" velocity="5"/>
    <origin rpy="0 0 0" xyz="0 0 0"/>
    <parent link="upper_left_arm_y_link"/>
    <child link="upper_left_arm_x_link"/>
  </joint>

  <link name="upper_left_arm_z_link"/>
  <link name="upper_left_arm_y_link"/>
  <link name="upper_left_arm_x_link">
    <visual>
      <origin rpy="0 0 0" xyz="0 0 0"/>
      <geometry>
        <mesh filename="package://human_description/meshes/zoey/l_upperarm.dae" scale="100 100 100"/>
      </geometry>
      <material name="Blue"/>
    </visual>
    <collision>
      <origin rpy="0 0 0" xyz="0 0 0"/>
      <geometry>
        <mesh filename="package://human_description/meshes/zoey/l_upperarm.dae" scale="100 100 100"/>
      </geometry>
    </collision>
  </link>

  <joint name="lower_left_arm_joint" type="revolute">
    <axis xyz="1 0 0"/>
    <limit effort="15" lower="0" upper="3.14" velocity="5"/>
    <origin rpy="0 0 0" xyz="-0.069024 0.0101 -0.210864"/>
    <parent link="upper_left_arm_x_link"/>
    <child link="lower_left_arm_link"/>
  </joint>

  <link name="lower_left_arm_link">
    <visual>
      <origin rpy="0 0 0" xyz="0 0 0"/>
      <geometry>
        <mesh filename="package://human_description/meshes/zoey/l_forearm.dae" scale="100 100 100"/>
      </geometry>
      <material name="Blue"/>
    </visual>
    <collision>
      <origin rpy="0 0 0" xyz="0 0 0"/>
      <geometry>
        <mesh filename="package://human_description/meshes/zoey/l_forearm.dae" scale="100 100 100"/>
      </geometry>
    </collision>
  </link>

  <joint name="left_hand_z_joint" type="revolute">
    <axis xyz="0 0 1"/>
    <limit effort="15" lower="-1.0" upper="1.0" velocity="5"/>
    <origin rpy="0 0 0" xyz="-0.060346 0.035716 -0.184354"/>
    <parent link="lower_left_arm_link"/>
    <child link="left_hand_z_link"/>
  </joint>
  <joint name="left_hand_y_joint" type="revolute">
    <axis xyz="0 1 0"/>
    <limit effort="15" lower="-1.3" upper="1.5" velocity="5"/>
    <origin rpy="0 0 0" xyz="0 0 0"/>
    <parent link="left_hand_z_link"/>
    <child link="left_hand_y_link"/>
  </joint>
  <joint name="left_hand_x_joint" type="revolute">
    <axis xyz="1 0 0"/>
    <limit effort="15" lower="-0.5" upper="1.4" velocity="5"/>
    <origin rpy="0 0 0" xyz="0 0 0"/>
    <parent link="left_hand_y_link"/>
    <child link="left_hand_x_link"/>
  </joint>

  <link name="left_hand_z_link"/>
  <link name="left_hand_y_link"/>
  <link name="left_hand_x_link">
    <visual>
      <origin rpy="0 0 0" xyz="0 0 0"/>
      <geometry>
        <mesh filename="package://human_description/meshes/zoey/l_hand.dae" scale="100 100 100"/>
      </geometry>
      <material name="Blue"/>
    </visual>
    <collision>
      <origin rpy="0 0 0" xyz="0 0 0"/>
      <geometry>
        <mesh filename="package://human_description/meshes/zoey/l_hand.dae" scale="100 100 100"/>
      </geometry>
    </collision>
  </link>

  <joint name="left_hand_endeffector_joint" type="revolute">
    <axis xyz="0 0 1"/>
    <limit effort="15" lower="-0.001" upper="0.001" velocity="5"/>
    <origin rpy="0 0 0" xyz="-0.006974 0.00016 -0.089562"/>
    <parent link="left_hand_x_link"/>
    <child link="left_hand_endeffector_link"/>
  </joint>

  <link name="left_hand_endeffector_link">
    <visual>
      <origin rpy="0 0 0" xyz="0 0 0"/>
      <geometry>
        <box size="0.001 0.001 0.001"/>
      </geometry>
      <material name="Blue"/>
    </visual>
    <collision>
      <origin rpy="0 0 0" xyz="0 0 0"/>
      <geometry>
        <box size="0.001 0.001 0.001"/>
      </geometry>
    </collision>
  </link>

  
  <joint name="upper_right_specula_joint" type="revolute">
    <axis xyz="0 0 1"/>
    <limit effort="15" lower="-0.5" upper="0.5" velocity="5"/>
    <origin rpy="0 0 0" xyz="0.03 -0.00434 0.19102"/>
    <parent link="torso_up_link"/>
    <child link="upper_right_arm_specula_link"/>
  </joint>
    
  <link name="upper_right_arm_specula_link"/>
  
  <joint name="upper_right_arm_z_joint" type="revolute">
    <axis xyz="0 0 1"/>
    <limit effort="15" lower="-0.5" upper="0.5" velocity="5"/>
    <origin rpy="0 0 0" xyz="0.074956 -0.026976 -0.0338"/>
    <parent link="upper_right_arm_specula_link"/>
    <child link="upper_right_arm_z_link"/>
  </joint>
  <joint name="upper_right_arm_y_joint" type="revolute">
    <axis xyz="0 1 0"/>
    <limit effort="15" lower="-2.0" upper="3.14" velocity="5"/>
    <origin rpy="0 0 0" xyz="0 0 0"/>
    <parent link="upper_right_arm_z_link"/>
    <child link="upper_right_arm_y_link"/>
  </joint>
  <joint name="upper_right_arm_x_joint" type="revolute">
    <axis xyz="1 0 0"/>
    <limit effort="15" lower="-1.0" upper="3.14" velocity="5"/>
    <origin rpy="0 0 0" xyz="0 0 0"/>
    <parent link="upper_right_arm_y_link"/>
    <child link="upper_right_arm_x_link"/>
  </joint>

  <link name="upper_right_arm_z_link"/>
  <link name="upper_right_arm_y_link"/>
  <link name="upper_right_arm_x_link">
    <visual>
      <origin rpy="0 0 0" xyz="0 0 0"/>
      <geometry>
        <mesh filename="package://human_description/meshes/zoey/r_upperarm.dae"/>
      </geometry>
      <material name="Blue"/>
    </visual>
    <collision>
      <origin rpy="0 0 0" xyz="0 0 0"/>
      <geometry>
        <mesh filename="package://human_description/meshes/zoey/r_upperarm.dae"/>
      </geometry>
    </collision>
  </link>

  <joint name="lower_right_arm_joint" type="revolute">
    <axis xyz="1 0 0"/>
    <limit effort="15" lower="0" upper="3.14" velocity="5"/>
    <origin rpy="0 0 0" xyz="0.069024 0.010102 -0.210864"/>
    <parent link="upper_right_arm_x_link"/>
    <child link="lower_right_arm_link"/>
  </joint>

  <link name="lower_right_arm_link">
    <visual>
      <origin rpy="0 0 0" xyz="0 0 0"/>
      <geometry>
        <mesh filename="package://human_description/meshes/zoey/r_forearm.dae"/>
      </geometry>
      <material name="Blue"/>
    </visual>
    <collision>
      <origin rpy="0 0 0" xyz="0 0 0"/>
      <geometry>
        <mesh filename="package://human_description/meshes/zoey/r_forearm.dae"/>
      </geometry>
    </collision>
  </link>

  <joint name="right_hand_z_joint" type="revolute">
    <axis xyz="0 0 1"/>
    <limit effort="15" lower="-1.0" upper="1.0" velocity="5"/>
    <origin rpy="0 0 0" xyz="0.060348 0.035716 -0.184354"/>
    <parent link="lower_right_arm_link"/>
    <child link="right_hand_z_link"/>
  </joint>
  <joint name="right_hand_y_joint" type="revolute">
    <axis xyz="0 1 0"/>
    <limit effort="15" lower="-1.5" upper="1.3" velocity="5"/>
    <origin rpy="0 0 0" xyz="0 0 0"/>
    <parent link="right_hand_z_link"/>
    <child link="right_hand_y_link"/>
  </joint>
  <joint name="right_hand_x_joint" type="revolute">
    <axis xyz="1 0 0"/>
    <limit effort="15" lower="-0.5" upper="1.4" velocity="5"/>
    <origin rpy="0 0 0" xyz="0 0 0"/>
    <parent link="right_hand_y_link"/>
    <child link="right_hand_x_link"/>
  </joint>

  <link name="right_hand_z_link"/>
  <link name="right_hand_y_link"/>
  <link name="right_hand_x_link">
    <visual>
      <origin rpy="0 0 0" xyz="0 0 0"/>
      <geometry>
        <mesh filename="package://human_description/meshes/zoey/r_hand.dae"/>
      </geometry>
      <material name="Blue"/>
    </visual>
    <collision>
      <origin rpy="0 0 0" xyz="0 0 0"/>
      <geometry>
        <mesh filename="package://human_description/meshes/zoey/r_hand.dae"/>
      </geometry>
    </collision>
  </link>

  <joint name="right_hand_endeffector_joint" type="revolute">
    <axis xyz="0 0 1"/>
    <limit effort="15" lower="-0.001" upper="0.001" velocity="5"/>
    <origin rpy="0 0 0" xyz="0.011072 0.017 -0.099982"/>
    <parent link="right_hand_x_link"/>
    <child link="right_hand_endeffector_link"/>
  </joint>

  <link name="right_hand_endeffector_link">
    <visual>
      <origin rpy="0 0 0" xyz="0 0 0"/>
      <geometry>
        <box size="0.001 0.001 0.001"/>
      </geometry>
      <material name="Blue"/>
    </visual>
    <collision>
      <origin rpy="0 0 0" xyz="0 0 0"/>
      <geometry>
        <box size="0.001 0.001 0.001"/>
      </geometry>
    </collision>
  </link>

</robot>
